Workbook

Sheet Parametres
A1: PARAMÈTRES - PROJECTIONS 36 MOIS (SYSTÈME TRANCHES PROGRESSIVES)
A2: Mise à jour: 24/10/2025 02:04 | LOGIQUE FINALE VALIDÉE
A4: INFORMATIONS GÉNÉRALES
A5: Date début projections | B5: 2025-09-01 | C5: Septembre 2025
A6: Durée projections (mois) | B6: 36 | C6: 3 ans
A8: FINANCEMENT ET DETTE
A9: Dette totale | B9: 1726692 | C9: Capital emprunté
A10: Taux annuel | B10: 0.0645 | C10: 6.45%
A11: Durée (mois) | B11: 144 | C11: 12 ans
A12: Mois début dette | B12: 5 | C12: Janvier 2026 (M5)
A13: Moratoire capital | B13: 24 | C13: Intérêts seuls An1-2
A14: Service dette An 1-2 | B14: =B9*B10/12 -> 9280.9695 | C14: Intérêts
A15: Service dette An 3+ | B15: 17254 | C15: Capital + intérêts
A17: LOYER ET INDEXATION
A18: Loyer mensuel base | B18: 9000 | C18: M1-M15
A19: Loyer triple net | B19: 10800 | C19: M16+
A20: Indexation loyer | B20: 0.03 | C20: 3%/an
A21: Mois changement triple net | B21: 16 | C21: Janv 2027
A23: 🎯 SYSTÈME DE TRANCHES PROGRESSIVES
A24: Seuil Tranche 1 (GV) | B24: 0.1 | C24: 0-10% revenu → Gestion VETA
A25: Seuil Tranche 2 (Amanda) | B25: 0.2 | C25: 10-20% revenu → Amanda
A26: Split Tranche 3 | B26: 0.5 | C26: 20%+ revenu → 50/50 GV+Amanda
A27: Moratoire GV (mois) | B27: 6 | C27: M1-M6: GV = 0$
A29: FRAIS GÉNÉRAUX
A30: Frais généraux NET | B30: 16680 | C30: Fixe non indexé
A32: REVENUS ET SAISONNALITÉ
A33: Mois normal (coeff 1.00) | B33: 138691 | C33: Base saisonnalité
A34: Coeff Sept | B34: 1.05 | C34: Cycle annuel
A35: Coeff Oct | B35: 1 | C35: Cycle annuel
A36: Coeff Nov | B36: 0.85 | C36: Cycle annuel
A37: Coeff Déc | B37: 0.8 | C37: Cycle annuel
A38: Coeff Jan | B38: 0.8 | C38: Cycle annuel
A39: Coeff Fév | B39: 0.75 | C39: Cycle annuel
A40: Coeff Mar | B40: 0.9 | C40: Cycle annuel
A41: Coeff Avr | B41: 1 | C41: Cycle annuel
A42: Coeff Mai | B42: 1.05 | C42: Cycle annuel
A43: Coeff Juin | B43: 1.15 | C43: Cycle annuel
A44: Coeff Juil | B44: 1.15 | C44: Cycle annuel
... A49: Croissance Optimiste | B49: 0.1 | C49: +10%/an
A51: CMV ET MASSE SALARIALE
...

Sheet Conservateur
A1: PROJECTIONS 36 MOIS - CONSERVATEUR (TRANCHES PROGRESSIVES)
A2: Généré: 24/10/2025 02:04 | GV: 0-10% | Amanda: 10-20% | Split: 20%+
A3: REVENUS | G3: CHARGES | L3: PROFIT | N3: TRANCHES | T3: TOTAUX | V3: CLINIQUE
A4: N° | B4: Mois | C4: Rev_Base | D4: Tamara | E4: Vet4 | F4: Rev_Total | G4: CMV | H4: Masse_Sal | I4: Loyer | J4: Frais | K4: Dette | L4: Marge_Brute | M4: % Profit | N4: Seuil_10% | O4: Seuil_20% | P4: Tranche_GV | Q4: Tranche_Amanda | R4: Tranche_Split | S4: Split_GV | T4: Split_Amanda | U4: Total_GV | V4: Total_Amanda | W4: Marge_Clinique | X4: Cumul | Y4: Notes
A5: 1 | B5: Sep-2025 | C5: =Parametres!$B$33*Parametres!$B$34 -> 145625.55 | D5: =IF(A5>=Parametres!$B$60,Parametres!$B$61,0) -> 0 | E5: =IF(A5>=Parametres!$B$65,Parametres!$B$66,0) -> 0 | F5: =C5+D5+E5 -> 145625.55 | G5: =F5*Parametres!$B$52 -> 43687.665 | H5: =F5*Parametres!$B$55 -> 68444.009 | I5: =IF(A5<Parametres!$B$21,IF(A5<=12,Parametres!$B$18,Parametres!$B$18*(1+Parametres!$B$20)),IF(A5<=24,Parametres!$B$19*(1+Parametres!$B$20),Parametres!$B$19*POWER(1+Parametres!$B$20,2))) -> 9000 | J5: =Parametres!$B$30 -> 16680 | K5: =IF(A5<Parametres!$B$12,0,IF(A5<=24,Parametres!$B$14,Parametres!$B$15)) -> 0 | L5: =F5-G5-H5-I5-J5-K5 -> 7813.8765 | M5: =IF(F5=0,0,L5/F5) -> 0.053657318 | N5: =F5*Parametres!$B$24 -> 14562.555 | O5: =F5*Parametres!$B$25 -> 29125.11 | P5: =IF(A5<=Parametres!$B$27,0,MIN(L5,N5)) -> 0 | Q5: =IF(L5>N5,MIN(L5-N5,O5-N5),0) -> 0 | R5: =IF(L5>O5,L5-O5,0) -> 0 | S5: =R5*Parametres!$B$26 -> 0 | T5: =R5*Parametres!$B$26 -> 0 | U5: =P5+S5 -> 0 | V5: =Q5+T5 -> 0 | W5: =L5-U5-V5 -> 7813.8765 | X5: =W5 -> 7813.8765 | Y5: Moratoire GV
A6: 2 | B6: Oct-2025 | C6: =Parametres!$B$33*Parametres!$B$35 -> 138691 | D6: =IF(A6>=Parametres!$B$60,Parametres!$B$61,0) -> 0 | E6: =IF(A6>=Parametres!$B$65,Parametres!$B$66,0) -> 0 | F6: =C6+D6+E6 -> 138691 | G6: =F6*Parametres!$B$52 -> 41607.3 | H6: =F6*Parametres!$B$55 -> 65184.77 | I6: =IF(A6<Parametres!$B$21,IF(A6<=12,Parametres!$B$18,Parametres!$B$18*(1+Parametres!$B$20)),IF(A6<=24,Parametres!$B$19*(1+Parametres!$B$20),Parametres!$B$19*POWER(1+Parametres!$B$20,2))) -> 9000 | J6: =Parametres!$B$30 -> 16680 | K6: =IF(A6<Parametres!$B$12,0,IF(A6<=24,Parametres!$B$14,Parametres!$B$15)) -> 0 | L6: =F6-G6-H6-I6-J6-K6 -> 6218.93 | M6: =IF(F6=0,0,L6/F6) -> 0.044840184 | N6: =F6*Parametres!$B$24 -> 13869.1 | O6: =F6*Parametres!$B$25 -> 27738.2 | P6: =IF(A6<=Parametres!$B$27,0,MIN(L6,N6)) -> 0 | Q6: =IF(L6>N6,MIN(L6-N6,O6-N6),0) -> 0 | R6: =IF(L6>O6,L6-O6,0) -> 0 | S6: =R6*Parametres!$B$26 -> 0 | T6: =R6*Parametres!$B$26 -> 0 | U6: =P6+S6 -> 0 | V6: =Q6+T6 -> 0 | W6: =L6-U6-V6 -> 6218.93 | X6: =X5+W6 -> 14032.807 | Y6: Moratoire GV
A7: 3 | B7: Nov-2025 | C7: =Parametres!$B$33*Parametres!$B$36 -> 117887.35 | D7: =IF(A7>=Parametres!$B$60,Parametres!$B$61,0) -> 40131 | E7: =IF(A7>=Parametres!$B$65,Parametres!$B$66,0) -> 0 | F7: =C7+D7+E7 -> 158018.35 | G7: =F7*Parametres!$B$52 -> 47405.505 | H7: =F7*Parametres!$B$55 -> 74268.624 | I7: =IF(A7<Parametres!$B$21,IF(A7<=12,Parametres!$B$18,Parametres!$B$18*(1+Parametres!$B$20)),IF(A7<=24,Parametres!$B$19*(1+Parametres!$B$20),Parametres!$B$19*POWER(1+Parametres!$B$20,2))) -> 9000 | J7: =Parametres!$B$30 -> 16680 | K7: =IF(A7<Parametres!$B$12,0,IF(A7<=24,Parametres!$B$14,Parametres!$B$15)) -> 0 | L7: =F7-G7-H7-I7-J7-K7 -> 10664.22 | M7: =IF(F7=0,0,L7/F7) -> 0.067487229 | N7: =F7*Parametres!$B$24 -> 15801.835 | O7: =F7*Parametres!$B$25 -> 31603.67 | P7: =IF(A7<=Parametres!$B$27,0,MIN(L7,N7)) -> 0 | Q7: =IF(L7>N7,MIN(L7-N7,O7-N7),0) -> 0 | R7: =IF(L7>O7,L7-O7,0) -> 0 | S7: =R7*Parametres!$B$26 -> 0 | T7: =R7*Parametres!$B$26 -> 0 | U7: =P7+S7 -> 0 | V7: =Q7+T7 -> 0 | W7: =L7-U7-V7 -> 10664.22 | X7: =X6+W7 -> 24697.027 | Y7: Moratoire GV
A8: 4 | B8: Dec-2025 | C8: =Parametres!$B$33*Parametres!$B$37 -> 110952.8 | D8: =IF(A8>=Parametres!$B$60,Parametres!$B$61,0) -> 40131 | E8: =IF(A8>=Parametres!$B$65,Parametres!$B$66,0) -> 0 | F8: =C8+D8+E8 -> 151083.8 | G8: =F8*Parametres!$B$52 -> 45325.14 | H8: =F8*Parametres!$B$55 -> 71009.386 | I8: =IF(A8<Parametres!$B$21,IF(A8<=12,Parametres!$B$18,Parametres!$B$18*(1+Parametres!$B$20)),IF(A8<=24,Parametres!$B$19*(1+Parametres!$B$20),Parametres!$B$19*POWER(1+Parametres!$B$20,2))) -> 9000 | J8: =Parametres!$B$30 -> 16680 | K8: =IF(A8<Parametres!$B$12,0,IF(A8<=24,Parametres!$B$14,Parametres!$B$15)) -> 0 | L8: =F8-G8-H8-I8-J8-K8 -> 9069.274 | M8: =IF(F8=0,0,L8/F8) -> 0.060028104 | N8: =F8*Parametres!$B$24 -> 15108.38 | O8: =F8*Parametres!$B$25 -> 30216.76 | P8: =IF(A8<=Parametres!$B$27,0,MIN(L8,N8)) -> 0 | Q8: =IF(L8>N8,MIN(L8-N8,O8-N8),0) -> 0 | R8: =IF(L8>O8,L8-O8,0) -> 0 | S8: =R8*Parametres!$B$26 -> 0 | T8: =R8*Parametres!$B$26 -> 0 | U8: =P8+S8 -> 0 | V8: =Q8+T8 -> 0 | W8: =L8-U8-V8 -> 9069.274 | X8: =X7+W8 -> 33766.301 | Y8: Moratoire GV
A9: 5 | B9: Jan-2026 | C9: =Parametres!$B$33*Parametres!$B$38 -> 110952.8 | D9: =IF(A9>=Parametres!$B$60,Parametres!$B$61,0) -> 40131 | E9: =IF(A9>=Parametres!$B$65,Parametres!$B$66,0) -> 0 | F9: =C9+D9+E9 -> 151083.8 | G9: =F9*Parametres!$B$52 -> 45325.14 | H9: =F9*Parametres!$B$55 -> 71009.386 | I9: =IF(A9<Parametres!$B$21,IF(A9<=12,Parametres!$B$18,Parametres!$B$18*(1+Parametres!$B$20)),IF(A9<=24,Parametres!$B$19*(1+Parametres!$B$20),Parametres!$B$19*POWER(1+Parametres!$B$20,2))) -> 9000 | J9: =Parametres!$B$30 -> 16680 | K9: =IF(A9<Parametres!$B$12,0,IF(A9<=24,Parametres!$B$14,Parametres!$B$15)) -> 9280.9695 | L9: =F9-G9-H9-I9-J9-K9 -> -211.6955 | M9: =IF(F9=0,0,L9/F9) -> -0.0014011793 | N9: =F9*Parametres!$B$24 -> 15108.38 | O9: =F9*Parametres!$B$25 -> 30216.76 | P9: =IF(A9<=Parametres!$B$27,0,MIN(L9,N9)) -> 0 | Q9: =IF(L9>N9,MIN(L9-N9,O9-N9),0) -> 0 | R9: =IF(L9>O9,L9-O9,0) -> 0 | S9: =R9*Parametres!$B$26 -> 0 | T9: =R9*Parametres!$B$26 -> 0 | U9: =P9+S9 -> 0 | V9: =Q9+T9 -> 0 | W9: =L9-U9-V9 -> -211.6955 | X9: =X8+W9 -> 33554.606 | Y9: Moratoire GV
A10: 6 | B10: Feb-2026 | C10: =Parametres!$B$33*Parametres!$B$39 -> 104018.25 | D10: =IF(A10>=Parametres!$B$60,Parametres!$B$61,0) -> 40131 | E10: =IF(A10>=Parametres!$B$65,Parametres!$B$66,0) -> 0 | F10: =C10+D10+E10 -> 144149.25 | G10: =F10*Parametres!$B$52 -> 43244.775 | H10: =F10*Parametres!$B$55 -> 67750.147 | I10: =IF(A10<Parametres!$B$21,IF(A10<=12,Parametres!$B$18,Parametres!$B$18*(1+Parametres!$B$20)),IF(A10<=24,Parametres!$B$19*(1+Parametres!$B$20),Parametres!$B$19*POWER(1+Parametres!$B$20,2))) -> 9000 | J10: =Parametres!$B$30 -> 16680 | K10: =IF(A10<Parametres!$B$12,0,IF(A10<=24,Parametres!$B$14,Parametres!$B$15)) -> 9280.9695 | L10: =F10-G10-H10-I10-J10-K10 -> -1806.642 | M10: =IF(F10=0,0,L10/F10) -> -0.012533135 | N10: =F10*Parametres!$B$24 -> 14414.925 | O10: =F10*Parametres!$B$25 -> 28829.85 | P10: =IF(A10<=Parametres!$B$27,0,MIN(L10,N10)) -> 0 | Q10: =IF(L10>N10,MIN(L10-N10,O10-N10),0) -> 0 | R10: =IF(L10>O10,L10-O10,0) -> 0 | S10: =R10*Parametres!$B$26 -> 0 | T10: =R10*Parametres!$B$26 -> 0 | U10: =P10+S10 -> 0 | V10: =Q10+T10 -> 0 | W10: =L10-U10-V10 -> -1806.642 | X10: =X9+W10 -> 31747.964 | Y10: Moratoire GV
A11: 7 | B11: Mar-2026 | C11: =Parametres!$B$33*Parametres!$B$40 -> 124821.9 | D11: =IF(A11>=Parametres!$B$60,Parametres!$B$61,0) -> 40131 | E11: =IF(A11>=Parametres!$B$65,Parametres!$B$66,0) -> 0 | F11: =C11+D11+E11 -> 164952.9 | G11: =F11*Parametres!$B$52 -> 49485.87 | H11: =F11*Parametres!$B$55 -> 77527.863 | I11: =IF(A11<Parametres!$B$21,IF(A11<=12,Parametres!$B$18,Parametres!$B$18*(1+Parametres!$B$20)),IF(A11<=24,Parametres!$B$19*(1+Parametres!$B$20),Parametres!$B$19*POWER(1+Parametres!$B$20,2))) -> 9000 | J11: =Parametres!$B$30 -> 16680 | K11: =IF(A11<Parametres!$B$12,0,IF(A11<=24,Parametres!$B$14,Parametres!$B$15)) -> 9280.9695 | L11: =F11-G11-H11-I11-J11-K11 -> 2978.1975 | M11: =IF(F11=0,0,L11/F11) -> 0.018054836 | N11: =F11*Parametres!$B$24 -> 16495.29 | O11: =F11*Parametres!$B$25 -> 32990.58 | P11: =IF(A11<=Parametres!$B$27,0,MIN(L11,N11)) -> 2978.1975 | Q11: =IF(L11>N11,MIN(L11-N11,O11-N11),0) -> 0 | R11: =IF(L11>O11,L11-O11,0) -> 0 | S11: =R11*Parametres!$B$26 -> 0 | T11: =R11*Parametres!$B$26 -> 0 | U11: =P11+S11 -> 2978.1975 | V11: =Q11+T11 -> 0 | W11: =L11-U11-V11 -> 0 | X11: =X10+W11 -> 31747.964
A12: 8 | B12: Apr-2026 | C12: =Parametres!$B$33*Parametres!$B$41 -> 138691 | D12: =IF(A12>=Parametres!$B$60,Parametres!$B$61,0) -> 40131 | E12: =IF(A12>=Parametres!$B$65,Parametres!$B$66,0) -> 0 | F12: =C12+D12+E12 -> 178822 | G12: =F12*Parametres!$B$52 -> 53646.6 | H12: =F12*Parametres!$B$55 -> 84046.34 | I12: =IF(A12<Parametres!$B$21,IF(A12<=12,Parametres!$B$18,Parametres!$B$18*(1+Parametres!$B$20)),IF(A12<=24,Parametres!$B$19*(1+Parametres!$B$20),Parametres!$B$19*POWER(1+Parametres!$B$20,2))) -> 9000 | J12: =Parametres!$B$30 -> 16680 | K12: =IF(A12<Parametres!$B$12,0,IF(A12<=24,Parametres!$B$14,Parametres!$B$15)) -> 9280.9695 | L12: =F12-G12-H12-I12-J12-K12 -> 6168.0905 | M12: =IF(F12=0,0,L12/F12) -> 0.034492906 | N12: =F12*Parametres!$B$24 -> 17882.2 | O12: =F12*Parametres!$B$25 -> 35764.4 | P12: =IF(A12<=Parametres!$B$27,0,MIN(L12,N12)) -> 6168.0905 | Q12: =IF(L12>N12,MIN(L12-N12,O12-N12),0) -> 0 | R12: =IF(L12>O12,L12-O12,0) -> 0 | S12: =R12*Parametres!$B$26 -> 0 | T12: =R12*Parametres!$B$26 -> 0 | U12: =P12+S12 -> 6168.0905 | V12: =Q12+T12 -> 0 | W12: =L12-U12-V12 -> 0 | X12: =X11+W12 -> 31747.964
A13: 9 | B13: May-2026 | C13: =Parametres!$B$33*Parametres!$B$42 -> 145625.55 | D13: =IF(A13>=Parametres!$B$60,Parametres!$B$61,0) -> 40131 | E13: =IF(A13>=Parametres!$B$65,Parametres!$B$66,0) -> 0 | F13: =C13+D13+E13 -> 185756.55 | G13: =F13*Parametres!$B$52 -> 55726.965 | H13: =F13*Parametres!$B$55 -> 87305.579 | I13: =IF(A13<Parametres!$B$21,IF(A13<=12,Parametres!$B$18,Parametres!$B$18*(1+Parametres!$B$20)),IF(A13<=24,Parametres!$B$19*(1+Parametres!$B$20),Parametres!$B$19*POWER(1+Parametres!$B$20,2))) -> 9000 | J13: =Parametres!$B$30 -> 16680 | K13: =IF(A13<Parametres!$B$12,0,IF(A13<=24,Parametres!$B$14,Parametres!$B$15)) -> 9280.9695 | L13: =F13-G13-H13-I13-J13-K13 -> 7763.037 | M13: =IF(F13=0,0,L13/F13) -> 0.041791458 | N13: =F13*Parametres!$B$24 -> 18575.655 | O13: =F13*Parametres!$B$25 -> 37151.31 | P13: =IF(A13<=Parametres!$B$27,0,MIN(L13,N13)) -> 7763.037 | Q13: =IF(L13>N13,MIN(L13-N13,O13-N13),0) -> 0 | R13: =IF(L13>O13,L13-O13,0) -> 0 | S13: =R13*Parametres!$B$26 -> 0 | T13: =R13*Parametres!$B$26 -> 0 | U13: =P13+S13 -> 7763.037 | V13: =Q13+T13 -> 0 | W13: =L13-U13-V13 -> 0 | X13: =X12+W13 -> 31747.964
A14: 10 | B14: Jun-2026 | C14: =Parametres!$B$33*Parametres!$B$43 -> 159494.65 | D14: =IF(A14>=Parametres!$B$60,Parametres!$B$61,0) -> 40131 | E14: =IF(A14>=Parametres!$B$65,Parametres!$B$66,0) -> 0 | F14: =C14+D14+E14 -> 199625.65 | G14: =F14*Parametres!$B$52 -> 59887.695 | H14: =F14*Parametres!$B$55 -> 93824.055 | I14: =IF(A14<Parametres!$B$21,IF(A14<=12,Parametres!$B$18,Parametres!$B$18*(1+Parametres!$B$20)),IF(A14<=24,Parametres!$B$19*(1+Parametres!$B$20),Parametres!$B$19*POWER(1+Parametres!$B$20,2))) -> 9000 | J14: =Parametres!$B$30 -> 16680 | K14: =IF(A14<Parametres!$B$12,0,IF(A14<=24,Parametres!$B$14,Parametres!$B$15)) -> 9280.9695 | L14: =F14-G14-H14-I14-J14-K14 -> 10952.93 | M14: =IF(F14=0,0,L14/F14) -> 0.054867348 | N14: =F14*Parametres!$B$24 -> 19962.565 | O14: =F14*Parametres!$B$25 -> 39925.13 | P14: =IF(A14<=Parametres!$B$27,0,MIN(L14,N14)) -> 10952.93 | Q14: =IF(L14>N14,MIN(L14-N14,O14-N14),0) -> 0 | R14: =IF(L14>O14,L14-O14,0) -> 0 | S14: =R14*Parametres!$B$26 -> 0 | T14: =R14*Parametres!$B$26 -> 0 | U14: =P14+S14 -> 10952.93 | V14: =Q14+T14 -> 0 | W14: =L14-U14-V14 -> 0 | X14: =X13+W14 -> 31747.964
A15: 11 | B15: Jul-2026 | C15: =Parametres!$B$33*Parametres!$B$44 -> 159494.65 | D15: =IF(A15>=Parametres!$B$60,Parametres!$B$61,0) -> 40131 | E15: =IF(A15>=Parametres!$B$65,Parametres!$B$66,0) -> 0 | F15: =C15+D15+E15 -> 199625.65 | G15: =F15*Parametres!$B$52 -> 59887.695 | H15: =F15*Parametres!$B$55 -> 93824.055 | I15: =IF(A15<Parametres!$B$21,IF(A15<=12,Parametres!$B$18,Parametres!$B$18*(1+Parametres!$B$20)),IF(A15<=24,Parametres!$B$19*(1+Parametres!$B$20),Parametres!$B$19*POWER(1+Parametres!$B$20,2))) -> 9000 | J15: =Parametres!$B$30 -> 16680 | K15: =IF(A15<Parametres!$B$12,0,IF(A15<=24,Parametres!$B$14,Parametres!$B$15)) -> 9280.9695 | L15: =F15-G15-H15-I15-J15-K15 -> 10952.93 | M15: =IF(F15=0,0,L15/F15) -> 0.054867348 | N15: =F15*Parametres!$B$24 -> 19962.565 | O15: =F15*Parametres!$B$25 -> 39925.13 | P15: =IF(A15<=Parametres!$B$27,0,MIN(L15,N15)) -> 10952.93 | Q15: =IF(L15>N15,MIN(L15-N15,O15-N15),0) -> 0 | R15: =IF(L15>O15,L15-O15,0) -> 0 | S15: =R15*Parametres!$B$26 -> 0 | T15: =R15*Parametres!$B$26 -> 0 | U15: =P15+S15 -> 10952.93 | V15: =Q15+T15 -> 0 | W15: =L15-U15-V15 -> 0 | X15: =X14+W15 -> 31747.964
A16: 12 | B16: Aug-2026 | C16: =Parametres!$B$33*Parametres!$B$45 -> 159494.65 | D16: =IF(A16>=Parametres!$B$60,Parametres!$B$61,0) -> 40131 | E16: =IF(A16>=Parametres!$B$65,Parametres!$B$66,0) -> 0 | F16: =C16+D16+E16 -> 199625.65 | G16: =F16*Parametres!$B$52 -> 59887.695 | H16: =F16*Parametres!$B$55 -> 93824.055 | I16: =IF(A16<Parametres!$B$21,IF(A16<=12,Parametres!$B$18,Parametres!$B$18*(1+Parametres!$B$20)),IF(A16<=24,Parametres!$B$19*(1+Parametres!$B$20),Parametres!$B$19*POWER(1+Parametres!$B$20,2))) -> 9000 | J16: =Parametres!$B$30 -> 16680 | K16: =IF(A16<Parametres!$B$12,0,IF(A16<=24,Parametres!$B$14,Parametres!$B$15)) -> 9280.9695 | L16: =F16-G16-H16-I16-J16-K16 -> 10952.93 | M16: =IF(F16=0,0,L16/F16) -> 0.054867348 | N16: =F16*Parametres!$B$24 -> 19962.565 | O16: =F16*Parametres!$B$25 -> 39925.13 | P16: =IF(A16<=Parametres!$B$27,0,MIN(L16,N16)) -> 10952.93 | Q16: =IF(L16>N16,MIN(L16-N16,O16-N16),0) -> 0 | R16: =IF(L16>O16,L16-O16,0) -> 0 | S16: =R16*Parametres!$B$26 -> 0 | T16: =R16*Parametres!$B$26 -> 0 | U16: =P16+S16 -> 10952.93 | V16: =Q16+T16 -> 0 | W16: =L16-U16-V16 -> 0 | X16: =X15+W16 -> 31747.964
A17: 13 | B17: Sep-2026 | C17: =Parametres!$B$33*(1+Parametres!$B$47)*Parametres!$B$34 -> 149994.32 | D17: =IF(A17>=Parametres!$B$60,Parametres!$B$61,0) -> 40131 | E17: =IF(A17>=Parametres!$B$65,Parametres!$B$66,0) -> 0 | F17: =C17+D17+E17 -> 190125.32 | G17: =F17*Parametres!$B$52 -> 57037.595 | H17: =F17*Parametres!$B$55 -> 89358.899 | I17: =IF(A17<Parametres!$B$21,IF(A17<=12,Parametres!$B$18,Parametres!$B$18*(1+Parametres!$B$20)),IF(A17<=24,Parametres!$B$19*(1+Parametres!$B$20),Parametres!$B$19*POWER(1+Parametres!$B$20,2))) -> 9270 | J17: =Parametres!$B$30 -> 16680 | K17: =IF(A17<Parametres!$B$12,0,IF(A17<=24,Parametres!$B$14,Parametres!$B$15)) -> 9280.9695 | L17: =F17-G17-H17-I17-J17-K17 -> 8497.8533 | M17: =IF(F17=0,0,L17/F17) -> 0.044696064 | N17: =F17*Parametres!$B$24 -> 19012.532 | O17: =F17*Parametres!$B$25 -> 38025.063 | P17: =IF(A17<=Parametres!$B$27,0,MIN(L17,N17)) -> 8497.8533 | Q17: =IF(L17>N17,MIN(L17-N17,O17-N17),0) -> 0 | R17: =IF(L17>O17,L17-O17,0) -> 0 | S17: =R17*Parametres!$B$26 -> 0 | T17: =R17*Parametres!$B$26 -> 0 | U17: =P17+S17 -> 8497.8533 | V17: =Q17+T17 -> 0 | W17: =L17-U17-V17 -> 0 | X17: =X16+W17 -> 31747.964
A18: 14 | B18: Oct-2026 | C18: =Parametres!$B$33*(1+Parametres!$B$47)*Parametres!$B$35 -> 142851.73 | D18: =IF(A18>=Parametres!$B$60,Parametres!$B$61,0) -> 40131 | E18: =IF(A18>=Parametres!$B$65,Parametres!$B$66,0) -> 0 | F18: =C18+D18+E18 -> 182982.73 | G18: =F18*Parametres!$B$52 -> 54894.819 | H18: =F18*Parametres!$B$55 -> 86001.883 | I18: =IF(A18<Parametres!$B$21,IF(A18<=12,Parametres!$B$18,Parametres!$B$18*(1+Parametres!$B$20)),IF(A18<=24,Parametres!$B$19*(1+Parametres!$B$20),Parametres!$B$19*POWER(1+Parametres!$B$20,2))) -> 9270 | J18: =Parametres!$B$30 -> 16680 | K18: =IF(A18<Parametres!$B$12,0,IF(A18<=24,Parametres!$B$14,Parametres!$B$15)) -> 9280.9695 | L18: =F18-G18-H18-I18-J18-K18 -> 6855.0584 | M18: =IF(F18=0,0,L18/F18) -> 0.037462871 | N18: =F18*Parametres!$B$24 -> 18298.273 | O18: =F18*Parametres!$B$25 -> 36596.546 | P18: =IF(A18<=Parametres!$B$27,0,MIN(L18,N18)) -> 6855.0584 | Q18: =IF(L18>N18,MIN(L18-N18,O18-N18),0) -> 0 | R18: =IF(L18>O18,L18-O18,0) -> 0 | S18: =R18*Parametres!$B$26 -> 0 | T18: =R18*Parametres!$B$26 -> 0 | U18: =P18+S18 -> 6855.0584 | V18: =Q18+T18 -> 0 | W18: =L18-U18-V18 -> 0 | X18: =X17+W18 -> 31747.964
A19: 15 | B19: Nov-2026 | C19: =Parametres!$B$33*(1+Parametres!$B$47)*Parametres!$B$36 -> 121423.97 | D19: =IF(A19>=Parametres!$B$60,Parametres!$B$61,0) -> 40131 | E19: =IF(A19>=Parametres!$B$65,Parametres!$B$66,0) -> 0 | F19: =C19+D19+E19 -> 161554.97 | G19: =F19*Parametres!$B$52 -> 48466.491 | H19: =F19*Parametres!$B$55 -> 75930.836 | I19: =IF(A19<Parametres!$B$21,IF(A19<=12,Parametres!$B$18,Parametres!$B$18*(1+Parametres!$B$20)),IF(A19<=24,Parametres!$B$19*(1+Parametres!$B$20),Parametres!$B$19*POWER(1+Parametres!$B$20,2))) -> 9270 | J19: =Parametres!$B$30 -> 16680 | K19: =IF(A19<Parametres!$B$12,0,IF(A19<=24,Parametres!$B$14,Parametres!$B$15)) -> 9280.9695 | L19: =F19-G19-H19-I19-J19-K19 -> 1926.6737 | M19: =IF(F19=0,0,L19/F19) -> 0.011925809 | N19: =F19*Parametres!$B$24 -> 16155.497 | O19: =F19*Parametres!$B$25 -> 32310.994 | P19: =IF(A19<=Parametres!$B$27,0,MIN(L19,N19)) -> 1926.6737 | Q19: =IF(L19>N19,MIN(L19-N19,O19-N19),0) -> 0 | R19: =IF(L19>O19,L19-O19,0) -> 0 | S19: =R19*Parametres!$B$26 -> 0 | T19: =R19*Parametres!$B$26 -> 0 | U19: =P19+S19 -> 1926.6737 | V19: =Q19+T19 -> 0 | W19: =L19-U19-V19 -> 0 | X19: =X18+W19 -> 31747.964
A20: 16 | B20: Dec-2026 | C20: =Parametres!$B$33*(1+Parametres!$B$47)*Parametres!$B$37 -> 114281.38 | D20: =IF(A20>=Parametres!$B$60,Parametres!$B$61,0) -> 40131 | E20: =IF(A20>=Parametres!$B$65,Parametres!$B$66,0) -> 0 | F20: =C20+D20+E20 -> 154412.38 | G20: =F20*Parametres!$B$52 -> 46323.715 | H20: =F20*Parametres!$B$55 -> 72573.82 | I20: =IF(A20<Parametres!$B$21,IF(A20<=12,Parametres!$B$18,Parametres!$B$18*(1+Parametres!$B$20)),IF(A20<=24,Parametres!$B$19*(1+Parametres!$B$20),Parametres!$B$19*POWER(1+Parametres!$B$20,2))) -> 11124 | J20: =Parametres!$B$30 -> 16680 | K20: =IF(A20<Parametres!$B$12,0,IF(A20<=24,Parametres!$B$14,Parametres!$B$15)) -> 9280.9695 | L20: =F20-G20-H20-I20-J20-K20 -> -1570.1212 | M20: =IF(F20=0,0,L20/F20) -> -0.010168363 | N20: =F20*Parametres!$B$24 -> 15441.238 | O20: =F20*Parametres!$B$25 -> 30882.477 | P20: =IF(A20<=Parametres!$B$27,0,MIN(L20,N20)) -> -1570.1212 | Q20: =IF(L20>N20,MIN(L20-N20,O20-N20),0) -> 0 | R20: =IF(L20>O20,L20-O20,0) -> 0 | S20: =R20*Parametres!$B$26 -> 0 | T20: =R20*Parametres!$B$26 -> 0 | U20: =P20+S20 -> -1570.1212 | V20: =Q20+T20 -> 0 | W20: =L20-U20-V20 -> 0 | X20: =X19+W20 -> 31747.964
A21: 17 | B21: Jan-2027 | C21: =Parametres!$B$33*(1+Parametres!$B$47)*Parametres!$B$38 -> 114281.38 | D21: =IF(A21>=Parametres!$B$60,Parametres!$B$61,0) -> 40131 | E21: =IF(A21>=Parametres!$B$65,Parametres!$B$66,0) -> 0 | F21: =C21+D21+E21 -> 154412.38 | G21: =F21*Parametres!$B$52 -> 46323.715 | H21: =F21*Parametres!$B$55 -> 72573.82 | I21: =IF(A21<Parametres!$B$21,IF(A21<=12,Parametres!$B$18,Parametres!$B$18*(1+Parametres!$B$20)),IF(A21<=24,Parametres!$B$19*(1+Parametres!$B$20),Parametres!$B$19*POWER(1+Parametres!$B$20,2))) -> 11124 | J21: =Parametres!$B$30 -> 16680 | K21: =IF(A21<Parametres!$B$12,0,IF(A21<=24,Parametres!$B$14,Parametres!$B$15)) -> 9280.9695 | L21: =F21-G21-H21-I21-J21-K21 -> -1570.1212 | M21: =IF(F21=0,0,L21/F21) -> -0.010168363 | N21: =F21*Parametres!$B$24 -> 15441.238 | O21: =F21*Parametres!$B$25 -> 30882.477 | P21: =IF(A21<=Parametres!$B$27,0,MIN(L21,N21)) -> -1570.1212 | Q21: =IF(L21>N21,MIN(L21-N21,O21-N21),0) -> 0 | R21: =IF(L21>O21,L21-O21,0) -> 0 | S21: =R21*Parametres!$B$26 -> 0 | T21: =R21*Parametres!$B$26 -> 0 | U21: =P21+S21 -> -1570.1212 | V21: =Q21+T21 -> 0 | W21: =L21-U21-V21 -> 0 | X21: =X20+W21 -> 31747.964
A22: 18 | B22: Feb-2027 | C22: =Parametres!$B$33*(1+Parametres!$B$47)*Parametres!$B$39 -> 107138.8 | D22: =IF(A22>=Parametres!$B$60,Parametres!$B$61,0) -> 40131 | E22: =IF(A22>=Parametres!$B$65,Parametres!$B$66,0) -> 0 | F22: =C22+D22+E22 -> 147269.8 | G22: =F22*Parametres!$B$52 -> 44180.939 | H22: =F22*Parametres!$B$55 -> 69216.805 | I22: =IF(A22<Parametres!$B$21,IF(A22<=12,Parametres!$B$18,Parametres!$B$18*(1+Parametres!$B$20)),IF(A22<=24,Parametres!$B$19*(1+Parametres!$B$20),Parametres!$B$19*POWER(1+Parametres!$B$20,2))) -> 11124 | J22: =Parametres!$B$30 -> 16680 | K22: =IF(A22<Parametres!$B$12,0,IF(A22<=24,Parametres!$B$14,Parametres!$B$15)) -> 9280.9695 | L22: =F22-G22-H22-I22-J22-K22 -> -3212.9161 | M22: =IF(F22=0,0,L22/F22) -> -0.021816531 | N22: =F22*Parametres!$B$24 -> 14726.98 | O22: =F22*Parametres!$B$25 -> 29453.96 | P22: =IF(A22<=Parametres!$B$27,0,MIN(L22,N22)) -> -3212.9161 | Q22: =IF(L22>N22,MIN(L22-N22,O22-N22),0) -> 0 | R22: =IF(L22>O22,L22-O22,0) -> 0 | S22: =R22*Parametres!$B$26 -> 0 | T22: =R22*Parametres!$B$26 -> 0 | U22: =P22+S22 -> -3212.9161 | V22: =Q22+T22 -> 0 | W22: =L22-U22-V22 -> 0 | X22: =X21+W22 -> 31747.964
A23: 19 | B23: Mar-2027 | C23: =Parametres!$B$33*(1+Parametres!$B$47)*Parametres!$B$40 -> 128566.56 | D23: =IF(A23>=Parametres!$B$60,Parametres!$B$61,0) -> 40131 | E23: =IF(A23>=Parametres!$B$65,Parametres!$B$66,0) -> 0 | F23: =C23+D23+E23 -> 168697.56 | G23: =F23*Parametres!$B$52 -> 50609.267 | H23: =F23*Parametres!$B$55 -> 79287.852 | I23: =IF(A23<Parametres!$B$21,IF(A23<=12,Parametres!$B$18,Parametres!$B$18*(1+Parametres!$B$20)),IF(A23<=24,Parametres!$B$19*(1+Parametres!$B$20),Parametres!$B$19*POWER(1+Parametres!$B$20,2))) -> 11124 | J23: =Parametres!$B$30 -> 16680 | K23: =IF(A23<Parametres!$B$12,0,IF(A23<=24,Parametres!$B$14,Parametres!$B$15)) -> 9280.9695 | L23: =F23-G23-H23-I23-J23-K23 -> 1715.4686 | M23: =IF(F23=0,0,L23/F23) -> 0.0101689 | N23: =F23*Parametres!$B$24 -> 16869.756 | O23: =F23*Parametres!$B$25 -> 33739.511 | P23: =IF(A23<=Parametres!$B$27,0,MIN(L23,N23)) -> 1715.4686 | Q23: =IF(L23>N23,MIN(L23-N23,O23-N23),0) -> 0 | R23: =IF(L23>O23,L23-O23,0) -> 0 | S23: =R23*Parametres!$B$26 -> 0 | T23: =R23*Parametres!$B$26 -> 0 | U23: =P23+S23 -> 1715.4686 | V23: =Q23+T23 -> 0 | W23: =L23-U23-V23 -> 0 | X23: =X22+W23 -> 31747.964
A24: 20 | B24: Apr-2027 | C24: =Parametres!$B$33*(1+Parametres!$B$47)*Parametres!$B$41 -> 142851.73 | D24: =IF(A24>=Parametres!$B$60,Parametres!$B$61,0) -> 40131 | E24: =IF(A24>=Parametres!$B$65,Parametres!$B$66,0) -> 58704 | F24: =C24+D24+E24 -> 241686.73 | G24: =F24*Parametres!$B$52 -> 72506.019 | H24: =F24*Parametres!$B$55 -> 113592.76 | I24: =IF(A24<Parametres!$B$21,IF(A24<=12,Parametres!$B$18,Parametres!$B$18*(1+Parametres!$B$20)),IF(A24<=24,Parametres!$B$19*(1+Parametres!$B$20),Parametres!$B$19*POWER(1+Parametres!$B$20,2))) -> 11124 | J24: =Parametres!$B$30 -> 16680 | K24: =IF(A24<Parametres!$B$12,0,IF(A24<=24,Parametres!$B$14,Parametres!$B$15)) -> 9280.9695 | L24: =F24-G24-H24-I24-J24-K24 -> 18502.978 | M24: =IF(F24=0,0,L24/F24) -> 0.076557693 | N24: =F24*Parametres!$B$24 -> 24168.673 | O24: =F24*Parametres!$B$25 -> 48337.346 | P24: =IF(A24<=Parametres!$B$27,0,MIN(L24,N24)) -> 18502.978 | Q24: =IF(L24>N24,MIN(L24-N24,O24-N24),0) -> 0 | R24: =IF(L24>O24,L24-O24,0) -> 0 | S24: =R24*Parametres!$B$26 -> 0 | T24: =R24*Parametres!$B$26 -> 0 | U24: =P24+S24 -> 18502.978 | V24: =Q24+T24 -> 0 | W24: =L24-U24-V24 -> 0 | X24: =X23+W24 -> 31747.964
A25: 21 | B25: May-2027 | C25: =Parametres!$B$33*(1+Parametres!$B$47)*Parametres!$B$42 -> 149994.32 | D25: =IF(A25>=Parametres!$B$60,Parametres!$B$61,0) -> 40131 | E25: =IF(A25>=Parametres!$B$65,Parametres!$B$66,0) -> 58704 | F25: =C25+D25+E25 -> 248829.32 | G25: =F25*Parametres!$B$52 -> 74648.795 | H25: =F25*Parametres!$B$55 -> 116949.78 | I25: =IF(A25<Parametres!$B$21,IF(A25<=12,Parametres!$B$18,Parametres!$B$18*(1+Parametres!$B$20)),IF(A25<=24,Parametres!$B$19*(1+Parametres!$B$20),Parametres!$B$19*POWER(1+Parametres!$B$20,2))) -> 11124 | J25: =Parametres!$B$30 -> 16680 | K25: =IF(A25<Parametres!$B$12,0,IF(A25<=24,Parametres!$B$14,Parametres!$B$15)) -> 9280.9695 | L25: =F25-G25-H25-I25-J25-K25 -> 20145.773 | M25: =IF(F25=0,0,L25/F25) -> 0.080962218 | N25: =F25*Parametres!$B$24 -> 24882.932 | O25: =F25*Parametres!$B$25 -> 49765.863 | P25: =IF(A25<=Parametres!$B$27,0,MIN(L25,N25)) -> 20145.773 | Q25: =IF(L25>N25,MIN(L25-N25,O25-N25),0) -> 0 | R25: =IF(L25>O25,L25-O25,0) -> 0 | S25: =R25*Parametres!$B$26 -> 0 | T25: =R25*Parametres!$B$26 -> 0 | U25: =P25+S25 -> 20145.773 | V25: =Q25+T25 -> 0 | W25: =L25-U25-V25 -> 0 | X25: =X24+W25 -> 31747.964
A26: 22 | B26: Jun-2027 | C26: =Parametres!$B$33*(1+Parametres!$B$47)*Parametres!$B$43 -> 164279.49 | D26: =IF(A26>=Parametres!$B$60,Parametres!$B$61,0) -> 40131 | E26: =IF(A26>=Parametres!$B$65,Parametres!$B$66,0) -> 58704 | F26: =C26+D26+E26 -> 263114.49 | G26: =F26*Parametres!$B$52 -> 78934.347 | H26: =F26*Parametres!$B$55 -> 123663.81 | I26: =IF(A26<Parametres!$B$21,IF(A26<=12,Parametres!$B$18,Parametres!$B$18*(1+Parametres!$B$20)),IF(A26<=24,Parametres!$B$19*(1+Parametres!$B$20),Parametres!$B$19*POWER(1+Parametres!$B$20,2))) -> 11124 | J26: =Parametres!$B$30 -> 16680 | K26: =IF(A26<Parametres!$B$12,0,IF(A26<=24,Parametres!$B$14,Parametres!$B$15)) -> 9280.9695 | L26: =F26-G26-H26-I26-J26-K26 -> 23431.363 | M26: =IF(F26=0,0,L26/F26) -> 0.089053868 | N26: =F26*Parametres!$B$24 -> 26311.449 | O26: =F26*Parametres!$B$25 -> 52622.898 | P26: =IF(A26<=Parametres!$B$27,0,MIN(L26,N26)) -> 23431.363 | Q26: =IF(L26>N26,MIN(L26-N26,O26-N26),0) -> 0 | R26: =IF(L26>O26,L26-O26,0) -> 0 | S26: =R26*Parametres!$B$26 -> 0 | T26: =R26*Parametres!$B$26 -> 0 | U26: =P26+S26 -> 23431.363 | V26: =Q26+T26 -> 0 | W26: =L26-U26-V26 -> 0 | X26: =X25+W26 -> 31747.964
A27: 23 | B27: Jul-2027 | C27: =Parametres!$B$33*(1+Parametres!$B$47)*Parametres!$B$44 -> 164279.49 | D27: =IF(A27>=Parametres!$B$60,Parametres!$B$61,0) -> 40131 | E27: =IF(A27>=Parametres!$B$65,Parametres!$B$66,0) -> 58704 | F27: =C27+D27+E27 -> 263114.49 | G27: =F27*Parametres!$B$52 -> 78934.347 | H27: =F27*Parametres!$B$55 -> 123663.81 | I27: =IF(A27<Parametres!$B$21,IF(A27<=12,Parametres!$B$18,Parametres!$B$18*(1+Parametres!$B$20)),IF(A27<=24,Parametres!$B$19*(1+Parametres!$B$20),Parametres!$B$19*POWER(1+Parametres!$B$20,2))) -> 11124 | J27: =Parametres!$B$30 -> 16680 | K27: =IF(A27<Parametres!$B$12,0,IF(A27<=24,Parametres!$B$14,Parametres!$B$15)) -> 9280.9695 | L27: =F27-G27-H27-I27-J27-K27 -> 23431.363 | M27: =IF(F27=0,0,L27/F27) -> 0.089053868 | N27: =F27*Parametres!$B$24 -> 26311.449 | O27: =F27*Parametres!$B$25 -> 52622.898 | P27: =IF(A27<=Parametres!$B$27,0,MIN(L27,N27)) -> 23431.363 | Q27: =IF(L27>N27,MIN(L27-N27,O27-N27),0) -> 0 | R27: =IF(L27>O27,L27-O27,0) -> 0 | S27: =R27*Parametres!$B$26 -> 0 | T27: =R27*Parametres!$B$26 -> 0 | U27: =P27+S27 -> 23431.363 | V27: =Q27+T27 -> 0 | W27: =L27-U27-V27 -> 0 | X27: =X26+W27 -> 31747.964
A28: 24 | B28: Aug-2027 | C28: =Parametres!$B$33*(1+Parametres!$B$47)*Parametres!$B$45 -> 164279.49 | D28: =IF(A28>=Parametres!$B$60,Parametres!$B$61,0) -> 40131 | E28: =IF(A28>=Parametres!$B$65,Parametres!$B$66,0) -> 58704 | F28: =C28+D28+E28 -> 263114.49 | G28: =F28*Parametres!$B$52 -> 78934.347 | H28: =F28*Parametres!$B$55 -> 123663.81 | I28: =IF(A28<Parametres!$B$21,IF(A28<=12,Parametres!$B$18,Parametres!$B$18*(1+Parametres!$B$20)),IF(A28<=24,Parametres!$B$19*(1+Parametres!$B$20),Parametres!$B$19*POWER(1+Parametres!$B$20,2))) -> 11124 | J28: =Parametres!$B$30 -> 16680 | K28: =IF(A28<Parametres!$B$12,0,IF(A28<=24,Parametres!$B$14,Parametres!$B$15)) -> 9280.9695 | L28: =F28-G28-H28-I28-J28-K28 -> 23431.363 | M28: =IF(F28=0,0,L28/F28) -> 0.089053868 | N28: =F28*Parametres!$B$24 -> 26311.449 | O28: =F28*Parametres!$B$25 -> 52622.898 | P28: =IF(A28<=Parametres!$B$27,0,MIN(L28,N28)) -> 23431.363 | Q28: =IF(L28>N28,MIN(L28-N28,O28-N28),0) -> 0 | R28: =IF(L28>O28,L28-O28,0) -> 0 | S28: =R28*Parametres!$B$26 -> 0 | T28: =R28*Parametres!$B$26 -> 0 | U28: =P28+S28 -> 23431.363 | V28: =Q28+T28 -> 0 | W28: =L28-U28-V28 -> 0 | X28: =X27+W28 -> 31747.964
A29: 25 | B29: Sep-2027 | C29: =Parametres!$B$33*POWER(1+Parametres!$B$47,2)*Parametres!$B$34 -> 154494.15 | D29: =IF(A29>=Parametres!$B$60,Parametres!$B$61,0) -> 40131 | E29: =IF(A29>=Parametres!$B$65,Parametres!$B$66,0) -> 58704 | F29: =C29+D29+E29 -> 253329.15 | G29: =F29*Parametres!$B$52 -> 75998.744 | H29: =F29*Parametres!$B$55 -> 119064.7 | I29: =IF(A29<Parametres!$B$21,IF(A29<=12,Parametres!$B$18,Parametres!$B$18*(1+Parametres!$B$20)),IF(A29<=24,Parametres!$B$19*(1+Parametres!$B$20),Parametres!$B$19*POWER(1+Parametres!$B$20,2))) -> 11457.72 | J29: =Parametres!$B$30 -> 16680 | K29: =IF(A29<Parametres!$B$12,0,IF(A29<=24,Parametres!$B$14,Parametres!$B$15)) -> 17254 | L29: =F29-G29-H29-I29-J29-K29 -> 12873.984 | M29: =IF(F29=0,0,L29/F29) -> 0.050819196 | N29: =F29*Parametres!$B$24 -> 25332.915 | O29: =F29*Parametres!$B$25 -> 50665.829 | P29: =IF(A29<=Parametres!$B$27,0,MIN(L29,N29)) -> 12873.984 | Q29: =IF(L29>N29,MIN(L29-N29,O29-N29),0) -> 0 | R29: =IF(L29>O29,L29-O29,0) -> 0 | S29: =R29*Parametres!$B$26 -> 0 | T29: =R29*Parametres!$B$26 -> 0 | U29: =P29+S29 -> 12873.984 | V29: =Q29+T29 -> 0 | W29: =L29-U29-V29 -> 0 | X29: =X28+W29 -> 31747.964
A30: 26 | B30: Oct-2027 | C30: =Parametres!$B$33*POWER(1+Parametres!$B$47,2)*Parametres!$B$35 -> 147137.28 | D30: =IF(A30>=Parametres!$B$60,Parametres!$B$61,0) -> 40131 | E30: =IF(A30>=Parametres!$B$65,Parametres!$B$66,0) -> 58704 | F30: =C30+D30+E30 -> 245972.28 | G30: =F30*Parametres!$B$52 -> 73791.685 | H30: =F30*Parametres!$B$55 -> 115606.97 | I30: =IF(A30<Parametres!$B$21,IF(A30<=12,Parametres!$B$18,Parametres!$B$18*(1+Parametres!$B$20)),IF(A30<=24,Parametres!$B$19*(1+Parametres!$B$20),Parametres!$B$19*POWER(1+Parametres!$B$20,2))) -> 11457.72 | J30: =Parametres!$B$30 -> 16680 | K30: =IF(A30<Parametres!$B$12,0,IF(A30<=24,Parametres!$B$14,Parametres!$B$15)) -> 17254 | L30: =F30-G30-H30-I30-J30-K30 -> 11181.905 | M30: =IF(F30=0,0,L30/F30) -> 0.04546002 | N30: =F30*Parametres!$B$24 -> 24597.228 | O30: =F30*Parametres!$B$25 -> 49194.456 | P30: =IF(A30<=Parametres!$B$27,0,MIN(L30,N30)) -> 11181.905 | Q30: =IF(L30>N30,MIN(L30-N30,O30-N30),0) -> 0 | R30: =IF(L30>O30,L30-O30,0) -> 0 | S30: =R30*Parametres!$B$26 -> 0 | T30: =R30*Parametres!$B$26 -> 0 | U30: =P30+S30 -> 11181.905 | V30: =Q30+T30 -> 0 | W30: =L30-U30-V30 -> 0 | X30: =X29+W30 -> 31747.964
A31: 27 | B31: Nov-2027 | C31: =Parametres!$B$33*POWER(1+Parametres!$B$47,2)*Parametres!$B$36 -> 125066.69 | D31: =IF(A31>=Parametres!$B$60,Parametres!$B$61,0) -> 40131 | E31: =IF(A31>=Parametres!$B$65,Parametres!$B$66,0) -> 58704 | F31: =C31+D31+E31 -> 223901.69 | G31: =F31*Parametres!$B$52 -> 67170.507 | H31: =F31*Parametres!$B$55 -> 105233.79 | I31: =IF(A31<Parametres!$B$21,IF(A31<=12,Parametres!$B$18,Parametres!$B$18*(1+Parametres!$B$20)),IF(A31<=24,Parametres!$B$19*(1+Parametres!$B$20),Parametres!$B$19*POWER(1+Parametres!$B$20,2))) -> 11457.72 | J31: =Parametres!$B$30 -> 16680 | K31: =IF(A31<Parametres!$B$12,0,IF(A31<=24,Parametres!$B$14,Parametres!$B$15)) -> 17254 | L31: =F31-G31-H31-I31-J31-K31 -> 6105.6686 | M31: =IF(F31=0,0,L31/F31) -> 0.027269417 | N31: =F31*Parametres!$B$24 -> 22390.169 | O31: =F31*Parametres!$B$25 -> 44780.338 | P31: =IF(A31<=Parametres!$B$27,0,MIN(L31,N31)) -> 6105.6686 | Q31: =IF(L31>N31,MIN(L31-N31,O31-N31),0) -> 0 | R31: =IF(L31>O31,L31-O31,0) -> 0 | S31: =R31*Parametres!$B$26 -> 0 | T31: =R31*Parametres!$B$26 -> 0 | U31: =P31+S31 -> 6105.6686 | V31: =Q31+T31 -> 0 | W31: =L31-U31-V31 -> 0 | X31: =X30+W31 -> 31747.964
A32: 28 | B32: Dec-2027 | C32: =Parametres!$B$33*POWER(1+Parametres!$B$47,2)*Parametres!$B$37 -> 117709.83 | D32: =IF(A32>=Parametres!$B$60,Parametres!$B$61,0) -> 40131 | E32: =IF(A32>=Parametres!$B$65,Parametres!$B$66,0) -> 58704 | F32: =C32+D32+E32 -> 216544.83 | G32: =F32*Parametres!$B$52 -> 64963.448 | H32: =F32*Parametres!$B$55 -> 101776.07 | I32: =IF(A32<Parametres!$B$21,IF(A32<=12,Parametres!$B$18,Parametres!$B$18*(1+Parametres!$B$20)),IF(A32<=24,Parametres!$B$19*(1+Parametres!$B$20),Parametres!$B$19*POWER(1+Parametres!$B$20,2))) -> 11457.72 | J32: =Parametres!$B$30 -> 16680 | K32: =IF(A32<Parametres!$B$12,0,IF(A32<=24,Parametres!$B$14,Parametres!$B$15)) -> 17254 | L32: =F32-G32-H32-I32-J32-K32 -> 4413.5899 | M32: =IF(F32=0,0,L32/F32) -> 0.020381876 | N32: =F32*Parametres!$B$24 -> 21654.483 | O32: =F32*Parametres!$B$25 -> 43308.965 | P32: =IF(A32<=Parametres!$B$27,0,MIN(L32,N32)) -> 4413.5899 | Q32: =IF(L32>N32,MIN(L32-N32,O32-N32),0) -> 0 | R32: =IF(L32>O32,L32-O32,0) -> 0 | S32: =R32*Parametres!$B$26 -> 0 | T32: =R32*Parametres!$B$26 -> 0 | U32: =P32+S32 -> 4413.5899 | V32: =Q32+T32 -> 0 | W32: =L32-U32-V32 -> 0 | X32: =X31+W32 -> 31747.964
A33: 29 | B33: Jan-2028 | C33: =Parametres!$B$33*POWER(1+Parametres!$B$47,2)*Parametres!$B$38 -> 117709.83 | D33: =IF(A33>=Parametres!$B$60,Parametres!$B$61,0) -> 40131 | E33: =IF(A33>=Parametres!$B$65,Parametres!$B$66,0) -> 58704 | F33: =C33+D33+E33 -> 216544.83 | G33: =F33*Parametres!$B$52 -> 64963.448 | H33: =F33*Parametres!$B$55 -> 101776.07 | I33: =IF(A33<Parametres!$B$21,IF(A33<=12,Parametres!$B$18,Parametres!$B$18*(1+Parametres!$B$20)),IF(A33<=24,Parametres!$B$19*(1+Parametres!$B$20),Parametres!$B$19*POWER(1+Parametres!$B$20,2))) -> 11457.72 | J33: =Parametres!$B$30 -> 16680 | K33: =IF(A33<Parametres!$B$12,0,IF(A33<=24,Parametres!$B$14,Parametres!$B$15)) -> 17254 | L33: =F33-G33-H33-I33-J33-K33 -> 4413.5899 | M33: =IF(F33=0,0,L33/F33) -> 0.020381876 | N33: =F33*Parametres!$B$24 -> 21654.483 | O33: =F33*Parametres!$B$25 -> 43308.965 | P33: =IF(A33<=Parametres!$B$27,0,MIN(L33,N33)) -> 4413.5899 | Q33: =IF(L33>N33,MIN(L33-N33,O33-N33),0) -> 0 | R33: =IF(L33>O33,L33-O33,0) -> 0 | S33: =R33*Parametres!$B$26 -> 0 | T33: =R33*Parametres!$B$26 -> 0 | U33: =P33+S33 -> 4413.5899 | V33: =Q33+T33 -> 0 | W33: =L33-U33-V33 -> 0 | X33: =X32+W33 -> 31747.964
A34: 30 | B34: Feb-2028 | C34: =Parametres!$B$33*POWER(1+Parametres!$B$47,2)*Parametres!$B$39 -> 110352.96 | D34: =IF(A34>=Parametres!$B$60,Parametres!$B$61,0) -> 40131 | E34: =IF(A34>=Parametres!$B$65,Parametres!$B$66,0) -> 58704 | F34: =C34+D34+E34 -> 209187.96 | G34: =F34*Parametres!$B$52 -> 62756.388 | H34: =F34*Parametres!$B$55 -> 98318.342 | I34: =IF(A34<Parametres!$B$21,IF(A34<=12,Parametres!$B$18,Parametres!$B$18*(1+Parametres!$B$20)),IF(A34<=24,Parametres!$B$19*(1+Parametres!$B$20),Parametres!$B$19*POWER(1+Parametres!$B$20,2))) -> 11457.72 | J34: =Parametres!$B$30 -> 16680 | K34: =IF(A34<Parametres!$B$12,0,IF(A34<=24,Parametres!$B$14,Parametres!$B$15)) -> 17254 | L34: =F34-G34-H34-I34-J34-K34 -> 2721.5111 | M34: =IF(F34=0,0,L34/F34) -> 0.013009884 | N34: =F34*Parametres!$B$24 -> 20918.796 | O34: =F34*Parametres!$B$25 -> 41837.592 | P34: =IF(A34<=Parametres!$B$27,0,MIN(L34,N34)) -> 2721.5111 | Q34: =IF(L34>N34,MIN(L34-N34,O34-N34),0) -> 0 | R34: =IF(L34>O34,L34-O34,0) -> 0 | S34: =R34*Parametres!$B$26 -> 0 | T34: =R34*Parametres!$B$26 -> 0 | U34: =P34+S34 -> 2721.5111 | V34: =Q34+T34 -> 0 | W34: =L34-U34-V34 -> 0 | X34: =X33+W34 -> 31747.964
A35: 31 | B35: Mar-2028 | C35: =Parametres!$B$33*POWER(1+Parametres!$B$47,2)*Parametres!$B$40 -> 132423.55 | D35: =IF(A35>=Parametres!$B$60,Parametres!$B$61,0) -> 40131 | E35: =IF(A35>=Parametres!$B$65,Parametres!$B$66,0) -> 58704 | F35: =C35+D35+E35 -> 231258.55 | G35: =F35*Parametres!$B$52 -> 69377.566 | H35: =F35*Parametres!$B$55 -> 108691.52 | I35: =IF(A35<Parametres!$B$21,IF(A35<=12,Parametres!$B$18,Parametres!$B$18*(1+Parametres!$B$20)),IF(A35<=24,Parametres!$B$19*(1+Parametres!$B$20),Parametres!$B$19*POWER(1+Parametres!$B$20,2))) -> 11457.72 | J35: =Parametres!$B$30 -> 16680 | K35: =IF(A35<Parametres!$B$12,0,IF(A35<=24,Parametres!$B$14,Parametres!$B$15)) -> 17254 | L35: =F35-G35-H35-I35-J35-K35 -> 7797.7474 | M35: =IF(F35=0,0,L35/F35) -> 0.033718741 | N35: =F35*Parametres!$B$24 -> 23125.855 | O35: =F35*Parametres!$B$25 -> 46251.711 | P35: =IF(A35<=Parametres!$B$27,0,MIN(L35,N35)) -> 7797.7474 | Q35: =IF(L35>N35,MIN(L35-N35,O35-N35),0) -> 0 | R35: =IF(L35>O35,L35-O35,0) -> 0 | S35: =R35*Parametres!$B$26 -> 0 | T35: =R35*Parametres!$B$26 -> 0 | U35: =P35+S35 -> 7797.7474 | V35: =Q35+T35 -> 0 | W35: =L35-U35-V35 -> 0 | X35: =X34+W35 -> 31747.964
A36: 32 | B36: Apr-2028 | C36: =Parametres!$B$33*POWER(1+Parametres!$B$47,2)*Parametres!$B$41 -> 147137.28 | D36: =IF(A36>=Parametres!$B$60,Parametres!$B$61,0) -> 40131 | E36: =IF(A36>=Parametres!$B$65,Parametres!$B$66,0) -> 58704 | F36: =C36+D36+E36 -> 245972.28 | G36: =F36*Parametres!$B$52 -> 73791.685 | H36: =F36*Parametres!$B$55 -> 115606.97 | I36: =IF(A36<Parametres!$B$21,IF(A36<=12,Parametres!$B$18,Parametres!$B$18*(1+Parametres!$B$20)),IF(A36<=24,Parametres!$B$19*(1+Parametres!$B$20),Parametres!$B$19*POWER(1+Parametres!$B$20,2))) -> 11457.72 | J36: =Parametres!$B$30 -> 16680 | K36: =IF(A36<Parametres!$B$12,0,IF(A36<=24,Parametres!$B$14,Parametres!$B$15)) -> 17254 | L36: =F36-G36-H36-I36-J36-K36 -> 11181.905 | M36: =IF(F36=0,0,L36/F36) -> 0.04546002 | N36: =F36*Parametres!$B$24 -> 24597.228 | O36: =F36*Parametres!$B$25 -> 49194.456 | P36: =IF(A36<=Parametres!$B$27,0,MIN(L36,N36)) -> 11181.905 | Q36: =IF(L36>N36,MIN(L36-N36,O36-N36),0) -> 0 | R36: =IF(L36>O36,L36-O36,0) -> 0 | S36: =R36*Parametres!$B$26 -> 0 | T36: =R36*Parametres!$B$26 -> 0 | U36: =P36+S36 -> 11181.905 | V36: =Q36+T36 -> 0 | W36: =L36-U36-V36 -> 0 | X36: =X35+W36 -> 31747.964
A37: 33 | B37: May-2028 | C37: =Parametres!$B$33*POWER(1+Parametres!$B$47,2)*Parametres!$B$42 -> 154494.15 | D37: =IF(A37>=Parametres!$B$60,Parametres!$B$61,0) -> 40131 | E37: =IF(A37>=Parametres!$B$65,Parametres!$B$66,0) -> 58704 | F37: =C37+D37+E37 -> 253329.15 | G37: =F37*Parametres!$B$52 -> 75998.744 | H37: =F37*Parametres!$B$55 -> 119064.7 | I37: =IF(A37<Parametres!$B$21,IF(A37<=12,Parametres!$B$18,Parametres!$B$18*(1+Parametres!$B$20)),IF(A37<=24,Parametres!$B$19*(1+Parametres!$B$20),Parametres!$B$19*POWER(1+Parametres!$B$20,2))) -> 11457.72 | J37: =Parametres!$B$30 -> 16680 | K37: =IF(A37<Parametres!$B$12,0,IF(A37<=24,Parametres!$B$14,Parametres!$B$15)) -> 17254 | L37: =F37-G37-H37-I37-J37-K37 -> 12873.984 | M37: =IF(F37=0,0,L37/F37) -> 0.050819196 | N37: =F37*Parametres!$B$24 -> 25332.915 | O37: =F37*Parametres!$B$25 -> 50665.829 | P37: =IF(A37<=Parametres!$B$27,0,MIN(L37,N37)) -> 12873.984 | Q37: =IF(L37>N37,MIN(L37-N37,O37-N37),0) -> 0 | R37: =IF(L37>O37,L37-O37,0) -> 0 | S37: =R37*Parametres!$B$26 -> 0 | T37: =R37*Parametres!$B$26 -> 0 | U37: =P37+S37 -> 12873.984 | V37: =Q37+T37 -> 0 | W37: =L37-U37-V37 -> 0 | X37: =X36+W37 -> 31747.964
A38: 34 | B38: Jun-2028 | C38: =Parametres!$B$33*POWER(1+Parametres!$B$47,2)*Parametres!$B$43 -> 169207.87 | D38: =IF(A38>=Parametres!$B$60,Parametres!$B$61,0) -> 40131 | E38: =IF(A38>=Parametres!$B$65,Parametres!$B$66,0) -> 58704 | F38: =C38+D38+E38 -> 268042.87 | G38: =F38*Parametres!$B$52 -> 80412.862 | H38: =F38*Parametres!$B$55 -> 125980.15 | I38: =IF(A38<Parametres!$B$21,IF(A38<=12,Parametres!$B$18,Parametres!$B$18*(1+Parametres!$B$20)),IF(A38<=24,Parametres!$B$19*(1+Parametres!$B$20),Parametres!$B$19*POWER(1+Parametres!$B$20,2))) -> 11457.72 | J38: =Parametres!$B$30 -> 16680 | K38: =IF(A38<Parametres!$B$12,0,IF(A38<=24,Parametres!$B$14,Parametres!$B$15)) -> 17254 | L38: =F38-G38-H38-I38-J38-K38 -> 16258.141 | M38: =IF(F38=0,0,L38/F38) -> 0.060655002 | N38: =F38*Parametres!$B$24 -> 26804.287 | O38: =F38*Parametres!$B$25 -> 53608.575 | P38: =IF(A38<=Parametres!$B$27,0,MIN(L38,N38)) -> 16258.141 | Q38: =IF(L38>N38,MIN(L38-N38,O38-N38),0) -> 0 | R38: =IF(L38>O38,L38-O38,0) -> 0 | S38: =R38*Parametres!$B$26 -> 0 | T38: =R38*Parametres!$B$26 -> 0 | U38: =P38+S38 -> 16258.141 | V38: =Q38+T38 -> 0 | W38: =L38-U38-V38 -> 0 | X38: =X37+W38 -> 31747.964
A39: 35 | B39: Jul-2028 | C39: =Parametres!$B$33*POWER(1+Parametres!$B$47,2)*Parametres!$B$44 -> 169207.87 | D39: =IF(A39>=Parametres!$B$60,Parametres!$B$61,0) -> 40131 | E39: =IF(A39>=Parametres!$B$65,Parametres!$B$66,0) -> 58704 | F39: =C39+D39+E39 -> 268042.87 | G39: =F39*Parametres!$B$52 -> 80412.862 | H39: =F39*Parametres!$B$55 -> 125980.15 | I39: =IF(A39<Parametres!$B$21,IF(A39<=12,Parametres!$B$18,Parametres!$B$18*(1+Parametres!$B$20)),IF(A39<=24,Parametres!$B$19*(1+Parametres!$B$20),Parametres!$B$19*POWER(1+Parametres!$B$20,2))) -> 11457.72 | J39: =Parametres!$B$30 -> 16680 | K39: =IF(A39<Parametres!$B$12,0,IF(A39<=24,Parametres!$B$14,Parametres!$B$15)) -> 17254 | L39: =F39-G39-H39-I39-J39-K39 -> 16258.141 | M39: =IF(F39=0,0,L39/F39) -> 0.060655002 | N39: =F39*Parametres!$B$24 -> 26804.287 | O39: =F39*Parametres!$B$25 -> 53608.575 | P39: =IF(A39<=Parametres!$B$27,0,MIN(L39,N39)) -> 16258.141 | Q39: =IF(L39>N39,MIN(L39-N39,O39-N39),0) -> 0 | R39: =IF(L39>O39,L39-O39,0) -> 0 | S39: =R39*Parametres!$B$26 -> 0 | T39: =R39*Parametres!$B$26 -> 0 | U39: =P39+S39 -> 16258.141 | V39: =Q39+T39 -> 0 | W39: =L39-U39-V39 -> 0 | X39: =X38+W39 -> 31747.964
A40: 36 | B40: Aug-2028 | C40: =Parametres!$B$33*POWER(1+Parametres!$B$47,2)*Parametres!$B$45 -> 169207.87 | D40: =IF(A40>=Parametres!$B$60,Parametres!$B$61,0) -> 40131 | E40: =IF(A40>=Parametres!$B$65,Parametres!$B$66,0) -> 58704 | F40: =C40+D40+E40 -> 268042.87 | G40: =F40*Parametres!$B$52 -> 80412.862 | H40: =F40*Parametres!$B$55 -> 125980.15 | I40: =IF(A40<Parametres!$B$21,IF(A40<=12,Parametres!$B$18,Parametres!$B$18*(1+Parametres!$B$20)),IF(A40<=24,Parametres!$B$19*(1+Parametres!$B$20),Parametres!$B$19*POWER(1+Parametres!$B$20,2))) -> 11457.72 | J40: =Parametres!$B$30 -> 16680 | K40: =IF(A40<Parametres!$B$12,0,IF(A40<=24,Parametres!$B$14,Parametres!$B$15)) -> 17254 | L40: =F40-G40-H40-I40-J40-K40 -> 16258.141 | M40: =IF(F40=0,0,L40/F40) -> 0.060655002 | N40: =F40*Parametres!$B$24 -> 26804.287 | O40: =F40*Parametres!$B$25 -> 53608.575 | P40: =IF(A40<=Parametres!$B$27,0,MIN(L40,N40)) -> 16258.141 | Q40: =IF(L40>N40,MIN(L40-N40,O40-N40),0) -> 0 | R40: =IF(L40>O40,L40-O40,0) -> 0 | S40: =R40*Parametres!$B$26 -> 0 | T40: =R40*Parametres!$B$26 -> 0 | U40: =P40+S40 -> 16258.141 | V40: =Q40+T40 -> 0 | W40: =L40-U40-V40 -> 0 | X40: =X39+W40 -> 31747.964
...

Sheet Realiste
A1: PROJECTIONS 36 MOIS - REALISTE (TRANCHES PROGRESSIVES)
A2: Généré: 24/10/2025 02:04 | GV: 0-10% | Amanda: 10-20% | Split: 20%+
A3: REVENUS | G3: CHARGES | L3: PROFIT | N3: TRANCHES | T3: TOTAUX | V3: CLINIQUE
A4: N° | B4: Mois | C4: Rev_Base | D4: Tamara | E4: Vet4 | F4: Rev_Total | G4: CMV | H4: Masse_Sal | I4: Loyer | J4: Frais | K4: Dette | L4: Marge_Brute | M4: % Profit | N4: Seuil_10% | O4: Seuil_20% | P4: Tranche_GV | Q4: Tranche_Amanda | R4: Tranche_Split | S4: Split_GV | T4: Split_Amanda | U4: Total_GV | V4: Total_Amanda | W4: Marge_Clinique | X4: Cumul | Y4: Notes
A5: 1 | B5: Sep-2025 | C5: =Parametres!$B$33*Parametres!$B$34 -> 145625.55 | D5: =IF(A5>=Parametres!$B$60,Parametres!$B$62,0) -> 0 | E5: =IF(A5>=Parametres!$B$65,Parametres!$B$67,0) -> 0 | F5: =C5+D5+E5 -> 145625.55 | G5: =F5*Parametres!$B$53 -> 41503.282 | H5: =F5*Parametres!$B$56 -> 65531.498 | I5: =IF(A5<Parametres!$B$21,IF(A5<=12,Parametres!$B$18,Parametres!$B$18*(1+Parametres!$B$20)),IF(A5<=24,Parametres!$B$19*(1+Parametres!$B$20),Parametres!$B$19*POWER(1+Parametres!$B$20,2))) -> 9000 | J5: =Parametres!$B$30 -> 16680 | K5: =IF(A5<Parametres!$B$12,0,IF(A5<=24,Parametres!$B$14,Parametres!$B$15)) -> 0 | L5: =F5-G5-H5-I5-J5-K5 -> 12910.771 | M5: =IF(F5=0,0,L5/F5) -> 0.088657318 | N5: =F5*Parametres!$B$24 -> 14562.555 | O5: =F5*Parametres!$B$25 -> 29125.11 | P5: =IF(A5<=Parametres!$B$27,0,MIN(L5,N5)) -> 0 | Q5: =IF(L5>N5,MIN(L5-N5,O5-N5),0) -> 0 | R5: =IF(L5>O5,L5-O5,0) -> 0 | S5: =R5*Parametres!$B$26 -> 0 | T5: =R5*Parametres!$B$26 -> 0 | U5: =P5+S5 -> 0 | V5: =Q5+T5 -> 0 | W5: =L5-U5-V5 -> 12910.771 | X5: =W5 -> 12910.771 | Y5: Moratoire GV
A6: 2 | B6: Oct-2025 | C6: =Parametres!$B$33*Parametres!$B$35 -> 138691 | D6: =IF(A6>=Parametres!$B$60,Parametres!$B$62,0) -> 0 | E6: =IF(A6>=Parametres!$B$65,Parametres!$B$67,0) -> 0 | F6: =C6+D6+E6 -> 138691 | G6: =F6*Parametres!$B$53 -> 39526.935 | H6: =F6*Parametres!$B$56 -> 62410.95 | I6: =IF(A6<Parametres!$B$21,IF(A6<=12,Parametres!$B$18,Parametres!$B$18*(1+Parametres!$B$20)),IF(A6<=24,Parametres!$B$19*(1+Parametres!$B$20),Parametres!$B$19*POWER(1+Parametres!$B$20,2))) -> 9000 | J6: =Parametres!$B$30 -> 16680 | K6: =IF(A6<Parametres!$B$12,0,IF(A6<=24,Parametres!$B$14,Parametres!$B$15)) -> 0 | L6: =F6-G6-H6-I6-J6-K6 -> 11073.115 | M6: =IF(F6=0,0,L6/F6) -> 0.079840184 | N6: =F6*Parametres!$B$24 -> 13869.1 | O6: =F6*Parametres!$B$25 -> 27738.2 | P6: =IF(A6<=Parametres!$B$27,0,MIN(L6,N6)) -> 0 | Q6: =IF(L6>N6,MIN(L6-N6,O6-N6),0) -> 0 | R6: =IF(L6>O6,L6-O6,0) -> 0 | S6: =R6*Parametres!$B$26 -> 0 | T6: =R6*Parametres!$B$26 -> 0 | U6: =P6+S6 -> 0 | V6: =Q6+T6 -> 0 | W6: =L6-U6-V6 -> 11073.115 | X6: =X5+W6 -> 23983.886 | Y6: Moratoire GV
A7: 3 | B7: Nov-2025 | C7: =Parametres!$B$33*Parametres!$B$36 -> 117887.35 | D7: =IF(A7>=Parametres!$B$60,Parametres!$B$62,0) -> 48732 | E7: =IF(A7>=Parametres!$B$65,Parametres!$B$67,0) -> 0 | F7: =C7+D7+E7 -> 166619.35 | G7: =F7*Parametres!$B$53 -> 47486.515 | H7: =F7*Parametres!$B$56 -> 74978.707 | I7: =IF(A7<Parametres!$B$21,IF(A7<=12,Parametres!$B$18,Parametres!$B$18*(1+Parametres!$B$20)),IF(A7<=24,Parametres!$B$19*(1+Parametres!$B$20),Parametres!$B$19*POWER(1+Parametres!$B$20,2))) -> 9000 | J7: =Parametres!$B$30 -> 16680 | K7: =IF(A7<Parametres!$B$12,0,IF(A7<=24,Parametres!$B$14,Parametres!$B$15)) -> 0 | L7: =F7-G7-H7-I7-J7-K7 -> 18474.128 | M7: =IF(F7=0,0,L7/F7) -> 0.11087624 | N7: =F7*Parametres!$B$24 -> 16661.935 | O7: =F7*Parametres!$B$25 -> 33323.87 | P7: =IF(A7<=Parametres!$B$27,0,MIN(L7,N7)) -> 0 | Q7: =IF(L7>N7,MIN(L7-N7,O7-N7),0) -> 1812.1928 | R7: =IF(L7>O7,L7-O7,0) -> 0 | S7: =R7*Parametres!$B$26 -> 0 | T7: =R7*Parametres!$B$26 -> 0 | U7: =P7+S7 -> 0 | V7: =Q7+T7 -> 1812.1928 | W7: =L7-U7-V7 -> 16661.935 | X7: =X6+W7 -> 40645.821 | Y7: Moratoire GV
A8: 4 | B8: Dec-2025 | C8: =Parametres!$B$33*Parametres!$B$37 -> 110952.8 | D8: =IF(A8>=Parametres!$B$60,Parametres!$B$62,0) -> 48732 | E8: =IF(A8>=Parametres!$B$65,Parametres!$B$67,0) -> 0 | F8: =C8+D8+E8 -> 159684.8 | G8: =F8*Parametres!$B$53 -> 45510.168 | H8: =F8*Parametres!$B$56 -> 71858.16 | I8: =IF(A8<Parametres!$B$21,IF(A8<=12,Parametres!$B$18,Parametres!$B$18*(1+Parametres!$B$20)),IF(A8<=24,Parametres!$B$19*(1+Parametres!$B$20),Parametres!$B$19*POWER(1+Parametres!$B$20,2))) -> 9000 | J8: =Parametres!$B$30 -> 16680 | K8: =IF(A8<Parametres!$B$12,0,IF(A8<=24,Parametres!$B$14,Parametres!$B$15)) -> 0 | L8: =F8-G8-H8-I8-J8-K8 -> 16636.472 | M8: =IF(F8=0,0,L8/F8) -> 0.10418319 | N8: =F8*Parametres!$B$24 -> 15968.48 | O8: =F8*Parametres!$B$25 -> 31936.96 | P8: =IF(A8<=Parametres!$B$27,0,MIN(L8,N8)) -> 0 | Q8: =IF(L8>N8,MIN(L8-N8,O8-N8),0) -> 667.992 | R8: =IF(L8>O8,L8-O8,0) -> 0 | S8: =R8*Parametres!$B$26 -> 0 | T8: =R8*Parametres!$B$26 -> 0 | U8: =P8+S8 -> 0 | V8: =Q8+T8 -> 667.992 | W8: =L8-U8-V8 -> 15968.48 | X8: =X7+W8 -> 56614.301 | Y8: Moratoire GV
A9: 5 | B9: Jan-2026 | C9: =Parametres!$B$33*Parametres!$B$38 -> 110952.8 | D9: =IF(A9>=Parametres!$B$60,Parametres!$B$62,0) -> 48732 | E9: =IF(A9>=Parametres!$B$65,Parametres!$B$67,0) -> 0 | F9: =C9+D9+E9 -> 159684.8 | G9: =F9*Parametres!$B$53 -> 45510.168 | H9: =F9*Parametres!$B$56 -> 71858.16 | I9: =IF(A9<Parametres!$B$21,IF(A9<=12,Parametres!$B$18,Parametres!$B$18*(1+Parametres!$B$20)),IF(A9<=24,Parametres!$B$19*(1+Parametres!$B$20),Parametres!$B$19*POWER(1+Parametres!$B$20,2))) -> 9000 | J9: =Parametres!$B$30 -> 16680 | K9: =IF(A9<Parametres!$B$12,0,IF(A9<=24,Parametres!$B$14,Parametres!$B$15)) -> 9280.9695 | L9: =F9-G9-H9-I9-J9-K9 -> 7355.5025 | M9: =IF(F9=0,0,L9/F9) -> 0.046062634 | N9: =F9*Parametres!$B$24 -> 15968.48 | O9: =F9*Parametres!$B$25 -> 31936.96 | P9: =IF(A9<=Parametres!$B$27,0,MIN(L9,N9)) -> 0 | Q9: =IF(L9>N9,MIN(L9-N9,O9-N9),0) -> 0 | R9: =IF(L9>O9,L9-O9,0) -> 0 | S9: =R9*Parametres!$B$26 -> 0 | T9: =R9*Parametres!$B$26 -> 0 | U9: =P9+S9 -> 0 | V9: =Q9+T9 -> 0 | W9: =L9-U9-V9 -> 7355.5025 | X9: =X8+W9 -> 63969.803 | Y9: Moratoire GV
A10: 6 | B10: Feb-2026 | C10: =Parametres!$B$33*Parametres!$B$39 -> 104018.25 | D10: =IF(A10>=Parametres!$B$60,Parametres!$B$62,0) -> 48732 | E10: =IF(A10>=Parametres!$B$65,Parametres!$B$67,0) -> 0 | F10: =C10+D10+E10 -> 152750.25 | G10: =F10*Parametres!$B$53 -> 43533.821 | H10: =F10*Parametres!$B$56 -> 68737.613 | I10: =IF(A10<Parametres!$B$21,IF(A10<=12,Parametres!$B$18,Parametres!$B$18*(1+Parametres!$B$20)),IF(A10<=24,Parametres!$B$19*(1+Parametres!$B$20),Parametres!$B$19*POWER(1+Parametres!$B$20,2))) -> 9000 | J10: =Parametres!$B$30 -> 16680 | K10: =IF(A10<Parametres!$B$12,0,IF(A10<=24,Parametres!$B$14,Parametres!$B$15)) -> 9280.9695 | L10: =F10-G10-H10-I10-J10-K10 -> 5517.8468 | M10: =IF(F10=0,0,L10/F10) -> 0.036123324 | N10: =F10*Parametres!$B$24 -> 15275.025 | O10: =F10*Parametres!$B$25 -> 30550.05 | P10: =IF(A10<=Parametres!$B$27,0,MIN(L10,N10)) -> 0 | Q10: =IF(L10>N10,MIN(L10-N10,O10-N10),0) -> 0 | R10: =IF(L10>O10,L10-O10,0) -> 0 | S10: =R10*Parametres!$B$26 -> 0 | T10: =R10*Parametres!$B$26 -> 0 | U10: =P10+S10 -> 0 | V10: =Q10+T10 -> 0 | W10: =L10-U10-V10 -> 5517.8468 | X10: =X9+W10 -> 69487.65 | Y10: Moratoire GV
A11: 7 | B11: Mar-2026 | C11: =Parametres!$B$33*Parametres!$B$40 -> 124821.9 | D11: =IF(A11>=Parametres!$B$60,Parametres!$B$62,0) -> 48732 | E11: =IF(A11>=Parametres!$B$65,Parametres!$B$67,0) -> 0 | F11: =C11+D11+E11 -> 173553.9 | G11: =F11*Parametres!$B$53 -> 49462.861 | H11: =F11*Parametres!$B$56 -> 78099.255 | I11: =IF(A11<Parametres!$B$21,IF(A11<=12,Parametres!$B$18,Parametres!$B$18*(1+Parametres!$B$20)),IF(A11<=24,Parametres!$B$19*(1+Parametres!$B$20),Parametres!$B$19*POWER(1+Parametres!$B$20,2))) -> 9000 | J11: =Parametres!$B$30 -> 16680 | K11: =IF(A11<Parametres!$B$12,0,IF(A11<=24,Parametres!$B$14,Parametres!$B$15)) -> 9280.9695 | L11: =F11-G11-H11-I11-J11-K11 -> 11030.814 | M11: =IF(F11=0,0,L11/F11) -> 0.063558433 | N11: =F11*Parametres!$B$24 -> 17355.39 | O11: =F11*Parametres!$B$25 -> 34710.78 | P11: =IF(A11<=Parametres!$B$27,0,MIN(L11,N11)) -> 11030.814 | Q11: =IF(L11>N11,MIN(L11-N11,O11-N11),0) -> 0 | R11: =IF(L11>O11,L11-O11,0) -> 0 | S11: =R11*Parametres!$B$26 -> 0 | T11: =R11*Parametres!$B$26 -> 0 | U11: =P11+S11 -> 11030.814 | V11: =Q11+T11 -> 0 | W11: =L11-U11-V11 -> 0 | X11: =X10+W11 -> 69487.65
A12: 8 | B12: Apr-2026 | C12: =Parametres!$B$33*Parametres!$B$41 -> 138691 | D12: =IF(A12>=Parametres!$B$60,Parametres!$B$62,0) -> 48732 | E12: =IF(A12>=Parametres!$B$65,Parametres!$B$67,0) -> 0 | F12: =C12+D12+E12 -> 187423 | G12: =F12*Parametres!$B$53 -> 53415.555 | H12: =F12*Parametres!$B$56 -> 84340.35 | I12: =IF(A12<Parametres!$B$21,IF(A12<=12,Parametres!$B$18,Parametres!$B$18*(1+Parametres!$B$20)),IF(A12<=24,Parametres!$B$19*(1+Parametres!$B$20),Parametres!$B$19*POWER(1+Parametres!$B$20,2))) -> 9000 | J12: =Parametres!$B$30 -> 16680 | K12: =IF(A12<Parametres!$B$12,0,IF(A12<=24,Parametres!$B$14,Parametres!$B$15)) -> 9280.9695 | L12: =F12-G12-H12-I12-J12-K12 -> 14706.126 | M12: =IF(F12=0,0,L12/F12) -> 0.078464892 | N12: =F12*Parametres!$B$24 -> 18742.3 | O12: =F12*Parametres!$B$25 -> 37484.6 | P12: =IF(A12<=Parametres!$B$27,0,MIN(L12,N12)) -> 14706.126 | Q12: =IF(L12>N12,MIN(L12-N12,O12-N12),0) -> 0 | R12: =IF(L12>O12,L12-O12,0) -> 0 | S12: =R12*Parametres!$B$26 -> 0 | T12: =R12*Parametres!$B$26 -> 0 | U12: =P12+S12 -> 14706.126 | V12: =Q12+T12 -> 0 | W12: =L12-U12-V12 -> 0 | X12: =X11+W12 -> 69487.65
A13: 9 | B13: May-2026 | C13: =Parametres!$B$33*Parametres!$B$42 -> 145625.55 | D13: =IF(A13>=Parametres!$B$60,Parametres!$B$62,0) -> 48732 | E13: =IF(A13>=Parametres!$B$65,Parametres!$B$67,0) -> 0 | F13: =C13+D13+E13 -> 194357.55 | G13: =F13*Parametres!$B$53 -> 55391.902 | H13: =F13*Parametres!$B$56 -> 87460.898 | I13: =IF(A13<Parametres!$B$21,IF(A13<=12,Parametres!$B$18,Parametres!$B$18*(1+Parametres!$B$20)),IF(A13<=24,Parametres!$B$19*(1+Parametres!$B$20),Parametres!$B$19*POWER(1+Parametres!$B$20,2))) -> 9000 | J13: =Parametres!$B$30 -> 16680 | K13: =IF(A13<Parametres!$B$12,0,IF(A13<=24,Parametres!$B$14,Parametres!$B$15)) -> 9280.9695 | L13: =F13-G13-H13-I13-J13-K13 -> 16543.781 | M13: =IF(F13=0,0,L13/F13) -> 0.085120343 | N13: =F13*Parametres!$B$24 -> 19435.755 | O13: =F13*Parametres!$B$25 -> 38871.51 | P13: =IF(A13<=Parametres!$B$27,0,MIN(L13,N13)) -> 16543.781 | Q13: =IF(L13>N13,MIN(L13-N13,O13-N13),0) -> 0 | R13: =IF(L13>O13,L13-O13,0) -> 0 | S13: =R13*Parametres!$B$26 -> 0 | T13: =R13*Parametres!$B$26 -> 0 | U13: =P13+S13 -> 16543.781 | V13: =Q13+T13 -> 0 | W13: =L13-U13-V13 -> 0 | X13: =X12+W13 -> 69487.65
A14: 10 | B14: Jun-2026 | C14: =Parametres!$B$33*Parametres!$B$43 -> 159494.65 | D14: =IF(A14>=Parametres!$B$60,Parametres!$B$62,0) -> 48732 | E14: =IF(A14>=Parametres!$B$65,Parametres!$B$67,0) -> 0 | F14: =C14+D14+E14 -> 208226.65 | G14: =F14*Parametres!$B$53 -> 59344.595 | H14: =F14*Parametres!$B$56 -> 93701.992 | I14: =IF(A14<Parametres!$B$21,IF(A14<=12,Parametres!$B$18,Parametres!$B$18*(1+Parametres!$B$20)),IF(A14<=24,Parametres!$B$19*(1+Parametres!$B$20),Parametres!$B$19*POWER(1+Parametres!$B$20,2))) -> 9000 | J14: =Parametres!$B$30 -> 16680 | K14: =IF(A14<Parametres!$B$12,0,IF(A14<=24,Parametres!$B$14,Parametres!$B$15)) -> 9280.9695 | L14: =F14-G14-H14-I14-J14-K14 -> 20219.093 | M14: =IF(F14=0,0,L14/F14) -> 0.097101369 | N14: =F14*Parametres!$B$24 -> 20822.665 | O14: =F14*Parametres!$B$25 -> 41645.33 | P14: =IF(A14<=Parametres!$B$27,0,MIN(L14,N14)) -> 20219.093 | Q14: =IF(L14>N14,MIN(L14-N14,O14-N14),0) -> 0 | R14: =IF(L14>O14,L14-O14,0) -> 0 | S14: =R14*Parametres!$B$26 -> 0 | T14: =R14*Parametres!$B$26 -> 0 | U14: =P14+S14 -> 20219.093 | V14: =Q14+T14 -> 0 | W14: =L14-U14-V14 -> 0 | X14: =X13+W14 -> 69487.65
A15: 11 | B15: Jul-2026 | C15: =Parametres!$B$33*Parametres!$B$44 -> 159494.65 | D15: =IF(A15>=Parametres!$B$60,Parametres!$B$62,0) -> 48732 | E15: =IF(A15>=Parametres!$B$65,Parametres!$B$67,0) -> 0 | F15: =C15+D15+E15 -> 208226.65 | G15: =F15*Parametres!$B$53 -> 59344.595 | H15: =F15*Parametres!$B$56 -> 93701.992 | I15: =IF(A15<Parametres!$B$21,IF(A15<=12,Parametres!$B$18,Parametres!$B$18*(1+Parametres!$B$20)),IF(A15<=24,Parametres!$B$19*(1+Parametres!$B$20),Parametres!$B$19*POWER(1+Parametres!$B$20,2))) -> 9000 | J15: =Parametres!$B$30 -> 16680 | K15: =IF(A15<Parametres!$B$12,0,IF(A15<=24,Parametres!$B$14,Parametres!$B$15)) -> 9280.9695 | L15: =F15-G15-H15-I15-J15-K15 -> 20219.093 | M15: =IF(F15=0,0,L15/F15) -> 0.097101369 | N15: =F15*Parametres!$B$24 -> 20822.665 | O15: =F15*Parametres!$B$25 -> 41645.33 | P15: =IF(A15<=Parametres!$B$27,0,MIN(L15,N15)) -> 20219.093 | Q15: =IF(L15>N15,MIN(L15-N15,O15-N15),0) -> 0 | R15: =IF(L15>O15,L15-O15,0) -> 0 | S15: =R15*Parametres!$B$26 -> 0 | T15: =R15*Parametres!$B$26 -> 0 | U15: =P15+S15 -> 20219.093 | V15: =Q15+T15 -> 0 | W15: =L15-U15-V15 -> 0 | X15: =X14+W15 -> 69487.65
A16: 12 | B16: Aug-2026 | C16: =Parametres!$B$33*Parametres!$B$45 -> 159494.65 | D16: =IF(A16>=Parametres!$B$60,Parametres!$B$62,0) -> 48732 | E16: =IF(A16>=Parametres!$B$65,Parametres!$B$67,0) -> 0 | F16: =C16+D16+E16 -> 208226.65 | G16: =F16*Parametres!$B$53 -> 59344.595 | H16: =F16*Parametres!$B$56 -> 93701.992 | I16: =IF(A16<Parametres!$B$21,IF(A16<=12,Parametres!$B$18,Parametres!$B$18*(1+Parametres!$B$20)),IF(A16<=24,Parametres!$B$19*(1+Parametres!$B$20),Parametres!$B$19*POWER(1+Parametres!$B$20,2))) -> 9000 | J16: =Parametres!$B$30 -> 16680 | K16: =IF(A16<Parametres!$B$12,0,IF(A16<=24,Parametres!$B$14,Parametres!$B$15)) -> 9280.9695 | L16: =F16-G16-H16-I16-J16-K16 -> 20219.093 | M16: =IF(F16=0,0,L16/F16) -> 0.097101369 | N16: =F16*Parametres!$B$24 -> 20822.665 | O16: =F16*Parametres!$B$25 -> 41645.33 | P16: =IF(A16<=Parametres!$B$27,0,MIN(L16,N16)) -> 20219.093 | Q16: =IF(L16>N16,MIN(L16-N16,O16-N16),0) -> 0 | R16: =IF(L16>O16,L16-O16,0) -> 0 | S16: =R16*Parametres!$B$26 -> 0 | T16: =R16*Parametres!$B$26 -> 0 | U16: =P16+S16 -> 20219.093 | V16: =Q16+T16 -> 0 | W16: =L16-U16-V16 -> 0 | X16: =X15+W16 -> 69487.65
A17: 13 | B17: Sep-2026 | C17: =Parametres!$B$33*(1+Parametres!$B$48)*Parametres!$B$34 -> 152906.83 | D17: =IF(A17>=Parametres!$B$60,Parametres!$B$62,0) -> 48732 | E17: =IF(A17>=Parametres!$B$65,Parametres!$B$67,0) -> 0 | F17: =C17+D17+E17 -> 201638.83 | G17: =F17*Parametres!$B$53 -> 57467.066 | H17: =F17*Parametres!$B$56 -> 90737.472 | I17: =IF(A17<Parametres!$B$21,IF(A17<=12,Parametres!$B$18,Parametres!$B$18*(1+Parametres!$B$20)),IF(A17<=24,Parametres!$B$19*(1+Parametres!$B$20),Parametres!$B$19*POWER(1+Parametres!$B$20,2))) -> 9270 | J17: =Parametres!$B$30 -> 16680 | K17: =IF(A17<Parametres!$B$12,0,IF(A17<=24,Parametres!$B$14,Parametres!$B$15)) -> 9280.9695 | L17: =F17-G17-H17-I17-J17-K17 -> 18203.32 | M17: =IF(F17=0,0,L17/F17) -> 0.090276858 | N17: =F17*Parametres!$B$24 -> 20163.883 | O17: =F17*Parametres!$B$25 -> 40327.766 | P17: =IF(A17<=Parametres!$B$27,0,MIN(L17,N17)) -> 18203.32 | Q17: =IF(L17>N17,MIN(L17-N17,O17-N17),0) -> 0 | R17: =IF(L17>O17,L17-O17,0) -> 0 | S17: =R17*Parametres!$B$26 -> 0 | T17: =R17*Parametres!$B$26 -> 0 | U17: =P17+S17 -> 18203.32 | V17: =Q17+T17 -> 0 | W17: =L17-U17-V17 -> 0 | X17: =X16+W17 -> 69487.65
A18: 14 | B18: Oct-2026 | C18: =Parametres!$B$33*(1+Parametres!$B$48)*Parametres!$B$35 -> 145625.55 | D18: =IF(A18>=Parametres!$B$60,Parametres!$B$62,0) -> 48732 | E18: =IF(A18>=Parametres!$B$65,Parametres!$B$67,0) -> 0 | F18: =C18+D18+E18 -> 194357.55 | G18: =F18*Parametres!$B$53 -> 55391.902 | H18: =F18*Parametres!$B$56 -> 87460.898 | I18: =IF(A18<Parametres!$B$21,IF(A18<=12,Parametres!$B$18,Parametres!$B$18*(1+Parametres!$B$20)),IF(A18<=24,Parametres!$B$19*(1+Parametres!$B$20),Parametres!$B$19*POWER(1+Parametres!$B$20,2))) -> 9270 | J18: =Parametres!$B$30 -> 16680 | K18: =IF(A18<Parametres!$B$12,0,IF(A18<=24,Parametres!$B$14,Parametres!$B$15)) -> 9280.9695 | L18: =F18-G18-H18-I18-J18-K18 -> 16273.781 | M18: =IF(F18=0,0,L18/F18) -> 0.08373115 | N18: =F18*Parametres!$B$24 -> 19435.755 | O18: =F18*Parametres!$B$25 -> 38871.51 | P18: =IF(A18<=Parametres!$B$27,0,MIN(L18,N18)) -> 16273.781 | Q18: =IF(L18>N18,MIN(L18-N18,O18-N18),0) -> 0 | R18: =IF(L18>O18,L18-O18,0) -> 0 | S18: =R18*Parametres!$B$26 -> 0 | T18: =R18*Parametres!$B$26 -> 0 | U18: =P18+S18 -> 16273.781 | V18: =Q18+T18 -> 0 | W18: =L18-U18-V18 -> 0 | X18: =X17+W18 -> 69487.65
