Workbook

Sheet Clinique Veta

Sheet Résultats - Veta
G1: 1
A2: CLINIQUE VÉTÉRINAIRE VETA (ACQUISITION DE CLINIQUE VÉTÉRINAIRE VALLEYFIELD INC.)
A3: RÉSULTATS PRÉVISIONNELS
A4: SUR 3 ANS
C6: Année 3 | E6: Année 2 | G6: Année 1
A8: CHIFFRES D'AFFAIRES | C8: =+E8*1.02 -> 1275654.2 | E8: =+G8*1.02 -> 1250641.4 | G8: =ROUND(1202077*1.02,0) -> 1226119 | I8: Basé sur le Chiffres d'affaires de 2024, majoré de 2% annuellement
A9: .
A10: FRAIS D'EXPLOITATION
A11: Salaires et charges sociales | C11: =ROUND(+E11*1.05,0) -> 275857 | D11: =+C11/$C$8 -> 0.21624747 | E11: =ROUND(+G11*1.05,0) -> 262721 | F11: =+E11/$E$8 -> 0.21006901 | G11: =ROUND(175000-(75000*1.15)+(90*30*52)*1.15,0) -> 250210 | H11: =+G11/$G$8 -> 0.20406665 | I11: Ajusté pour augmenter le salaire de Dr. Grenier selon la LOI. Par la suite, croissance de 5% par année (pour les autres employés)
A12: Sous-traitance | C12: =ROUND(+E12*1.05,0) -> 27563 | D12: =+C12/$C$8 -> 0.021606953 | E12: =ROUND(+G12*1.05,0) -> 26250 | F12: =+E12/$E$8 -> 0.02098923 | G12: 25000 | H12: =+G12/$G$8 -> 0.020389538 | I12: Utilisation ponctuelle de sous-traitements. Environ selon le solde de 2023
A13: Fournitures | C13: =ROUND(+C8*'Hypothèses - Veta'!$C$8,0) -> 341333 | D13: =+C13/$C$8 -> 0.26757486 | E13: =ROUND(+E8*'Hypothèses - Veta'!$C$8,0) -> 334640 | F13: =+E13/$E$8 -> 0.26757471 | G13: =ROUND(+G8*'Hypothèses - Veta'!$C$8,0) -> 328079 | H13: =+G13/$G$8 -> 0.26757517 | I13: Taux de 26,76% du Chiffre d'affaires. Moyenne des 4 derniers exercices de la Clinique du Dr. Grenier
A14: Frais de laboratoires | C14: =ROUND('Hypothèses - Veta'!$C$16*'Résultats - Veta'!C8,0) -> 25035 | D14: =+C14/$C$8 -> 0.019625224 | E14: =ROUND('Hypothèses - Veta'!$C$16*'Résultats - Veta'!E8,0) -> 24544 | F14: =+E14/$E$8 -> 0.01962513 | G14: =ROUND('Hypothèses - Veta'!$C$16*'Résultats - Veta'!G8,0) -> 24063 | H14: =+G14/$G$8 -> 0.019625338 | I14: Taux de 1,96% du Chiffre d'affaires. Moyenne des 4 derniers exercices de la Clinique du Dr. Grenier
A15: Loyer | C15: ='Résultats - Immo'!D9 -> 70000 | D15: =+C15/$C$8 -> 0.054873805 | E15: ='Résultats - Immo'!E9 -> 70000 | F15: =+E15/$E$8 -> 0.055971281 | G15: ='Résultats - Immo'!F9 -> 70000 | H15: =+G15/$G$8 -> 0.057090707 | I15: 70 000$ par année (pour couvrir les dépenses et services de la dette de la société immo)
A16: Énergie | C16: =ROUND(+E16*1.05,0) -> 22050 | D16: =+C16/$C$8 -> 0.017285249 | E16: =ROUND(+G16*1.05,0) -> 21000 | F16: =+E16/$E$8 -> 0.016791384 | G16: 20000 | H16: =+G16/$G$8 -> 0.01631163 | I16: Année 1 basé sur la moyenne de 2022 et 2023. Ensuite, croissance de 5% par année
A17: Télécommunications | C17: =ROUND(+E17*1.05,0) -> 6615 | D17: =+C17/$C$8 -> 0.0051855746 | E17: =ROUND(+G17*1.05,0) -> 6300 | F17: =+E17/$E$8 -> 0.0050374153 | G17: =500*12 -> 6000 | H17: =+G17/$G$8 -> 0.0048934891 | I17: 500$ par mois pour internet, téléphonie et cellulaire et croissance de 5% par année
A18: Frais de bureau | C18: =ROUND(+E18*1.05,0) -> 8083 | D18: =+C18/$C$8 -> 0.0063363566 | E18: =ROUND(+G18*1.05,0) -> 7698 | F18: =+E18/$E$8 -> 0.0061552417 | G18: =ROUND('Hypothèses - Veta'!C25,0) -> 7331 | H18: =+G18/$G$8 -> 0.0059790281 | I18: Moyenne des 4 derniers exercices et croissance de 5% par année
A19: Entretien et réparations | C19: =ROUND(+E19*1.05,0) -> 10249 | D19: =+C19/$C$8 -> 0.0080343089 | E19: =ROUND(+G19*1.05,0) -> 9761 | F19: =+E19/$E$8 -> 0.0078047953 | G19: =ROUND('Hypothèses - Veta'!D25,0) -> 9296 | H19: =+G19/$G$8 -> 0.0075816458 | I19: Moyenne des 4 derniers exercices et croissance de 5% par année
A20: Assurances | C20: =ROUND(+E20*1.05,0) -> 3308 | D20: =+C20/$C$8 -> 0.0025931792 | E20: =ROUND(+G20*1.05,0) -> 3150 | F20: =+E20/$E$8 -> 0.0025187076 | G20: 3000 | H20: =+G20/$G$8 -> 0.0024467446 | I20: Au jugement, assurance entreprise (assurance bâtiment dans société immobilière)
A21: Taxes et permis | C21: =ROUND(+E21*1.05,0) -> 1924 | D21: =+C21/$C$8 -> 0.0015082457 | E21: =ROUND(+G21*1.05,0) -> 1832 | F21: =+E21/$E$8 -> 0.0014648484 | G21: =ROUND('Hypothèses - Veta'!F25,0) -> 1745 | H21: =+G21/$G$8 -> 0.0014231898 | I21: Moyenne des 4 derniers exercices et croissance de 5% par année
A22: Frais de déplacements | C22: =ROUND(+E22*1.05,0) -> 5671 | D22: =+C22/$C$8 -> 0.0044455621 | E22: =ROUND(+G22*1.05,0) -> 5401 | F22: =+E22/$E$8 -> 0.0043185841 | G22: =ROUND('Hypothèses - Veta'!G25,0) -> 5144 | H22: =+G22/$G$8 -> 0.0041953513 | I22: Moyenne des 4 derniers exercices et croissance de 5% par année
A23: Publicité | C23: =ROUND(+E23*1.05,0) -> 5692 | D23: =+C23/$C$8 -> 0.0044620242 | E23: =ROUND(+G23*1.05,0) -> 5421 | F23: =+E23/$E$8 -> 0.0043345759 | G23: =ROUND('Hypothèses - Veta'!H25,0) -> 5163 | H23: =+G23/$G$8 -> 0.0042108474 | I23: Moyenne des 4 derniers exercices et croissance de 5% par année
A24: Honoraires professionnels | C24: =ROUND(+E24*1.05,0) -> 14156 | D24: =+C24/$C$8 -> 0.011097051 | E24: =ROUND(+G24*1.05,0) -> 13482 | F24: =+E24/$E$8 -> 0.010780069 | G24: =ROUND('Hypothèses - Veta'!I25,0) -> 12840 | H24: =+G24/$G$8 -> 0.010472067 | I24: Moyenne des 4 derniers exercices et croissance de 5% par année
A25: Amortissement des immobilisations corporelles | C25: ='Hypothèses - Veta'!H41 -> 1728 | D25: =+C25/$C$8 -> 0.0013545991 | E25: ='Hypothèses - Veta'!G41 -> 2165 | F25: =+E25/$E$8 -> 0.0017311118 | G25: ='Hypothèses - Veta'!F41 -> 2716 | H25: =+G25/$G$8 -> 0.0022151194 | I25: Basé sur les immobilisations. Amorties au tx de 20% (sauf matériel informatique à 30%)
A26: Intérêts sur la dette à long terme | C26: =ROUND('Prêt - Veta'!H76+'BPV - Veta'!H76,0) -> 32640 | D26: =+C26/$C$8 -> 0.025586871 | E26: =ROUND('Prêt - Veta'!H60+'BPV - Veta'!H60,0) -> 40593 | F26: =+E26/$E$8 -> 0.032457746 | G26: =ROUND(SUM('BPV - Veta'!H44,'Prêt - Veta'!H44),0) -> 48402 | H26: =+G26/$G$8 -> 0.039475777 | I26: Selon schedule de prêt 700k$ + BPV à 5%
A27: Intérêts et frais bancaires | C27: =ROUND(0.01*C8,0) -> 12757 | D27: =+C27/$C$8 -> 0.010000359 | E27: =ROUND(0.01*E8,0) -> 12506 | F27: =+E27/$E$8 -> 0.0099996691 | G27: =ROUND(0.01*G8,0) -> 12261 | H27: =+G27/$G$8 -> 0.009999845 | I27: 1% du chiffre d'affaires (considérant les frais de transactions sur les paiements par carte)
C28: =SUM(C11:C27) -> 864661 | E28: =SUM(E11:E27) -> 847464 | G28: =SUM(G11:G27) -> 831250
A30: BÉNÉFICE AVANT IMPÔTS SUR LES BÉNÉFICES | C30: =C8-C28 -> 410993.21 | E30: =E8-E28 -> 403177.38 | G30: =G8-G28 -> 394869
A32: IMPÔTS SUR LES BÉNÉFICES
A33: Exigibles | C33: =IF(C30>500000,(500000*0.122)+((C30-500000)*0.265),ROUND(0.122*C30,0)) -> 50141 | E33: =IF(E30>500000,(500000*0.122)+((E30-500000)*0.265),ROUND(0.122*E30,0)) -> 49188 | G33: =IF(G30>500000,(500000*0.122)+((G30-500000)*0.265),ROUND(0.122*G30,0)) -> 48174 | I33: Taux de 12,20%
A35: BÉNÉFICE NET | C35: =+C30-C33 -> 360852.21 | E35: =+E30-E33 -> 353989.38 | G35: =+G30-G33 -> 346695
A37: BÉNÉFICE AVANT IMPÔT ET AMORT. (BAIA) | C37: =SUM(C35,C33,C25) -> 412721.21 | D37: =+C37/$C$8 -> 0.3235369 | E37: =SUM(E35,E33,E25) -> 405342.38 | F37: =+E37/$C$8 -> 0.31775255 | G37: =SUM(G35,G33,G25) -> 397585 | H37: =+G37/$C$8 -> 0.31167145
A38: N.B. % affiché en fonction du Chiffre d'affaires

Sheet Bilan - Veta
F1: 2
A2: ='Résultats - Veta'!A2 -> CLINIQUE VÉTÉRINAIRE VETA (ACQUISITION DE CLINIQUE VÉTÉRINAIRE VALLEYFIELD INC.)
A3: BILAN PRÉVISIONNEL
D7: ='Résultats - Veta'!C6 -> Année 3 | E7: ='Résultats - Veta'!E6 -> Année 2 | F7: ='Résultats - Veta'!G6 -> Année 1
A9: ACTIF
A10: À COURT TERME
A11: Encaisse | D11: =D37-D12-D16-D18-D13 -> 574745.59 | E11: =E37-E12-E16-E18-E13 -> 373414.38 | F11: =F37-F12-F16-F18-F13 -> 175557
A12: Comptes clients | D12: 5000 | E12: 5000 | F12: 5000 | G12: Approximatif
A13: Stocks | D13: =ROUND(0.05*'Résultats - Veta'!C8,0) -> 63783 | E13: =ROUND(0.05*'Résultats - Veta'!E8,0) -> 62532 | F13: =ROUND(0.05*'Résultats - Veta'!G8,0) -> 61306 | G13: 5% du chiffre d'affaires annuel - Correspond à la moyenne arrondie des 4 derniers exerices
D14: =SUM(D11:D13) -> 643528.59 | E14: =SUM(E11:E13) -> 440946.38 | F14: =SUM(F11:F13) -> 241863
A16: IMMOBILISATIONS CORPORELLES | D16: =+E16-'Résultats - Veta'!C25 -> 6857 | E16: =+F16-'Résultats - Veta'!E25 -> 8585 | F16: =SUM('Hypothèses - Veta'!D37:D40)-'Hypothèses - Veta'!F41 -> 10750 | G16: Aucune acquisition d'immobilisations ne seraient nécessaires lors des 3 premiers exercices
A18: ÉCART D'ACQUISITION | D18: 1000000 | E18: 1000000 | F18: 1000000 | G18: Suite à fusion d'une Middleco avec Clinique Vétérinaire Valleyfield Inc.
D20: =SUM(D14:D18) -> 1650385.6 | E20: =SUM(E14:E18) -> 1449531.4 | F20: =SUM(F14:F18) -> 1252613
A23: PASSIF
A24: À COURT TERME
A25: Créditeurs et frais courus | D25: =D13 -> 63783 | E25: =E13 -> 62532 | F25: =F13 -> 61306 | G25: 5% du chiffre d'affaires annuel - Correspond à la moyenne arrondie des 4 derniers exerices
A26: Portion court terme de la dette long terme | D26: =ROUND('Prêt - Veta'!I92,0) -> 64351 | E26: =ROUND('Prêt - Veta'!I76+100000,0) -> 161249 | F26: =ROUND('Prêt - Veta'!I60+100000,0) -> 158297 | G26: Selon schedule de prêt et BPV
D27: =SUM(D25:D26) -> 128134 | E27: =SUM(E25:E26) -> 223781 | F27: =SUM(F25:F26) -> 219603
A29: DETTE À LONG TERME | D29: =ROUND('Prêt - Veta'!J76,0)-'Bilan - Veta'!D26+'BPV - Veta'!J76 -> 460615 | E29: =ROUND('Prêt - Veta'!J60,0)-'Bilan - Veta'!E26+'BPV - Veta'!J60 -> 524966 | F29: =ROUND('Prêt - Veta'!J44,0)-F26+'BPV - Veta'!J44 -> 686215 | G29: Prêt de 700k$ à 4,95% (TP) sur 10 ans + BPV à 5% sur 3 ans (100k$ remboursé par année)
D31: =SUM(D27:D29) -> 588749 | E31: =SUM(E27:E29) -> 748747 | F31: =SUM(F27:F29) -> 905818
A33: CAPITAUX PROPRES
A34: Capital-actions | D34: 100 | E34: 100 | F34: 100
A35: Bénéfices non répartis | D35: =SUM('Résultats - Veta'!C35:G35) -> 1061536.6 | E35: =SUM('Résultats - Veta'!E35:G35) -> 700684.38 | F35: ='Résultats - Veta'!G35 -> 346695
D36: =+D34+D35 -> 1061636.6 | E36: =+E34+E35 -> 700784.38 | F36: =+F34+F35 -> 346795
D37: =+D31+D36 -> 1650385.6 | E37: =+E31+E36 -> 1449531.4 | F37: =+F31+F36 -> 1252613
F39: Au nom du conseil d'administration
F41: Administrateur
A44: Non audité - Voir avis au lecteur

Sheet Breakeven
A2: GO-DENTISTE INC.
A3: RÉSULTATS PRÉVISIONNELS
A4: SUR 3 ANS
G7: Année 2
A9: CHIFFRES D'AFFAIRES | G9: 1124170
A10: .
A11: FRAIS D'EXPLOITATION
A12: Salaires et charges sociales | G12: =0.345*G9 -> 387838.65 | H12: =+G12/$G$9 -> 0.345
A13: Honoraires des dentistes et denturologistes | G13: =ROUND(0.34*(G9*0.93)+0.4*(G9*0.07),0) -> 386939 | H13: =+G13/$G$9 -> 0.34419972
A14: Frais de laboratoire, fournitures dentaires et entretien d'équipements | G14: =ROUND(0.056*G9,-3) -> 63000 | H14: =+G14/$G$9 -> 0.056041346
A15: Loyer | G15: 131017 | H15: =+G15/$G$9 -> 0.11654554
A16: Énergie | G16: 9270 | H16: =+G16/$G$9 -> 0.0082460838
A17: Taxes et permis | G17: 1500 | H17: =+G17/$G$9 -> 0.0013343178
A18: Entretien et réparations | G18: 4447 | H18: =+G18/$G$9 -> 0.0039558074
A19: Assurances | G19: 4200 | H19: =+G19/$G$9 -> 0.0037360897
A20: Publicité | G20: 25120 | H20: =+G20/$G$9 -> 0.022345375
A21: Frais de déplacements | G21: 1030 | H21: =+G21/$G$9 -> 0.00091623153
A22: Papeterie, frais de bureau et frais informatiques | G22: 33482 | H22: =+G22/$G$9 -> 0.029783752
A23: Télécommunications | G23: 6180 | H23: =+G23/$G$9 -> 0.0054973892
A24: Honoraires professionnels | G24: 7500 | H24: =+G24/$G$9 -> 0.0066715888
A25: Amortissement des immobilisations corporelles | G25: 149740 | H25: =+G25/$G$9 -> 0.13320049
A26: Intérêts sur la dette à long terme | G26: 54920 | H26: =+G26/$G$9 -> 0.048853821
A27: Intérêts et frais bancaires | G27: 7725 | H27: =+G27/$G$9 -> 0.0068717365
G28: =SUM(G12:G27) -> 1273908.6
A30: BÉNÉFICE AVANT IMPÔTS SUR LES BÉNÉFICES | G30: =G9-G28 -> -149738.65
A32: IMPÔTS SUR LES BÉNÉFICES
A33: Exigibles | G33: =IF(ROUND(0.122*G30,0)<0,0,ROUND(0.122*G30,0)) -> 0
A35: BÉNÉFICE NET | G35: =+G30-G33 -> -149738.65
A37: BÉNÉFICE AVANT IMPÔT ET AMORT. (BAIA) | G37: =SUM(G35,G33,G25) -> 1.35

Sheet Hypothèses - Veta
B2: Fournitures
B4: 2024 | C4: 0.2555
B5: 2023 | C5: 0.2696
B6: 2022 | C6: 0.2779
B7: 2021 | C7: 0.2673
B8: Moyenne | C8: =AVERAGE(C4:C7) -> 0.267575
B10: Frais de laboratoires
B12: 2024 | C12: 0.0224
B13: 2023 | C13: 0.024
B14: 2022 | C14: 0.0185
B15: 2021 | C15: 0.0136
B16: Moyenne | C16: =AVERAGE(C12:C15) -> 0.019625
B18: Autres
C20: Frais de bureau | D20: Entretien et réparations | E20: Assurances | F20: Taxes et permis | G20: Frais de déplacements | H20: Publicité | I20: Honoraires professionnels
B21: 2024 | C21: 7809 | D21: 10068 | E21: 6994 | F21: 2485 | G21: 5549 | H21: 3953 | I21: 14745
B22: 2023 | C22: 6237 | D22: 11018 | E22: 6311 | F22: 1836 | G22: 5581 | H22: 5767 | I22: 13266
B23: 2022 | C23: 6240 | D23: 7544 | E23: 5905 | F23: 1407 | G23: 4806 | H23: 5690 | I23: 11925
B24: 2021 | C24: 9038 | D24: 8553 | E24: 5537 | F24: 1250 | G24: 4640 | H24: 5242 | I24: 11425
B25: Moyenne | C25: =AVERAGE(C21:C24) -> 7331 | D25: =AVERAGE(D21:D24) -> 9295.75 | E25: =AVERAGE(E21:E24) -> 6186.75 | F25: =AVERAGE(F21:F24) -> 1744.5 | G25: =AVERAGE(G21:G24) -> 5144 | H25: =AVERAGE(H21:H24) -> 5163 | I25: =AVERAGE(I21:I24) -> 12840.25
B27: Niveau de stock
C29: 2024 | D29: 2023 | E29: 2022 | F29: 2021
B30: Chiffres d'affaires | C30: 1202077 | D30: 1214957 | E30: 1147980 | F30: 1193976
B31: Stocks | C31: 56954 | D31: 61128 | E31: 60295 | F31: 51969
C32: =+C31/C30 -> 0.04737966 | D32: =+D31/D30 -> 0.050312892 | E32: =+E31/E30 -> 0.052522692 | F32: =+F31/F30 -> 0.043526001
B34: Immobilisations
D36: 2024 net | F36: Année 1 | G36: Année 2 | H36: Année 3
B37: Équipement méd. | D37: =10258 -> 10258 | E37: 0.2 | F37: =+ROUND(D37*E37,0) -> 2052 | G37: =ROUND((D37-F37)*E37,0) -> 1641 | H37: =ROUND((D37-F37-G37)*E37,0) -> 1313
B38: Mobilier | D38: 498 | E38: 0.2 | F38: =+ROUND(D38*E38,0) -> 100 | G38: =ROUND((D38-F38)*E38,0) -> 80 | H38: =ROUND((D38-F38-G38)*E38,0) -> 64
B39: Enseigne | D39: =2494 -> 2494 | E39: 0.2 | F39: =+ROUND(D39*E39,0) -> 499 | G39: =ROUND((D39-F39)*E39,0) -> 399 | H39: =ROUND((D39-F39-G39)*E39,0) -> 319
B40: Matériel informatique | D40: =216 -> 216 | E40: 0.3 | F40: =+ROUND(D40*E40,0) -> 65 | G40: =ROUND((D40-F40)*E40,0) -> 45 | H40: =ROUND((D40-F40-G40)*E40,0) -> 32
F41: =SUM(F37:F40) -> 2716 | G41: =SUM(G37:G40) -> 2165 | H41: =SUM(H37:H40) -> 1728
B43: Créditeurs
C45: 2024 | D45: 2023 | E45: 2022 | F45: 2021
B46: Chiffres d'affaires | C46: 1202077 | D46: 1214957 | E46: 1147980 | F46: 1193976
B47: Créditeurs | C47: 42924 | D47: 54915 | E47: 50848 | F47: 55711
C48: =+C47/C46 -> 0.035708195 | D48: =+D47/D46 -> 0.045199131 | E48: =+E47/E46 -> 0.044293455 | F48: =+F47/F46 -> 0.046660067

Sheet Prêt - Veta
A1: ='Bilan - Immo'!A2 -> SOCIÉTÉ IMMOBILIÈRE (BÂTIMENT CLINIQUE VÉTÉRINAIRE VALLEYFIELD INC.)
A2: 45292
A4: Suivi de l'emprunt | H4: ref.
A6: Principales informations
K7: Effectuez choix
A8: Solde initial | K8: Fixe
E9: {=_xlfn.SWITCH(C10,"Fixe","Taux","Variable","TP","Variable BDC","TB")} -> TP | F9: =IF($C$10="Fixe","","+/- prime") -> +/- prime | K9: Variable
A10: Taux | C10: Variable | E10: 0.0495 | K10: Variable BDC
A12: Paiement | C12: Capital + intérêts | E12: 7407.49 | F12: Mensuel | K12: Effectuez choix
K13: Capital + intérêts
E14: Commentaire | K14: Capital seulement
A15: Ratios | C15: NON
A16: Garantie | C16: NON | K16: Effectuez choix
A17: Caution | C17: NON | K17: OUI
K18: NON
A19: Concilation du solde à la date de clôture
A21: Code de liaison | F21: Description aux ÉF:
A22: Solde au GL | E22: KK
A23: Solde selon la cédule | C23: =+J43 -> 644512.47
A24: Écart | C24: =ROUND(C22-C23,2) -> -644512.47
A26: Portion CT | C26: =+I60 -> 58297.337 | E26: A -Sommaire
A28: Cédule d'amortissement
C29: Taux | E29: Solde au début | F29: Nouvel emprunt | G29: Paiement | H29: Intérêts | I29: Capital | J29: Solde de fin
A30: 2024
A31: =EDATE($A$2,-12)+1 -> 44928 | B31: 1 | C31: =SUM($E$10:$F$10) -> 0.0495 | D31: / | E31: 700000 | G31: =MIN(IF($C$12="Capital seulement",I31+H31,$E$12),E31+F31) -> 7407.49 | H31: =(E31+F31)*C31/12 -> 2887.5 | I31: =MIN(IF($C$12="Capital seulement",$E$12,G31-H31),E31+F31) -> 4519.99 | J31: =MAX(E31-I31+F31,0) -> 695480.01
A32: =EDATE(A31,1) -> 44959 | B32: 2 | C32: =SUM($E$10:$F$10) -> 0.0495 | E32: =+J31 -> 695480.01 | F32: 0 | G32: =MIN(IF($C$12="Capital seulement",I32+H32,$E$12),E32+F32) -> 7407.49 | H32: =(E32+F32)*C32/12 -> 2868.855 | I32: =MIN(IF($C$12="Capital seulement",$E$12,G32-H32),E32+F32) -> 4538.635 | J32: =MAX(E32-I32+F32,0) -> 690941.38
A33: =EDATE(A32,1) -> 44987 | B33: 3 | C33: =SUM($E$10:$F$10) -> 0.0495 | E33: =+J32 -> 690941.38 | F33: 0 | G33: =MIN(IF($C$12="Capital seulement",I33+H33,$E$12),E33+F33) -> 7407.49 | H33: =(E33+F33)*C33/12 -> 2850.1332 | I33: =MIN(IF($C$12="Capital seulement",$E$12,G33-H33),E33+F33) -> 4557.3568 | J33: =MAX(E33-I33+F33,0) -> 686384.02
A34: =EDATE(A33,1) -> 45018 | B34: 4 | C34: =SUM($E$10:$F$10) -> 0.0495 | E34: =+J33 -> 686384.02 | F34: 0 | G34: =MIN(IF($C$12="Capital seulement",I34+H34,$E$12),E34+F34) -> 7407.49 | H34: =(E34+F34)*C34/12 -> 2831.3341 | I34: =MIN(IF($C$12="Capital seulement",$E$12,G34-H34),E34+F34) -> 4576.1559 | J34: =MAX(E34-I34+F34,0) -> 681807.86
A35: =EDATE(A34,1) -> 45048 | B35: 5 | C35: =SUM($E$10:$F$10) -> 0.0495 | E35: =+J34 -> 681807.86 | F35: 0 | G35: =MIN(IF($C$12="Capital seulement",I35+H35,$E$12),E35+F35) -> 7407.49 | H35: =(E35+F35)*C35/12 -> 2812.4574 | I35: =MIN(IF($C$12="Capital seulement",$E$12,G35-H35),E35+F35) -> 4595.0326 | J35: =MAX(E35-I35+F35,0) -> 677212.83
A36: =EDATE(A35,1) -> 45079 | B36: 6 | C36: =SUM($E$10:$F$10) -> 0.0495 | E36: =+J35 -> 677212.83 | F36: 0 | G36: =MIN(IF($C$12="Capital seulement",I36+H36,$E$12),E36+F36) -> 7407.49 | H36: =(E36+F36)*C36/12 -> 2793.5029 | I36: =MIN(IF($C$12="Capital seulement",$E$12,G36-H36),E36+F36) -> 4613.9871 | J36: =MAX(E36-I36+F36,0) -> 672598.84
A37: =EDATE(A36,1) -> 45109 | B37: 7 | C37: =SUM($E$10:$F$10) -> 0.0495 | E37: =+J36 -> 672598.84 | F37: 0 | G37: =MIN(IF($C$12="Capital seulement",I37+H37,$E$12),E37+F37) -> 7407.49 | H37: =(E37+F37)*C37/12 -> 2774.4702 | I37: =MIN(IF($C$12="Capital seulement",$E$12,G37-H37),E37+F37) -> 4633.0198 | J37: =MAX(E37-I37+F37,0) -> 667965.82
A38: =EDATE(A37,1) -> 45140 | B38: 8 | C38: =SUM($E$10:$F$10) -> 0.0495 | E38: =+J37 -> 667965.82 | F38: 0 | G38: =MIN(IF($C$12="Capital seulement",I38+H38,$E$12),E38+F38) -> 7407.49 | H38: =(E38+F38)*C38/12 -> 2755.359 | I38: =MIN(IF($C$12="Capital seulement",$E$12,G38-H38),E38+F38) -> 4652.131 | J38: =MAX(E38-I38+F38,0) -> 663313.69
A39: =EDATE(A38,1) -> 45171 | B39: 9 | C39: =SUM($E$10:$F$10) -> 0.0495 | E39: =+J38 -> 663313.69 | F39: 0 | G39: =MIN(IF($C$12="Capital seulement",I39+H39,$E$12),E39+F39) -> 7407.49 | H39: =(E39+F39)*C39/12 -> 2736.169 | I39: =MIN(IF($C$12="Capital seulement",$E$12,G39-H39),E39+F39) -> 4671.321 | J39: =MAX(E39-I39+F39,0) -> 658642.37
A40: =EDATE(A39,1) -> 45201 | B40: 10 | C40: =SUM($E$10:$F$10) -> 0.0495 | E40: =+J39 -> 658642.37 | F40: 0 | G40: =MIN(IF($C$12="Capital seulement",I40+H40,$E$12),E40+F40) -> 7407.49 | H40: =(E40+F40)*C40/12 -> 2716.8998 | I40: =MIN(IF($C$12="Capital seulement",$E$12,G40-H40),E40+F40) -> 4690.5902 | J40: =MAX(E40-I40+F40,0) -> 653951.78
A41: =EDATE(A40,1) -> 45232 | B41: 11 | C41: =SUM($E$10:$F$10) -> 0.0495 | E41: =+J40 -> 653951.78 | F41: 0 | G41: =MIN(IF($C$12="Capital seulement",I41+H41,$E$12),E41+F41) -> 7407.49 | H41: =(E41+F41)*C41/12 -> 2697.5511 | I41: =MIN(IF($C$12="Capital seulement",$E$12,G41-H41),E41+F41) -> 4709.9389 | J41: =MAX(E41-I41+F41,0) -> 649241.84
A42: =EDATE(A41,1) -> 45262 | B42: 12 | C42: =SUM($E$10:$F$10) -> 0.0495 | E42: =+J41 -> 649241.84 | F42: 0 | G42: =MIN(IF($C$12="Capital seulement",I42+H42,$E$12),E42+F42) -> 7407.49 | H42: =(E42+F42)*C42/12 -> 2678.1226 | I42: =MIN(IF($C$12="Capital seulement",$E$12,G42-H42),E42+F42) -> 4729.3674 | J42: =MAX(E42-I42+F42,0) -> 644512.47
A43: Ajustement | E43: =+J42 -> 644512.47 | G43: =MIN(IF($C$12="Capital seulement",I43+H43,$E$12),E43) -> 7407.49 | H43: =-I43 -> 0 | J43: =MAX(E43-I43+F43,0) -> 644512.47
A44: =CONCATENATE("Total exercice ",A30) -> Total exercice 2024 | G44: =SUM(G31:G43) -> 96297.37 | H44: =SUM(H31:H43) -> 33402.354 | I44: =SUM(I31:I43) -> 55487.526 | J44: =+J43 -> 644512.47
A46: =+A30+1 -> 2025 | C46: Taux | E46: Solde au début | F46: Nouvel emprunt | G46: Paiement | H46: Intérêts | I46: Capital | J46: Solde de fin
A47: =EDATE(A42,1) -> 45293 | B47: 1 | C47: =SUM($E$10:$F$10) -> 0.0495 | E47: =+J43 -> 644512.47 | F47: 0 | G47: =MIN(IF($C$12="Capital seulement",I47+H47,$E$12),E47+F47) -> 7407.49 | H47: =(E47+F47)*C47/12 -> 2658.614 | I47: =MIN(IF($C$12="Capital seulement",$E$12,G47-H47),E47+F47) -> 4748.876 | J47: =MAX(E47-I47+F47,0) -> 639763.6
...

Sheet BPV - Veta
A1: ='Bilan - Immo'!A2 -> SOCIÉTÉ IMMOBILIÈRE (BÂTIMENT CLINIQUE VÉTÉRINAIRE VALLEYFIELD INC.)
A2: 45292
A4: Suivi de l'emprunt | H4: ref.
A6: Principales informations
K7: Effectuez choix
A8: Solde initial | K8: Fixe
E9: {=_xlfn.SWITCH(C10,"Fixe","Taux","Variable","TP","Variable BDC","TB")} -> TP | F9: =IF($C$10="Fixe","","+/- prime") -> +/- prime | K9: Variable
A10: Taux | C10: Variable | E10: 0.05 | K10: Variable BDC
A12: Paiement | C12: Capital + intérêts | F12: Mensuel | K12: Effectuez choix
K13: Capital + intérêts
E14: Commentaire | K14: Capital seulement
A15: Ratios | C15: NON
A16: Garantie | C16: NON | K16: Effectuez choix
A17: Caution | C17: NON | K17: OUI
K18: NON
A19: Concilation du solde à la date de clôture
A21: Code de liaison | F21: Description aux ÉF: | M21: Tableau provenant de Annie Castonguay, RBC
A22: Solde au GL | E22: KK
A23: Solde selon la cédule | C23: =+J43 -> 200000
A24: Écart | C24: =ROUND(C22-C23,2) -> -200000
A26: Portion CT | C26: =+I60 -> 100000 | E26: A -Sommaire
A28: Cédule d'amortissement
C29: Taux | E29: Solde au début | F29: Nouvel emprunt | G29: Paiement | H29: Intérêts | I29: Capital | J29: Solde de fin
A30: 2024
A31: =EDATE($A$2,-12)+1 -> 44928 | B31: 1 | C31: =SUM($E$10:$F$10) -> 0.05 | D31: / | E31: 300000 | G31: =MIN(IF($C$12="Capital seulement",I31+H31,$E$12),E31+F31) -> 300000 | H31: =(E31+F31)*C31/12 -> 1250 | J31: =MAX(E31-I31+F31,0) -> 300000
A32: =EDATE(A31,1) -> 44959 | B32: 2 | C32: =SUM($E$10:$F$10) -> 0.05 | E32: =+J31 -> 300000 | F32: 0 | G32: =MIN(IF($C$12="Capital seulement",I32+H32,$E$12),E32+F32) -> 300000 | H32: =(E32+F32)*C32/12 -> 1250 | J32: =MAX(E32-I32+F32,0) -> 300000
A33: =EDATE(A32,1) -> 44987 | B33: 3 | C33: =SUM($E$10:$F$10) -> 0.05 | E33: =+J32 -> 300000 | F33: 0 | G33: =MIN(IF($C$12="Capital seulement",I33+H33,$E$12),E33+F33) -> 300000 | H33: =(E33+F33)*C33/12 -> 1250 | J33: =MAX(E33-I33+F33,0) -> 300000
A34: =EDATE(A33,1) -> 45018 | B34: 4 | C34: =SUM($E$10:$F$10) -> 0.05 | E34: =+J33 -> 300000 | F34: 0 | G34: =MIN(IF($C$12="Capital seulement",I34+H34,$E$12),E34+F34) -> 300000 | H34: =(E34+F34)*C34/12 -> 1250 | J34: =MAX(E34-I34+F34,0) -> 300000
A35: =EDATE(A34,1) -> 45048 | B35: 5 | C35: =SUM($E$10:$F$10) -> 0.05 | E35: =+J34 -> 300000 | F35: 0 | G35: =MIN(IF($C$12="Capital seulement",I35+H35,$E$12),E35+F35) -> 300000 | H35: =(E35+F35)*C35/12 -> 1250 | J35: =MAX(E35-I35+F35,0) -> 300000
A36: =EDATE(A35,1) -> 45079 | B36: 6 | C36: =SUM($E$10:$F$10) -> 0.05 | E36: =+J35 -> 300000 | F36: 0 | G36: =MIN(IF($C$12="Capital seulement",I36+H36,$E$12),E36+F36) -> 300000 | H36: =(E36+F36)*C36/12 -> 1250 | J36: =MAX(E36-I36+F36,0) -> 300000
A37: =EDATE(A36,1) -> 45109 | B37: 7 | C37: =SUM($E$10:$F$10) -> 0.05 | E37: =+J36 -> 300000 | F37: 0 | G37: =MIN(IF($C$12="Capital seulement",I37+H37,$E$12),E37+F37) -> 300000 | H37: =(E37+F37)*C37/12 -> 1250 | J37: =MAX(E37-I37+F37,0) -> 300000
A38: =EDATE(A37,1) -> 45140 | B38: 8 | C38: =SUM($E$10:$F$10) -> 0.05 | E38: =+J37 -> 300000 | F38: 0 | G38: =MIN(IF($C$12="Capital seulement",I38+H38,$E$12),E38+F38) -> 300000 | H38: =(E38+F38)*C38/12 -> 1250 | J38: =MAX(E38-I38+F38,0) -> 300000
A39: =EDATE(A38,1) -> 45171 | B39: 9 | C39: =SUM($E$10:$F$10) -> 0.05 | E39: =+J38 -> 300000 | F39: 0 | G39: =MIN(IF($C$12="Capital seulement",I39+H39,$E$12),E39+F39) -> 300000 | H39: =(E39+F39)*C39/12 -> 1250 | J39: =MAX(E39-I39+F39,0) -> 300000
A40: =EDATE(A39,1) -> 45201 | B40: 10 | C40: =SUM($E$10:$F$10) -> 0.05 | E40: =+J39 -> 300000 | F40: 0 | G40: =MIN(IF($C$12="Capital seulement",I40+H40,$E$12),E40+F40) -> 300000 | H40: =(E40+F40)*C40/12 -> 1250 | J40: =MAX(E40-I40+F40,0) -> 300000
A41: =EDATE(A40,1) -> 45232 | B41: 11 | C41: =SUM($E$10:$F$10) -> 0.05 | E41: =+J40 -> 300000 | F41: 0 | G41: =MIN(IF($C$12="Capital seulement",I41+H41,$E$12),E41+F41) -> 300000 | H41: =(E41+F41)*C41/12 -> 1250 | J41: =MAX(E41-I41+F41,0) -> 300000
A42: =EDATE(A41,1) -> 45262 | B42: 12 | C42: =SUM($E$10:$F$10) -> 0.05 | E42: =+J41 -> 300000 | F42: 0 | G42: =MIN(IF($C$12="Capital seulement",I42+H42,$E$12),E42+F42) -> 300000 | H42: =(E42+F42)*C42/12 -> 1250 | I42: 100000 | J42: =MAX(E42-I42+F42,0) -> 200000
A43: Ajustement | E43: =+J42 -> 200000 | G43: =MIN(IF($C$12="Capital seulement",I43+H43,$E$12),E43) -> 200000 | H43: =-I43 -> 0 | J43: =MAX(E43-I43+F43,0) -> 200000
A44: =CONCATENATE("Total exercice ",A30) -> Total exercice 2024 | G44: =SUM(G31:G43) -> 3800000 | H44: =SUM(H31:H43) -> 15000 | I44: =SUM(I31:I43) -> 100000 | J44: =+J43 -> 200000
A46: =+A30+1 -> 2025 | C46: Taux | E46: Solde au début | F46: Nouvel emprunt | G46: Paiement | H46: Intérêts | I46: Capital | J46: Solde de fin
A47: =EDATE(A42,1) -> 45293 | B47: 1 | C47: =SUM($E$10:$F$10) -> 0.05 | E47: =+J43 -> 200000 | F47: 0 | G47: =MIN(IF($C$12="Capital seulement",I47+H47,$E$12),E47+F47) -> 200000 | H47: =(E47+F47)*C47/12 -> 833.33333 | J47: =MAX(E47-I47+F47,0) -> 200000
...

Sheet Immo

Sheet Résultats - Immo
F1: 1
A2: SOCIÉTÉ IMMOBILIÈRE (BÂTIMENT CLINIQUE VÉTÉRINAIRE VALLEYFIELD INC.)
A3: RÉSULTATS PRÉVISIONNELS
A4: SUR 3 ANS
D7: Année 3 | E7: Année 2 | F7: Année 1
A9: PRODUITS | D9: 70000 | E9: 70000 | F9: 70000 | G9: Initialement planifié à 62 500$ par année par Jean-Samuel - Réajusté pour couvrir les dépenses
A10: .
A11: FRAIS D'EXPLOITATION
A12: Taxes et licences | D12: =ROUND(E12*1.05,0) -> 11771 | E12: =ROUND(F12*1.05,0) -> 11210 | F12: 10676 | G12: Selon taxes municipales 2025 + 5% par année
A13: Assurances | D13: =ROUND(E13*1.05,0) -> 7161 | E13: =ROUND(F13*1.05,0) -> 6820 | F13: 6495 | G13: Selon rapport d'évaluation + 5% par année
A14: Honoraires professionnels | D14: 3500 | E14: 3500 | F14: =3000+1500 -> 4500 | G14: 3 000$ honoraires Ringuette + 1 500$ pour incorporation Année 1. 3 500$ année 2 et 3 par la suite
A15: Amortissement des immobilisations corporelles | D15: =-'Hypothèses - Immo'!J22 -> 15128 | E15: =-'Hypothèses - Immo'!J15 -> 15758 | F15: =-'Hypothèses - Immo'!J8 -> 8040 | G15: Selon tableau d'amortissement
A16: Intérêts sur la dette à long terme | D16: =ROUND('Prêt - Immo'!H76,0) -> 31407 | E16: =ROUND('Prêt - Immo'!H60,0) -> 32147 | F16: =ROUND('Prêt - Immo'!H44,0) -> 32852 | G16: Selon schedule de prêt
A17: Intérêts et frais bancaires | D17: 1000 | E17: 1000 | F17: 1000 | G17: Au jugement
D18: =SUM(D12:D17) -> 69967 | E18: =SUM(E12:E17) -> 70435 | F18: =SUM(F12:F17) -> 63563
A20: BÉNÉFICE AVANT IMPÔTS SUR LES BÉNÉFICES | D20: =D9-D18 -> 33 | E20: =E9-E18 -> -435 | F20: =F9-F18 -> 6437
A22: IMPÔTS SUR LES BÉNÉFICES
A23: Exigibles | D23: =IF(ROUND(0.265*D20,0)<0,0,ROUND(0.265*D20,0)) -> 9 | E23: =IF(ROUND(0.265*E20,0)<0,0,ROUND(0.265*E20,0)) -> 0 | F23: =IF(ROUND(0.265*F20,0)<0,0,ROUND(0.265*F20,0)) -> 1706 | G23: Taux de 26,5% utilisé
A25: BÉNÉFICE NET | D25: =+D20-D23 -> 24 | E25: =+E20-E23 -> -435 | F25: =+F20-F23 -> 4731
A27: BÉNÉFICE AVANT IMPÔT ET AMORT. (BAIA) | D27: =SUM(D25,D23,D15) -> 15161 | E27: =SUM(E25,E23,E15) -> 15323 | F27: =SUM(F25,F23,F15) -> 14477

Sheet Bilan - Immo
F1: 2
A2: ='Résultats - Immo'!A2 -> SOCIÉTÉ IMMOBILIÈRE (BÂTIMENT CLINIQUE VÉTÉRINAIRE VALLEYFIELD INC.)
A3: BILAN PRÉVISIONNEL
D7: ='Résultats - Immo'!D7 -> Année 3 | E7: ='Résultats - Immo'!E7 -> Année 2 | F7: ='Résultats - Immo'!F7 -> Année 1
A9: ACTIF
A10: À COURT TERME
A11: Encaisse | D11: =+D32-D13 -> 3051 | E11: =+E32-E13 -> 3259 | F11: =+F32-F13 -> 2056
A13: IMMOBILISATIONS CORPORELLES | D13: =+'Hypothèses - Immo'!G22+'Hypothèses - Immo'!K22 -> 631074 | E13: =+'Hypothèses - Immo'!G15+'Hypothèses - Immo'!K15 -> 646202 | F13: ='Hypothèses - Immo'!G8+'Hypothèses - Immo'!K8 -> 661960
D15: =SUM(D11:D13) -> 634125 | E15: =SUM(E11:E13) -> 649461 | F15: =SUM(F11:F13) -> 664016
A18: PASSIF
A19: À COURT TERME
A20: Créditeurs et frais courus | D20: 3500 | E20: 3500 | F20: 3000
A21: Portion court terme de la dette long terme | D21: =ROUND('Prêt - Immo'!I92,0) -> 16138 | E21: =ROUND('Prêt - Immo'!I76,0) -> 15360 | F21: =ROUND('Prêt - Immo'!I60,0) -> 14620
D22: =SUM(D20:D21) -> 19638 | E22: =SUM(E20:E21) -> 18860 | F22: =SUM(F20:F21) -> 17620
A24: DETTE À LONG TERME | D24: =ROUND('Prêt - Immo'!J76,0)-D21 -> 609967 | E24: =ROUND('Prêt - Immo'!J60,0)-E21 -> 626105 | F24: =ROUND('Prêt - Immo'!J44,0)-F21 -> 641465 | G24: Prêt sur 25 ans, 4,95 % (TP)
D26: =SUM(D22:D24) -> 629605 | E26: =SUM(E22:E24) -> 644965 | F26: =SUM(F22:F24) -> 659085
A28: CAPITAUX PROPRES
A29: Capital-actions | D29: 200 | E29: 200 | F29: 200
A30: Bénéfices non répartis | D30: =+E30+'Résultats - Immo'!D25 -> 4320 | E30: =F30+'Résultats - Immo'!E25 -> 4296 | F30: ='Résultats - Immo'!F25 -> 4731
D31: =+D29+D30 -> 4520 | E31: =+E29+E30 -> 4496 | F31: =+F29+F30 -> 4931
D32: =+D26+D31 -> 634125 | E32: =+E26+E31 -> 649461 | F32: =+F26+F31 -> 664016
F36: Au nom du conseil d'administration
F38: Administrateur
A41: Non audité - Voir avis au lecteur

Sheet Hypothèses - Immo
B2: Immobilisations
E4: Solde début | F4: Acquisition | G4: Solde Année 1 | I4: Am. Cul début | J4: Amortissement | K4: Am. Cul fin Année 1
B5: Bâtiment | E5: 0 | F5: =670000-F6 -> 402000 | G5: =SUM(E5:F5) -> 402000 | I5: 0 | J5: =ROUND(-G5*0.04*0.5,0) -> -8040 | K5: =SUM(I5:J5) -> -8040
B6: Terrain | E6: 0 | F6: =ROUND(670000*(211400/527600),-3) -> 268000 | G6: =SUM(E6:F6) -> 268000 | I6: 0 | J6: 0 | K6: 0
G8: =SUM(G5:G7) -> 670000 | J8: =SUM(J5:J7) -> -8040 | K8: =SUM(K5:K7) -> -8040
E10: Solde début | F10: Acquisition | G10: Solde Année 2 | I10: Am. Cul début | J10: Amortissement | K10: Am. Cul fin Année 2
B11: Bâtiment | E11: =G5 -> 402000 | F11: 0 | G11: =SUM(E11:F11) -> 402000 | I11: =K5 -> -8040 | J11: =ROUND((-G11-I11)*0.04,0) -> -15758 | K11: =SUM(I11:J11) -> -23798
B12: Terrain | E12: =G6 -> 268000 | G12: =SUM(E12:E12) -> 268000 | I12: 0 | J12: 0 | K12: 0
G15: =SUM(G11:G14) -> 670000 | J15: =SUM(J11:J14) -> -15758 | K15: =SUM(K11:K14) -> -23798
E17: Solde début | F17: Acquisition | G17: Solde Année 3 | I17: Am. Cul début | J17: Amortissement | K17: Am. Cul fin Année 3
B18: Bâtiment | E18: =G11 -> 402000 | F18: 0 | G18: =SUM(E18:F18) -> 402000 | I18: =K11 -> -23798 | J18: =ROUND((-G18-I18)*0.04,0) -> -15128 | K18: =SUM(I18:J18) -> -38926
B19: Terrain | E19: =G12 -> 268000 | G19: =SUM(E19:E19) -> 268000 | I19: 0 | J19: 0 | K19: 0
G22: =SUM(G18:G21) -> 670000 | J22: =SUM(J18:J21) -> -15128 | K22: =SUM(K18:K21) -> -38926

Sheet Prêt - Immo
A1: ='Bilan - Immo'!A2 -> SOCIÉTÉ IMMOBILIÈRE (BÂTIMENT CLINIQUE VÉTÉRINAIRE VALLEYFIELD INC.)
A2: 45292
A4: Suivi de l'emprunt | H4: ref.
A6: Principales informations
K7: Effectuez choix
A8: Solde initial | K8: Fixe
E9: {=_xlfn.SWITCH(C10,"Fixe","Taux","Variable","TP","Variable BDC","TB")} -> TP | F9: =IF($C$10="Fixe","","+/- prime") -> +/- prime | K9: Variable
A10: Taux | C10: Variable | E10: 0.0495 | K10: Variable BDC
A12: Paiement | C12: Capital + intérêts | E12: 3897.26 | F12: Mensuel | K12: Effectuez choix
K13: Capital + intérêts
E14: Commentaire | K14: Capital seulement
A15: Ratios | C15: NON
A16: Garantie | C16: NON | K16: Effectuez choix
A17: Caution | C17: NON | K17: OUI
K18: NON
A19: Concilation du solde à la date de clôture
A21: Code de liaison | F21: Description aux ÉF:
A22: Solde au GL | E22: KK
A23: Solde selon la cédule | C23: =+J43 -> 656085
A24: Écart | C24: =ROUND(C22-C23,2) -> -656085
A26: Portion CT | C26: =+I60 -> 14619.637 | E26: A -Sommaire
A28: Cédule d'amortissement
C29: Taux | E29: Solde au début | F29: Nouvel emprunt | G29: Paiement | H29: Intérêts | I29: Capital | J29: Solde de fin
A30: 2024
A31: =EDATE($A$2,-12)+1 -> 44928 | B31: 1 | C31: =SUM($E$10:$F$10) -> 0.0495 | D31: / | E31: 670000 | G31: =MIN(IF($C$12="Capital seulement",I31+H31,$E$12),E31+F31) -> 3897.26 | H31: =(E31+F31)*C31/12 -> 2763.75 | I31: =MIN(IF($C$12="Capital seulement",$E$12,G31-H31),E31+F31) -> 1133.51 | J31: =MAX(E31-I31+F31,0) -> 668866.49
A32: =EDATE(A31,1) -> 44959 | B32: 2 | C32: =SUM($E$10:$F$10) -> 0.0495 | E32: =+J31 -> 668866.49 | F32: 0 | G32: =MIN(IF($C$12="Capital seulement",I32+H32,$E$12),E32+F32) -> 3897.26 | H32: =(E32+F32)*C32/12 -> 2759.0743 | I32: =MIN(IF($C$12="Capital seulement",$E$12,G32-H32),E32+F32) -> 1138.1857 | J32: =MAX(E32-I32+F32,0) -> 667728.3
A33: =EDATE(A32,1) -> 44987 | B33: 3 | C33: =SUM($E$10:$F$10) -> 0.0495 | E33: =+J32 -> 667728.3 | F33: 0 | G33: =MIN(IF($C$12="Capital seulement",I33+H33,$E$12),E33+F33) -> 3897.26 | H33: =(E33+F33)*C33/12 -> 2754.3793 | I33: =MIN(IF($C$12="Capital seulement",$E$12,G33-H33),E33+F33) -> 1142.8807 | J33: =MAX(E33-I33+F33,0) -> 666585.42
A34: =EDATE(A33,1) -> 45018 | B34: 4 | C34: =SUM($E$10:$F$10) -> 0.0495 | E34: =+J33 -> 666585.42 | F34: 0 | G34: =MIN(IF($C$12="Capital seulement",I34+H34,$E$12),E34+F34) -> 3897.26 | H34: =(E34+F34)*C34/12 -> 2749.6649 | I34: =MIN(IF($C$12="Capital seulement",$E$12,G34-H34),E34+F34) -> 1147.5951 | J34: =MAX(E34-I34+F34,0) -> 665437.83
A35: =EDATE(A34,1) -> 45048 | B35: 5 | C35: =SUM($E$10:$F$10) -> 0.0495 | E35: =+J34 -> 665437.83 | F35: 0 | G35: =MIN(IF($C$12="Capital seulement",I35+H35,$E$12),E35+F35) -> 3897.26 | H35: =(E35+F35)*C35/12 -> 2744.931 | I35: =MIN(IF($C$12="Capital seulement",$E$12,G35-H35),E35+F35) -> 1152.329 | J35: =MAX(E35-I35+F35,0) -> 664285.5
A36: =EDATE(A35,1) -> 45079 | B36: 6 | C36: =SUM($E$10:$F$10) -> 0.0495 | E36: =+J35 -> 664285.5 | F36: 0 | G36: =MIN(IF($C$12="Capital seulement",I36+H36,$E$12),E36+F36) -> 3897.26 | H36: =(E36+F36)*C36/12 -> 2740.1777 | I36: =MIN(IF($C$12="Capital seulement",$E$12,G36-H36),E36+F36) -> 1157.0823 | J36: =MAX(E36-I36+F36,0) -> 663128.42
A37: =EDATE(A36,1) -> 45109 | B37: 7 | C37: =SUM($E$10:$F$10) -> 0.0495 | E37: =+J36 -> 663128.42 | F37: 0 | G37: =MIN(IF($C$12="Capital seulement",I37+H37,$E$12),E37+F37) -> 3897.26 | H37: =(E37+F37)*C37/12 -> 2735.4047 | I37: =MIN(IF($C$12="Capital seulement",$E$12,G37-H37),E37+F37) -> 1161.8553 | J37: =MAX(E37-I37+F37,0) -> 661966.56
A38: =EDATE(A37,1) -> 45140 | B38: 8 | C38: =SUM($E$10:$F$10) -> 0.0495 | E38: =+J37 -> 661966.56 | F38: 0 | G38: =MIN(IF($C$12="Capital seulement",I38+H38,$E$12),E38+F38) -> 3897.26 | H38: =(E38+F38)*C38/12 -> 2730.6121 | I38: =MIN(IF($C$12="Capital seulement",$E$12,G38-H38),E38+F38) -> 1166.6479 | J38: =MAX(E38-I38+F38,0) -> 660799.91
A39: =EDATE(A38,1) -> 45171 | B39: 9 | C39: =SUM($E$10:$F$10) -> 0.0495 | E39: =+J38 -> 660799.91 | F39: 0 | G39: =MIN(IF($C$12="Capital seulement",I39+H39,$E$12),E39+F39) -> 3897.26 | H39: =(E39+F39)*C39/12 -> 2725.7996 | I39: =MIN(IF($C$12="Capital seulement",$E$12,G39-H39),E39+F39) -> 1171.4604 | J39: =MAX(E39-I39+F39,0) -> 659628.45
A40: =EDATE(A39,1) -> 45201 | B40: 10 | C40: =SUM($E$10:$F$10) -> 0.0495 | E40: =+J39 -> 659628.45 | F40: 0 | G40: =MIN(IF($C$12="Capital seulement",I40+H40,$E$12),E40+F40) -> 3897.26 | H40: =(E40+F40)*C40/12 -> 2720.9674 | I40: =MIN(IF($C$12="Capital seulement",$E$12,G40-H40),E40+F40) -> 1176.2926 | J40: =MAX(E40-I40+F40,0) -> 658452.16
A41: =EDATE(A40,1) -> 45232 | B41: 11 | C41: =SUM($E$10:$F$10) -> 0.0495 | E41: =+J40 -> 658452.16 | F41: 0 | G41: =MIN(IF($C$12="Capital seulement",I41+H41,$E$12),E41+F41) -> 3897.26 | H41: =(E41+F41)*C41/12 -> 2716.1152 | I41: =MIN(IF($C$12="Capital seulement",$E$12,G41-H41),E41+F41) -> 1181.1448 | J41: =MAX(E41-I41+F41,0) -> 657271.02
A42: =EDATE(A41,1) -> 45262 | B42: 12 | C42: =SUM($E$10:$F$10) -> 0.0495 | E42: =+J41 -> 657271.02 | F42: 0 | G42: =MIN(IF($C$12="Capital seulement",I42+H42,$E$12),E42+F42) -> 3897.26 | H42: =(E42+F42)*C42/12 -> 2711.2429 | I42: =MIN(IF($C$12="Capital seulement",$E$12,G42-H42),E42+F42) -> 1186.0171 | J42: =MAX(E42-I42+F42,0) -> 656085
A43: Ajustement | E43: =+J42 -> 656085 | G43: =MIN(IF($C$12="Capital seulement",I43+H43,$E$12),E43) -> 3897.26 | H43: =-I43 -> 0 | J43: =MAX(E43-I43+F43,0) -> 656085
A44: =CONCATENATE("Total exercice ",A30) -> Total exercice 2024 | G44: =SUM(G31:G43) -> 50664.38 | H44: =SUM(H31:H43) -> 32852.119 | I44: =SUM(I31:I43) -> 13915.001 | J44: =+J43 -> 656085
A46: =+A30+1 -> 2025 | C46: Taux | E46: Solde au début | F46: Nouvel emprunt | G46: Paiement | H46: Intérêts | I46: Capital | J46: Solde de fin
A47: =EDATE(A42,1) -> 45293 | B47: 1 | C47: =SUM($E$10:$F$10) -> 0.0495 | E47: =+J43 -> 656085 | F47: 0 | G47: =MIN(IF($C$12="Capital seulement",I47+H47,$E$12),E47+F47) -> 3897.26 | H47: =(E47+F47)*C47/12 -> 2706.3506 | I47: =MIN(IF($C$12="Capital seulement",$E$12,G47-H47),E47+F47) -> 1190.9094 | J47: =MAX(E47-I47+F47,0) -> 654894.09
...

Sheet Bilan 2
F1: 5
A2: GROUPE FRÉDÉRIC LAFLEUR
A4: BILAN CUMULÉ
A6: AU 30 SEPTEMBRE 2021
E8: 2021 | F8: 2020
A10: PASSIF
A11: À COURT TERME
A12: Découvert bancaire | E12: 0 | F12: 0
A13: Emprunts bancaires | E13: 0 | F13: 120416
A14: Créditeurs | E14: 1278833 | F14: 1077727
A15: Dû à un administrateur, sans intérêt | E15: 2059 | F15: 5898
A16: Dû à une société ayant un administrateur commun | E16: 25914 | F16: 0
A17: Impôts sur les bénéfices à payer | E17: 189792 | F17: 152071
A18: Dette à long terme échéant au cours du prochain exercice | E18: 1302865 | F18: 797047
A19: Obligations à court terme découlant de contrats de location-acquisition | E19: 15914 | F19: 30904
E20: =SUM(E12:E19) -> 2815377 | F20: =SUM(F12:F19) -> 2184063
A22: DETTE À LONG TERME | E22: 13300937 | F22: 7221556
A24: OBLIGATIONS DÉCOULANT DE CONTRATS DE LOCATION-ACQUISITION | E24: 3231 | F24: 38083
E25: =+E22+E24+E20 -> 16119545 | F25: =+F22+F24+F20 -> 9443702
A27: CAPITAUX PROPRES
A28: Capital-actions | E28: 1329 | F28: =3174-2174 -> 1000
A29: Bénéfices non répartis | E29: =+#REF! -> #REF! | F29: =+#REF! -> #REF!
E30: =+E28+E29 -> #REF! | F30: =+F28+F29 -> #REF!
E32: =+E20+E22+E24+E30 -> #REF! | F32: =+F20+F22+F24+F30 -> #REF!
F36: AU NOM DU CONSEIL D'ADMINISTRATION
F38: ____________________________ Administrateur

Sheet Note
F1: 5
A2: SYNDICAT DES COPROPRIÉTAIRES 165-187 JOSEPH-CARRIER
A4: NOTES COMPLÉMENTAIRES
A6: AU 31 DÉCEMBRE 2022
A8: 1) STATUTS CONSTITUTIFS ET NATURE DES ACTIVITÉS
A10: Le syndicat de copropriété est constitué en vertu du Code civil du Québec. Au sens des lois fédérale et provinciale de l'impôt sur le revenu, il est un organisme sans but lucratif et est exempté de l'impôt sur les bénéfices. Ce syndicat a pour objet de régir les espaces communs des condos 165-187 Joseph-Carrier à Vaudreuil-Dorion.
A12: 2) MÉTHODE DE COMPTABILITÉ APPLIQUÉE DANS LA PRÉPARATION DES INFORMATIONS FINANCIÈRES
A14: La méthode de comptabilité appliquée dans la préparation des informations financières se fonde sur le coût historique, compte tenu des opérations de trésorerie et de l'ajout des éléments suivants:
A15: - Comptes à recevoir;
A16: - Fournisseurs et charges à payer.
A18: 2) CHANGEMENT DE PRÉSENTATION
A20: Certains chiffres de l'exercice 2021 ont été reclassés afin de rendre leur présentation identique à celle de l'exercice 2022.
