Workbook
Name Honoraire: #REF!

Sheet Medzy P&L Summary
C1: Medzy Inc - Summary Profit and Loss Statement
D3: Fiscal Year Ending On
D4: Oct 31 2021 | E4: Oct 31 2022 | F4: Oct 31 2023 | G4: Oct 31 2024 | H4: Oct 31 2025 | I4: Oct 31 2026 | J4: Oct 31 2027 | K4: Oct 31 2028
B5: REVENUES & KPIS | D5: ACTUALS | G5: FORECASTS
C6: New Clients | E6: =SUM('P&L Medzy '!F10:Q10) -> 0 | F6: =SUM('P&L Medzy '!P10:AA10) -> 461.42857 | G6: =SUM('P&L Medzy '!AD10:AO10) -> 12909.77 | H6: =SUM('P&L Medzy '!AP10:BA10) -> 32575.341 | I6: =SUM('P&L Medzy '!BB10:BM10) -> 54208.941 | J6: =SUM('P&L Medzy '!BN10:BY10) -> 73562.541 | K6: =SUM('P&L Medzy '!BZ10:CK10) -> 92916.141
C7: Churn | E7: =SUM('P&L Medzy '!F11:Q11) -> 0 | F7: =SUM('P&L Medzy '!P11:AA11) -> 231.8558 | G7: =SUM('P&L Medzy '!AD11:AO11) -> 1557.4311 | H7: =SUM('P&L Medzy '!AP11:BA11) -> 5199.0281 | I7: =SUM('P&L Medzy '!BB11:BM11) -> 12824.986 | J7: =SUM('P&L Medzy '!BN11:BY11) -> 22808.062 | K7: =SUM('P&L Medzy '!BZ11:CK11) -> 34422.459
C8: Total Clients | E8: ='P&L Medzy '!Q12 -> 0 | F8: ='P&L Medzy '!AA12 -> 4645.6078 | G8: ='P&L Medzy '!AO12 -> 15819.69 | H8: ='P&L Medzy '!BA12 -> 42560.003 | I8: =SUM('P&L Medzy '!BB12:BM12) -> 740659.65 | J8: =SUM('P&L Medzy '!BN12:BY12) -> 1240124.2 | K8: =SUM('P&L Medzy '!BZ12:CK12) -> 1832417.5
C9: ='P&L Medzy '!B13 -> Pharmacy Revenues | D9: 2869230.8 | E9: 4030102.3 | F9: =SUM('P&L Medzy '!P13:AA13) -> 4942683.8 | G9: =SUM('P&L Medzy '!AD13:AO13) -> 8978508.2 | H9: =SUM('P&L Medzy '!AP13:BA13) -> 27076732 | I9: =SUM('P&L Medzy '!BB13:BM13) -> 56566517 | J9: =SUM('P&L Medzy '!BN13:BY13) -> 94205353 | K9: =SUM('P&L Medzy '!BZ13:CK13) -> 1.3774834e+08
C11: Medzy Platform Revenues | D11: 502115.3 | E11: 706554.49 | F11: =SUM('P&L Medzy '!P16:AA16) -> 843819.37 | G11: =SUM('P&L Medzy '!AD16:AO16) -> 1445221.5 | H11: =SUM('P&L Medzy '!AP16:BA16) -> 4353571.7 | I11: =SUM('P&L Medzy '!BB16:BM16) -> 11598674 | J11: =SUM('P&L Medzy '!BN16:BY16) -> 20629791 | K11: =SUM('P&L Medzy '!BZ16:CK16) -> 30917512
C12: Other Revenues | D12: 86807.64 | E12: 3590.43
C14: NET REVENUES | D14: =SUM(D11:D12) -> 588922.94 | E14: =SUM(E11:E12) -> 710144.92 | F14: =SUM(F11:F12) -> 843819.37 | G14: =SUM(G11:G12) -> 1445221.5 | H14: =SUM(H11:H12) -> 4353571.7 | I14: =SUM(I11:I12) -> 11598674 | J14: =SUM(J11:J12) -> 20629791 | K14: =SUM(K11:K12) -> 30917512
D16: Oct 31 2021 | E16: Oct 31 2022 | F16: Oct 31 2023 | G16: Oct 31 2024 | H16: Oct 31 2025 | I16: Oct 31 2026 | J16: Oct 31 2027 | K16: Oct 31 2028
B17: EXPENSES | C17: ='P&L Medzy '!B31 -> COS | D17: ACTUALS | G17: FORECASTS
C19: ='P&L Medzy '!B33 -> Salaries
C20: ='P&L Medzy '!B34 -> IT | D20: 417888.58 | E20: 717436.34 | F20: =SUM('P&L Medzy '!P34:AA34) -> 1126399.9 | G20: =SUM('P&L Medzy '!AB34:AM34) -> 1017794.4 | H20: =SUM('P&L Medzy '!AN34:BA34) -> 1593879.2 | I20: =SUM('P&L Medzy '!BB34:BM34) -> 1492200 | J20: =SUM('P&L Medzy '!BN34:BY34) -> 1492200 | K20: =SUM('P&L Medzy '!BZ34:CK34) -> 1492200
C21: ='P&L Medzy '!B35 -> Sales / Marketing | D21: 93569.48 | E21: 81287.16 | F21: =SUM('P&L Medzy '!P35:AA35) -> 105541.57 | G21: =SUM('P&L Medzy '!AB35:AM35) -> 318550 | H21: =SUM('P&L Medzy '!AN35:BA35) -> 1105866.7 | I21: =SUM('P&L Medzy '!BB35:BM35) -> 1025085 | J21: =SUM('P&L Medzy '!BN35:BY35) -> 1055624.2 | K21: =SUM('P&L Medzy '!BZ35:CK35) -> 1087690.5
C22: ='P&L Medzy '!B36 -> Operations | D22: 104396.35 | E22: 39939.72 | F22: =SUM('P&L Medzy '!P36:AA36) -> 110207 | G22: =SUM('P&L Medzy '!AB36:AM36) -> 325416.67 | H22: =SUM('P&L Medzy '!AN36:BA36) -> 1057916.7 | I22: =SUM('P&L Medzy '!BB36:BM36) -> 912500 | J22: =SUM('P&L Medzy '!BN36:BY36) -> 912500 | K22: =SUM('P&L Medzy '!BZ36:CK36) -> 912500
C23: ='P&L Medzy '!B37 -> Sub total | D23: =SUM(D20:D22) -> 615854.41 | E23: =SUM(E20:E22) -> 838663.22 | F23: =SUM('P&L Medzy '!P37:AA37) -> 1342148.5 | G23: =SUM('P&L Medzy '!AB37:AM37) -> 1661761.1 | H23: =SUM('P&L Medzy '!AN37:BA37) -> 3757662.5 | I23: =SUM('P&L Medzy '!BB37:BM37) -> 3429785 | J23: =SUM('P&L Medzy '!BN37:BY37) -> 3460324.2 | K23: =SUM('P&L Medzy '!BZ37:CK37) -> 3492390.5
C25: ='P&L Medzy '!B39 -> Fringes + Bonus | D25: 0 | E25: 0 | F25: =SUM('P&L Medzy '!P39:AA39) -> 0 | G25: =SUM('P&L Medzy '!AB39:AM39) -> 160241.9 | H25: =SUM('P&L Medzy '!AN39:BA39) -> 450919.5 | I25: =SUM('P&L Medzy '!BB39:BM39) -> 411574.2 | J25: =SUM('P&L Medzy '!BN39:BY39) -> 415238.91 | K25: =SUM('P&L Medzy '!BZ39:CK39) -> 419086.86
C27: ='P&L Medzy '!B41 -> Contractuals - Tech | D27: 0 | E27: 0 | F27: =SUM('P&L Medzy '!P41:AA41) -> 8448 | G27: =SUM('P&L Medzy '!AB41:AM41) -> 0 | H27: =SUM('P&L Medzy '!AN41:BA41) -> 0 | I27: =SUM('P&L Medzy '!BB41:BM41) -> 0 | J27: =SUM('P&L Medzy '!BN41:BY41) -> 0 | K27: =SUM('P&L Medzy '!BZ41:CK41) -> 0
C28: ='P&L Medzy '!B42 -> Contractuals - Operations | D28: =140930.08+254789.8 -> 395719.88 | E28: =281521.71+520357.4 -> 801879.11 | F28: =SUM('P&L Medzy '!P42:AA42) -> 342552.55 | G28: =SUM('P&L Medzy '!AB42:AM42) -> 70000 | H28: =SUM('P&L Medzy '!AN42:BA42) -> 5000 | I28: =SUM('P&L Medzy '!BB42:BM42) -> 0 | J28: =SUM('P&L Medzy '!BN42:BY42) -> 0 | K28: =SUM('P&L Medzy '!BZ42:CK42) -> 0
C30: ='P&L Medzy '!B44 -> Professionals
C31: ='P&L Medzy '!B45 -> Accounting Fees | F31: =SUM('P&L Medzy '!P45:AA45) -> 34550.5 | G31: =SUM('P&L Medzy '!AB45:AM45) -> 40000 | H31: =SUM('P&L Medzy '!AN45:BA45) -> 42000 | I31: =SUM('P&L Medzy '!BB45:BM45) -> 39500 | J31: =SUM('P&L Medzy '!BN45:BY45) -> 39500 | K31: =SUM('P&L Medzy '!BZ45:CK45) -> 39500
C32: ='P&L Medzy '!B46 -> Legal Fees | D32: 43059.58 | E32: 113846.78 | F32: =SUM('P&L Medzy '!P46:AA46) -> 28264.65 | G32: =SUM('P&L Medzy '!AB46:AM46) -> 60000 | H32: =SUM('P&L Medzy '!AN46:BA46) -> 68000 | I32: =SUM('P&L Medzy '!BB46:BM46) -> 60000 | J32: =SUM('P&L Medzy '!BN46:BY46) -> 60000 | K32: =SUM('P&L Medzy '!BZ46:CK46) -> 60000
C33: ='P&L Medzy '!B47 -> Other | F33: =SUM('P&L Medzy '!P47:AA47) -> 37076.4 | G33: =SUM('P&L Medzy '!AB47:AM47) -> 80000 | H33: =SUM('P&L Medzy '!AN47:BA47) -> 170000 | I33: =SUM('P&L Medzy '!BB47:BM47) -> 150000 | J33: =SUM('P&L Medzy '!BN47:BY47) -> 150000 | K33: =SUM('P&L Medzy '!BZ47:CK47) -> 150000
C37: ='P&L Medzy '!B51 -> SubTotal Salaries
C38: ='P&L Medzy '!B52 -> 0 | F38: =SUM('P&L Medzy '!P52:AA52) -> 0 | G38: =SUM('P&L Medzy '!AB52:AM52) -> 0 | H38: =SUM('P&L Medzy '!AN52:BA52) -> 0
C39: ='P&L Medzy '!B53 -> Rent | D39: 28253.4 | E39: 35644.64 | F39: =SUM('P&L Medzy '!P53:AA53) -> 54996.27 | G39: =SUM('P&L Medzy '!AB53:AM53) -> 63029.36 | H39: =SUM('P&L Medzy '!AN53:BA53) -> 84000 | I39: =SUM('P&L Medzy '!BB53:BM53) -> 72000 | J39: =SUM('P&L Medzy '!BN53:BY53) -> 72000 | K39: =SUM('P&L Medzy '!BZ53:CK53) -> 72000
C40: ='P&L Medzy '!B54 -> Utilities | F40: =SUM('P&L Medzy '!P54:AA54) -> 2075.75 | G40: =SUM('P&L Medzy '!AB54:AM54) -> 5400 | H40: =SUM('P&L Medzy '!AN54:BA54) -> 9600 | I40: =SUM('P&L Medzy '!BB54:BM54) -> 8400 | J40: =SUM('P&L Medzy '!BN54:BY54) -> 8400 | K40: =SUM('P&L Medzy '!BZ54:CK54) -> 8400
C41: ='P&L Medzy '!B55 -> Insurance | D41: 9863.01 | E41: =-230961.75+16209.9 -> -214751.85 | F41: =SUM('P&L Medzy '!P55:AA55) -> 13884.76 | G41: =SUM('P&L Medzy '!AB55:AM55) -> 14407.44 | H41: =SUM('P&L Medzy '!AN55:BA55) -> 30400 | I41: =SUM('P&L Medzy '!BB55:BM55) -> 26400 | J41: =SUM('P&L Medzy '!BN55:BY55) -> 26400 | K41: =SUM('P&L Medzy '!BZ55:CK55) -> 26400
C42: ='P&L Medzy '!B56 -> Meals and Entertainment | D42: 619.4 | E42: 34.89 | F42: =SUM('P&L Medzy '!P56:AA56) -> 293.76 | G42: =SUM('P&L Medzy '!AB56:AM56) -> 10837.52 | H42: =SUM('P&L Medzy '!AN56:BA56) -> 40250 | I42: =SUM('P&L Medzy '!BB56:BM56) -> 29500 | J42: =SUM('P&L Medzy '!BN56:BY56) -> 29500 | K42: =SUM('P&L Medzy '!BZ56:CK56) -> 29500
C43: ='P&L Medzy '!B57 -> Travel Expenses | D43: 373.71 | E43: 12153.03 | F43: =SUM('P&L Medzy '!P57:AA57) -> 2308.58 | G43: =SUM('P&L Medzy '!AB57:AM57) -> 24001.72 | H43: =SUM('P&L Medzy '!AN57:BA57) -> 54000 | I43: =SUM('P&L Medzy '!BB57:BM57) -> 48000 | J43: =SUM('P&L Medzy '!BN57:BY57) -> 48000 | K43: =SUM('P&L Medzy '!BZ57:CK57) -> 48000
C44: ='P&L Medzy '!B58 -> Depreciation - (delivery box) | D44: =23881.13+12920.71 -> 36801.84 | E44: 29169.96 | F44: =SUM('P&L Medzy '!P58:AA58) -> 1290.48 | G44: =SUM('P&L Medzy '!AB58:AM58) -> 5161.92 | H44: =SUM('P&L Medzy '!AN58:BA58) -> 6022.24 | I44: =SUM('P&L Medzy '!BB58:BM58) -> 5161.92 | J44: =SUM('P&L Medzy '!BN58:BY58) -> 5161.92 | K44: =SUM('P&L Medzy '!BZ58:CK58) -> 5161.92
C45: ='P&L Medzy '!B59 -> Telecommunication | D45: 1091.13 | E45: 1096.07 | F45: =SUM('P&L Medzy '!P59:AA59) -> 1925.77 | G45: =SUM('P&L Medzy '!AB59:AM59) -> 3439.68 | H45: =SUM('P&L Medzy '!AN59:BA59) -> 5500 | I45: =SUM('P&L Medzy '!BB59:BM59) -> 4800 | J45: =SUM('P&L Medzy '!BN59:BY59) -> 4800 | K45: =SUM('P&L Medzy '!BZ59:CK59) -> 4800
C46: ='P&L Medzy '!B60 -> License and Subscriptions | D46: 64710.01 | E46: =72183.09-89.97 -> 72093.12 | F46: =SUM('P&L Medzy '!P60:AA60) -> 72750.86 | G46: =SUM('P&L Medzy '!AB60:AM60) -> 92311.6 | H46: =SUM('P&L Medzy '!AN60:BA60) -> 170000 | I46: =SUM('P&L Medzy '!BB60:BM60) -> 150000 | J46: =SUM('P&L Medzy '!BN60:BY60) -> 150000 | K46: =SUM('P&L Medzy '!BZ60:CK60) -> 150000
C47: ='P&L Medzy '!B61 -> Repair and Maintenance | D47: 19290.5 | E47: 10770 | F47: =SUM('P&L Medzy '!P61:AA61) -> 2980.01 | G47: =SUM('P&L Medzy '!AB61:AM61) -> 12000 | H47: =SUM('P&L Medzy '!AN61:BA61) -> 27000 | I47: =SUM('P&L Medzy '!BB61:BM61) -> 24000 | J47: =SUM('P&L Medzy '!BN61:BY61) -> 24000 | K47: =SUM('P&L Medzy '!BZ61:CK61) -> 24000
C48: ='P&L Medzy '!B62 -> Recruitment Charges | D48: 11605.5 | E48: 4555.82 | F48: =SUM('P&L Medzy '!P62:AA62) -> 1634.73 | G48: =SUM('P&L Medzy '!AB62:AM62) -> 20890.56 | H48: =SUM('P&L Medzy '!AN62:BA62) -> 35000 | I48: =SUM('P&L Medzy '!BB62:BM62) -> 30000 | J48: =SUM('P&L Medzy '!BN62:BY62) -> 30000 | K48: =SUM('P&L Medzy '!BZ62:CK62) -> 30000
C49: ='P&L Medzy '!B63 -> Offices Expenses | D49: 107890.65 | E49: =151.37+36765.19 -> 36916.56 | F49: =SUM('P&L Medzy '!P63:AA63) -> 24286.95 | G49: =SUM('P&L Medzy '!AB63:AM63) -> 36203 | H49: =SUM('P&L Medzy '!AN63:BA63) -> 67000 | I49: =SUM('P&L Medzy '!BB63:BM63) -> 60000 | J49: =SUM('P&L Medzy '!BN63:BY63) -> 60000 | K49: =SUM('P&L Medzy '!BZ63:CK63) -> 60000
C50: ='P&L Medzy '!B64 -> Taxes, Permit | D50: =218+1299.03 -> 1517.03 | E50: =787+2736.7 -> 3523.7 | F50: =SUM('P&L Medzy '!P64:AA64) -> 2345.01 | G50: =SUM('P&L Medzy '!AB64:AM64) -> 4000 | H50: =SUM('P&L Medzy '!AN64:BA64) -> 10000 | I50: =SUM('P&L Medzy '!BB64:BM64) -> 9000 | J50: =SUM('P&L Medzy '!BN64:BY64) -> 9000 | K50: =SUM('P&L Medzy '!BZ64:CK64) -> 9000
C51: ='P&L Medzy '!B65 -> Interest and bank charges | D51: =2315.7+10750 -> 13065.7 | E51: =9261.43+163.76+710.54 -> 10135.73 | F51: =SUM('P&L Medzy '!P65:AA65) -> 23233.89 | G51: =SUM('P&L Medzy '!AB65:AM65) -> 16914.96 | H51: =SUM('P&L Medzy '!AN65:BA65) -> 16400 | I51: =SUM('P&L Medzy '!BB65:BM65) -> 14400 | J51: =SUM('P&L Medzy '!BN65:BY65) -> 14400 | K51: =SUM('P&L Medzy '!BZ65:CK65) -> 14400
...

Sheet P&L Medzy 
B1: MEDZY Inc - Forecast 2023-2025
P3: ACTUALS - indication of costs (NOT FORMAL FINANCIAL STATEMENTS) | AB3: Forecast | AC3: Forecast | AD3: Forecast | AE3: Forecast | AF3: Forecast | AG3: Forecast | AH3: Forecast | AI3: Forecast | AJ3: Forecast | AK3: Forecast | AL3: Forecast | AM3: Forecast | AN3: Forecast | AO3: Forecast | AP3: Forecast | AQ3: Forecast | AR3: Forecast | AS3: Forecast | AT3: Forecast | AU3: Forecast | AV3: Forecast | AW3: Forecast | AX3: Forecast | AY3: Forecast | AZ3: Forecast | BA3: Forecast | BB3: Forecast | BC3: Forecast | BD3: Forecast | BE3: Forecast | BF3: Forecast | BG3: Forecast | BH3: Forecast | BI3: Forecast | BJ3: Forecast | BK3: Forecast | BL3: Forecast | BM3: Forecast | BN3: Forecast | BO3: Forecast | BP3: Forecast | BQ3: Forecast | BR3: Forecast | BS3: Forecast | BT3: Forecast | BU3: Forecast | BV3: Forecast | BW3: Forecast | BX3: Forecast | BY3: Forecast | BZ3: Forecast | CA3: Forecast | CB3: Forecast | CC3: Forecast | CD3: Forecast | CE3: Forecast | CF3: Forecast | CG3: Forecast | CH3: Forecast | CI3: Forecast | CJ3: Forecast | CK3: Forecast
B4: REVENUS | F4: 2022 | R4: 2023 | AD4: 2024 | AP4: 2025 | BB4: 2026 | BN4: 2027 | BZ4: 2028
F5: 44562 | G5: 44593 | H5: 44621 | I5: 44652 | J5: 44682 | K5: 44713 | L5: 44743 | M5: 44774 | N5: 44805 | O5: 44835 | P5: 44866 | Q5: 44896 | R5: 44927 | S5: 44958 | T5: 44986 | U5: 45017 | V5: 45047 | W5: 45078 | X5: 45108 | Y5: 45139 | Z5: 45170 | AA5: 45200 | AB5: 45231 | AC5: 45261 | AD5: 45292 | AE5: 45323 | AF5: 45352 | AG5: 45383 | AH5: 45413 | AI5: 45444 | AJ5: 45474 | AK5: 45505 | AL5: 45536 | AM5: 45566 | AN5: 45597 | AO5: 45627 | AP5: 45658 | AQ5: 45689 | AR5: 45717 | AS5: 45748 | AT5: 45778 | AU5: 45809 | AV5: 45839 | AW5: 45870 | AX5: 45901 | AY5: 45931 | AZ5: 45962 | BA5: 45992 | BB5: 45658 | BC5: 45689 | BD5: 45717 | BE5: 45748 | BF5: 45778 | BG5: 45809 | BH5: 45839 | BI5: 45870 | BJ5: 45901 | BK5: 45931 | BL5: 45962 | BM5: 45992 | BN5: 45658 | BO5: 45689 | BP5: 45717 | BQ5: 45748 | BR5: 45778 | BS5: 45809 | BT5: 45839 | BU5: 45870 | BV5: 45901 | BW5: 45931 | BX5: 45962 | BY5: 45992 | BZ5: 45658 | CA5: 45689 | CB5: 45717 | CC5: 45748 | CD5: 45778 | CE5: 45809 | CF5: 45839 | CG5: 45870 | CH5: 45901 | CI5: 45931 | CJ5: 45962 | CK5: 45992
B8: KPIS
B10: New Clients | Y10: ='Marketing and Sales'!Y5 -> 151.80952 | Z10: ='Marketing and Sales'!Z5 -> 153.80952 | AA10: ='Marketing and Sales'!AA5 -> 155.80952 | AB10: ='Marketing and Sales'!AB5 -> 179 | AC10: ='Marketing and Sales'!AC5 -> 181 | AD10: ='Marketing and Sales'!AD5 -> 184.31579 | AE10: ='Marketing and Sales'!AE5 -> 226.31579 | AF10: ='Marketing and Sales'!AF5 -> 294.10526 | ... CK10: ='Marketing and Sales'!CK5 -> 8499.4667
B11: Churn | Y11: ='Marketing and Sales'!Y6 -> 76.320674 | Z11: ='Marketing and Sales'!Z6 -> 77.171637 | AA11: ='Marketing and Sales'!AA6 -> 78.363484 | AB11: ='Marketing and Sales'!AB6 -> 79.540252 | AC11: ='Marketing and Sales'!AC6 -> 80.716811 | AD11: ='Marketing and Sales'!AD6 -> 82.222232 | AE11: ='Marketing and Sales'!AE6 -> 83.729918 | AF11: ='Marketing and Sales'!AF6 -> 85.210688 | ... CK11: ='Marketing and Sales'!CK6 -> 3345.2054
B12: Total Clients | F12: 3500 | G12: 3500 | H12: 3500 | I12: 3500 | J12: 3500 | K12: 3500 | L12: 3550 | M12: 3800 | N12: 4000 | O12: 4100 | U12: ='Marketing and Sales'!U7 -> 4343.444 | V12: ='Marketing and Sales'!V7 -> 4370.632 | W12: ='Marketing and Sales'!W7 -> 4398.0362 | X12: ='Marketing and Sales'!X7 -> 4446.035 | Y12: ='Marketing and Sales'!Y7 -> 4513.5239 | Z12: ='Marketing and Sales'!Z7 -> 4580.1618 | AA12: ='Marketing and Sales'!AA7 -> 4645.6078 | AB12: ='Marketing and Sales'!AB7 -> 4731.0676 | ... CK12: ='Marketing and Sales'!CK7 -> 177380.24
B13: Pharmacy Revenues | F13: 271351.31 | G13: 346671.19 | H13: 299360.68 | I13: 286619.21 | J13: 335521.54 | K13: 308437.92 | L13: 327251.67 | M13: 423725.2 | N13: 381647.99 | O13: 392558 | P13: ='Marketing and Sales'!P8 -> 375747.67 | Q13: ='Marketing and Sales'!Q8 -> 359175 | R13: 395802 | S13: 393267.57 | T13: 385053.93 | U13: 436144.26 | V13: 429750.16 | W13: 407798.21 | X13: 462265.2 | Y13: =Y16/17.5*100 -> 399268.34 | Z13: =Z16/17.5*100 -> 397411.43 | AA13: 501000 | AB13: ='Marketing and Sales'!AB8 -> 450193.95 | AC13: ='Marketing and Sales'!AC8 -> 460150.73 | AD13: ='Marketing and Sales'!AD8 -> 426918.17 | AE13: ='Marketing and Sales'!AE8 -> 434143.85 | AF13: ='Marketing and Sales'!AF8 -> 448390.13 | AG13: ='Marketing and Sales'!AG8 -> 504042.4 | AH13: ='Marketing and Sales'!AH8 -> 568991.43 | AI13: ='Marketing and Sales'!AI8 -> 641535.19 | ... CK13: ='Marketing and Sales'!CK8 -> 13279308
B14: Original Target | F14: na | G14: na | H14: na | I14: na | J14: na | K14: na | L14: 325000 | M14: 340000 | N14: 345000 | O14: 360000
B16: Medzy Platform Revenues | C16: 0.175 | F16: =F13*$C$16 -> 47486.479 | G16: =G13*$C$16 -> 60667.458 | H16: =H13*$C$16 -> 52388.119 | I16: =I13*$C$16 -> 50158.362 | J16: =J13*$C$16 -> 58716.269 | K16: =K13*$C$16 -> 53976.636 | L16: =L13*$C$16 -> 57269.042 | M16: =M13*$C$16 -> 74151.91 | ... O16: =O13*$C$16 -> 68697.65 | P16: ='Marketing and Sales'!P10 -> 67254.145 | Q16: ='Marketing and Sales'!Q10 -> 69258.154 | R16: ='Marketing and Sales'!R10 -> 70328.32 | S16: 68821 | T16: 67834 | U16: 73237 | V16: 71263.84 | W16: 69604.03 | X16: 77682.41 | Y16: 69871.96 | Z16: 69547 | AA16: ='Marketing and Sales'!AA10 -> 69117.51 | AB16: ='Marketing and Sales'!AB10 -> 69586.356 | AC16: ='Marketing and Sales'!AC10 -> 70049.787 | AD16: ='Marketing and Sales'!AD10 -> 70527.864 | AE16: ='Marketing and Sales'!AE10 -> 71347.257 | AF16: ='Marketing and Sales'!AF10 -> 72915.688 | AG16: ='Marketing and Sales'!AG10 -> 81651.115 | AH16: ='Marketing and Sales'!AH10 -> 91935.22 | ... CK16: ='Marketing and Sales'!CK10 -> 2996024.2
B17: Rev Share PAID
B18: Due to Medzy Reimbursment
B19: Due to Medzy
B21: OTC upsell Medzy | C21: 0 | D21: avg | X21: =X12*$C21*$C22 -> 0 | Y21: =Y12*$C21*$C22 -> 0 | Z21: =Z12*$C21*$C22 -> 0 | AA21: =AA12*$C21*$C22 -> 0 | AB21: =AB12*$C21*$C22 -> 0 | AC21: =AC12*$C21*$C22 -> 0 | AD21: =AD12*$C21*$C22 -> 0 | AE21: =AE12*$C21*$C22 -> 0 | ... CK21: =CK12*$C21*$C22 -> 0
C22: 0 | D22: user base
B24: MEDZY TOTAL REVENUES | F24: =F17 -> 0 | G24: =G17 -> 0 | H24: =H17 -> 0 | I24: =I17 -> 0 | J24: =J17 -> 0 | K24: =K17 -> 0 | L24: =L17 -> 0 | M24: =M17 -> 0 | ... O24: =O17 -> 0 | P24: =SUM(P16:P23) -> 67254.145 | Q24: =SUM(Q16:Q23) -> 69258.154 | R24: =SUM(R16:R23) -> 70328.32 | S24: =SUM(S16:S23) -> 68821 | T24: =SUM(T16:T23) -> 67834 | U24: =SUM(U16:U23) -> 73237 | V24: =SUM(V16:V23) -> 71263.84 | W24: =SUM(W16:W23) -> 69604.03 | ... CK24: =SUM(CK16:CK23) -> 2996024.2
B25: CUMULATIVE TOTAL REVENUES | F25: =E25+F24 -> 0 | G25: =F25+G24 -> 0 | H25: =G25+H24 -> 0 | I25: =H25+I24 -> 0 | J25: =I25+J24 -> 0 | K25: =J25+K24 -> 0 | L25: =K25+L24 -> 0 | M25: =L25+M24 -> 0 | ... CK25: =CJ25+CK24 -> 69928226
B29: Expenses | C29: Annual | F29: 2022 | R29: 2023 | AD29: 2024 | AP29: 2025 | BB29: 2026 | BN29: 2027 | BZ29: 2028
C30: compensation | F30: 44562 | G30: 44593 | H30: 44621 | I30: 44652 | J30: 44682 | K30: 44713 | L30: 44743 | M30: 44774 | N30: 44805 | O30: 44835 | P30: 44866 | Q30: 44896 | R30: 44927 | S30: 44958 | T30: 44986 | U30: 45017 | V30: 45047 | W30: 45078 | X30: 45108 | Y30: 45139 | Z30: 45170 | AA30: 45200 | AB30: 45231 | AC30: 45261 | AD30: 45292 | AE30: 45323 | AF30: 45352 | AG30: 45383 | AH30: 45413 | AI30: 45444 | AJ30: 45474 | AK30: 45505 | AL30: 45536 | AM30: 45566 | AN30: 45597 | AO30: 45627 | AP30: 45658 | AQ30: 45689 | AR30: 45717 | AS30: 45748 | AT30: 45778 | AU30: 45809 | AV30: 45839 | AW30: 45870 | AX30: 45901 | AY30: 45931 | AZ30: 45962 | BA30: 45992 | BB30: 45658 | BC30: 45689 | BD30: 45717 | BE30: 45748 | BF30: 45778 | BG30: 45809 | BH30: 45839 | BI30: 45870 | BJ30: 45901 | BK30: 45931 | BL30: 45962 | BM30: 45992 | BN30: 45658 | BO30: 45689 | BP30: 45717 | BQ30: 45748 | BR30: 45778 | BS30: 45809 | BT30: 45839 | BU30: 45870 | BV30: 45901 | BW30: 45931 | BX30: 45962 | BY30: 45992 | BZ30: 45658 | CA30: 45689 | CB30: 45717 | CC30: 45748 | CD30: 45778 | CE30: 45809 | CF30: 45839 | CG30: 45870 | CH30: 45901 | CI30: 45931 | CJ30: 45962 | CK30: 45992
B31: COS
B33: Salaries
B34: IT | F34: 48745.74 | G34: 54972.78 | H34: 84348.68 | I34: 58881.67 | J34: 56288.86 | K34: 59612.95 | L34: 67173.04 | M34: 44926.4 | N34: 67827.67 | O34: 72345.39 | P34: 76912.42 | Q34: 80555.26 | R34: 79313.91 | S34: =-12000+103958.34 -> 91958.34 | T34: 137055.95 | U34: 104155.54 | V34: 93533.52 | W34: 98175.1 | X34: 80667.6 | Y34: 102940.38 | Z34: 90565.96 | AA34: 90565.96 | AB34: 90565.96 | AC34: 90565.96 | AD34: 80000 | AE34: 60000 | AF34: 60000 | AG34: ='Salaries & Contractuals'!AH29 -> 80654.167 | AH34: ='Salaries & Contractuals'!AI29 -> 80654.167 | AI34: ='Salaries & Contractuals'!AJ29 -> 95070.833 | AJ34: ='Salaries & Contractuals'!AK29 -> 95070.833 | AK34: ='Salaries & Contractuals'!AL29 -> 95070.833 | AL34: ='Salaries & Contractuals'!AM29 -> 95070.833 | AM34: ='Salaries & Contractuals'!AN29 -> 95070.833 | AN34: ='Salaries & Contractuals'!AO29 -> 95070.833 | ... CK34: ='Salaries & Contractuals'!CL29 -> 124350
B35: Sales / Marketing | F35: 7108.15 | G35: 9225.63 | H35: 11046.54 | I35: 7268.44 | J35: 7196.29 | K35: 9403.81 | L35: 11246.98 | M35: 3205.51 | N35: 1715.57 | O35: 0 | P35: 0 | Q35: 0 | R35: 0 | S35: 0 | T35: 0 | U35: 39609.07 | V35: 22272.5 | W35: 13460 | X35: 18545 | Y35: 9015 | Z35: 1320 | AA35: 1320 | AB35: 1320 | AC35: 1320 | AD35: 1320 | AE35: 1320 | AF35: 1320 | AG35: ='Salaries & Contractuals'!AH44 -> 16683.333 | AH35: ='Salaries & Contractuals'!AI44 -> 30433.333 | AI35: ='Salaries & Contractuals'!AJ44 -> 40016.667 | AJ35: ='Salaries & Contractuals'!AK44 -> 40016.667 | AK35: ='Salaries & Contractuals'!AL44 -> 57433.333 | AL35: ='Salaries & Contractuals'!AM44 -> 63683.333 | AM35: ='Salaries & Contractuals'!AN44 -> 63683.333 | AN35: ='Salaries & Contractuals'!AO44 -> 63683.333 | ... CK35: ='Salaries & Contractuals'!CL44 -> 90640.872
B36: Operations | F36: 6338.31 | G36: 1869.05 | H36: 0 | I36: 0 | J36: 0 | K36: 0 | L36: 676.06 | M36: 1944.12 | N36: 0 | O36: 0 | P36: =2600+300+2250+2422 -> 7572 | Q36: =5000+1400+525 -> 6925 | R36: 14200 | S36: 2700 | T36: 5650 | U36: 28600 | V36: 17778 | W36: 21232 | X36: 5550 | Y36: 0 | Z36: 0 | AA36: 0 | AB36: 0 | AC36: 0 | AD36: 0 | AE36: 0 | AG36: ='Salaries & Contractuals'!AH57 -> 22916.667 | AH36: ='Salaries & Contractuals'!AI57 -> 22916.667 | AI36: ='Salaries & Contractuals'!AJ57 -> 45833.333 | AJ36: ='Salaries & Contractuals'!AK57 -> 45833.333 | AK36: ='Salaries & Contractuals'!AL57 -> 55000 | AL36: ='Salaries & Contractuals'!AM57 -> 66458.333 | AM36: ='Salaries & Contractuals'!AN57 -> 66458.333 | AN36: ='Salaries & Contractuals'!AO57 -> 72708.333 | ... CK36: ='Salaries & Contractuals'!CL57 -> 76041.667
B37: Sub total | F37: =SUM(F34:F36) -> 62192.2 | G37: =SUM(G34:G36) -> 66067.46 | H37: =SUM(H34:H36) -> 95395.22 | I37: =SUM(I34:I36) -> 66150.11 | J37: =SUM(J34:J36) -> 63485.15 | K37: =SUM(K34:K36) -> 69016.76 | L37: =SUM(L34:L36) -> 79096.08 | M37: =SUM(M34:M36) -> 50076.03 | ... CK37: =SUM(CK34:CK36) -> 291032.54
B39: Fringes + Bonus | C39: 0.12 | AF39: =(SUM(AF34:AF36))*$C39 -> 7358.4 | AG39: =(SUM(AG34:AG36))*$C39 -> 14430.5 | AH39: =(SUM(AH34:AH36))*$C39 -> 16080.5 | AI39: =(SUM(AI34:AI36))*$C39 -> 21710.5 | AJ39: =(SUM(AJ34:AJ36))*$C39 -> 21710.5 | AK39: =(SUM(AK34:AK36))*$C39 -> 24900.5 | AL39: =(SUM(AL34:AL36))*$C39 -> 27025.5 | AM39: =(SUM(AM34:AM36))*$C39 -> 27025.5 | ... CK39: =(SUM(CK34:CK36))*$C39 -> 34923.905
B41: Contractuals - Tech | S41: 3168 | T41: 5280 | V41: ='Salaries & Contractuals'!W71 -> 0 | W41: ='Salaries & Contractuals'!X71 -> 0 | X41: ='Salaries & Contractuals'!Y71 -> 0 | Y41: ='Salaries & Contractuals'!Z71 -> 0 | Z41: ='Salaries & Contractuals'!AA71 -> 0 | AA41: ='Salaries & Contractuals'!AB71 -> 0 | AB41: ='Salaries & Contractuals'!AC71 -> 0 | AC41: ='Salaries & Contractuals'!AD71 -> 0 | ... CK41: ='Salaries & Contractuals'!CL71 -> 0
B42: Contractuals - Operations | P42: =0.87+5497.4+15000+9000+31035.9 -> 60534.17 | Q42: =15000+9000+15000+41934.91 -> 80934.91 | R42: =19229.24+24000 -> 43229.24 | S42: =37523.37+29000 -> 66523.37 | T42: =24998.48+24000 -> 48998.48 | U42: 0 | V42: 0 | W42: 0 | X42: 0 | Y42: =14475-3750 -> 10725 | Z42: =25357.38-3750 -> 21607.38 | AA42: 10000 | AB42: 10000 | AC42: 10000 | AD42: 5000 | AE42: 5000 | AF42: 5000 | AG42: 5000 | AH42: 5000 | AI42: 5000 | AJ42: 5000 | AK42: 5000 | AL42: 5000 | AM42: 5000 | AN42: 5000 | AO42: ='Salaries & Contractuals'!AP82 -> 0 | AP42: ='Salaries & Contractuals'!AQ82 -> 0 | AQ42: ='Salaries & Contractuals'!AR82 -> 0 | AR42: ='Salaries & Contractuals'!AS82 -> 0 | AS42: ='Salaries & Contractuals'!AT82 -> 0 | AT42: ='Salaries & Contractuals'!AU82 -> 0 | AU42: ='Salaries & Contractuals'!AV82 -> 0 | AV42: ='Salaries & Contractuals'!AW82 -> 0 | ... CK42: ='Salaries & Contractuals'!CL82 -> 0
B44: Professionals
B45: Accounting Fees | F45: 1000 | G45: 1000 | H45: 1000 | I45: 1000 | J45: 1000 | K45: 1000 | L45: 1000 | M45: 1000 | N45: 1000 | O45: 1000 | P45: =4456+1000+4150 -> 9606 | Q45: =2750+3123 -> 5873 | R45: 4756.5 | S45: 1815 | T45: 1250 | U45: 0 | V45: 0 | W45: 0 | X45: 0 | Y45: 3750 | Z45: 3750 | AA45: 3750 | AB45: 3750 | AC45: 3750 | AD45: 3750 | AE45: 3750 | AF45: 1250 | AG45: =15000+1250 -> 16250 | AH45: 1250 | AI45: 1250 | AJ45: 1250 | AK45: 1250 | AL45: 1250 | AM45: 1250 | AN45: 1250 | AO45: 1250 | AP45: 1500 | AQ45: 1500 | AR45: 1500 | AS45: =20000+1500 -> 21500 | AT45: 1500 | AU45: 1500 | AV45: 1750 | AW45: 1750 | AX45: 1750 | AY45: 1750 | AZ45: 1750 | BA45: 1750 | BB45: 1500 | BC45: 1500 | BD45: 1500 | BE45: =20000+1500 -> 21500 | BF45: 1500 | BG45: 1500 | BH45: 1750 | BI45: 1750 | BJ45: 1750 | BK45: 1750 | BL45: 1750 | BM45: 1750 | BN45: 1500 | BO45: 1500 | BP45: 1500 | BQ45: =20000+1500 -> 21500 | BR45: 1500 | BS45: 1500 | BT45: 1750 | BU45: 1750 | BV45: 1750 | BW45: 1750 | BX45: 1750 | BY45: 1750 | BZ45: 1500 | CA45: 1500 | CB45: 1500 | CC45: =20000+1500 -> 21500 | CD45: 1500 | CE45: 1500 | CF45: 1750 | CG45: 1750 | CH45: 1750 | CI45: 1750 | CJ45: 1750 | CK45: 1750
B46: Legal Fees | F46: 4875.76 | G46: 29404.68 | H46: 1876.64 | I46: 0 | J46: 0 | K46: 1672.4 | L46: 29404.12 | M46: 4237.1 | N46: 21453.37 | O46: -1498.26 | P46: 8814.06 | Q46: 503.59 | R46: 0 | S46: 0 | T46: 0 | U46: 1647 | V46: 2801 | W46: 3237 | X46: 1383 | Y46: 6684 | Z46: 3195 | AA46: 0 | AB46: 0 | AC46: 0 | AD46: 0 | AE46: 0 | AF46: 0 | AG46: 20000 | AH46: 20000 | AI46: 4000 | AJ46: 4000 | AK46: 4000 | AL46: 4000 | AM46: 4000 | AN46: 4000 | AO46: 4000 | AP46: 5000 | AQ46: 5000 | AR46: 5000 | AS46: 5000 | AT46: 5000 | AU46: 5000 | AV46: 5000 | AW46: 5000 | AX46: 5000 | AY46: 5000 | AZ46: 5000 | BA46: 5000 | BB46: 5000 | BC46: 5000 | BD46: 5000 | BE46: 5000 | BF46: 5000 | BG46: 5000 | BH46: 5000 | BI46: 5000 | BJ46: 5000 | BK46: 5000 | BL46: 5000 | BM46: 5000 | BN46: 5000 | BO46: 5000 | BP46: 5000 | BQ46: 5000 | BR46: 5000 | BS46: 5000 | BT46: 5000 | BU46: 5000 | BV46: 5000 | BW46: 5000 | BX46: 5000 | BY46: 5000 | BZ46: 5000 | CA46: 5000 | CB46: 5000 | CC46: 5000 | CD46: 5000 | CE46: 5000 | CF46: 5000 | CG46: 5000 | CH46: 5000 | CI46: 5000 | CJ46: 5000 | CK46: 5000
B47: Other | F47: 0 | G47: 0 | H47: 0 | I47: 0 | J47: 0 | K47: 0 | L47: 0 | M47: 0 | N47: 0 | O47: 0 | R47: =4956.76-500 -> 4456.76 | S47: =8408.39-500 -> 7908.39 | T47: =(16065.53-T41)+(6440.72-500) -> 16726.25 | U47: 0 | V47: 2657 | W47: 1017 | X47: 2311 | Y47: 0 | Z47: 0 | AA47: 2000 | AB47: 2000 | AC47: 2000 | AD47: 2000 | AE47: 2000 | AF47: 2000 | AG47: 10000 | AH47: 10000 | AI47: 10000 | AJ47: 10000 | AK47: 10000 | AL47: 10000 | AM47: 10000 | AN47: 10000 | AO47: 10000 | AP47: 12500 | AQ47: 12500 | AR47: 12500 | AS47: 12500 | AT47: 12500 | AU47: 12500 | AV47: 12500 | AW47: 12500 | AX47: 12500 | AY47: 12500 | AZ47: 12500 | BA47: 12500 | BB47: 12500 | BC47: 12500 | BD47: 12500 | BE47: 12500 | BF47: 12500 | BG47: 12500 | BH47: 12500 | BI47: 12500 | BJ47: 12500 | BK47: 12500 | BL47: 12500 | BM47: 12500 | BN47: 12500 | BO47: 12500 | BP47: 12500 | BQ47: 12500 | BR47: 12500 | BS47: 12500 | BT47: 12500 | BU47: 12500 | BV47: 12500 | BW47: 12500 | BX47: 12500 | BY47: 12500 | BZ47: 12500 | CA47: 12500 | CB47: 12500 | CC47: 12500 | CD47: 12500 | CE47: 12500 | CF47: 12500 | CG47: 12500 | CH47: 12500 | CI47: 12500 | CJ47: 12500 | CK47: 12500
B51: SubTotal Salaries | F51: =SUM(F45:F49)+F37 -> 68067.96 | G51: =SUM(G45:G49)+G37 -> 96472.14 | H51: =SUM(H45:H49)+H37 -> 98271.86 | I51: =SUM(I45:I49)+I37 -> 67150.11 | J51: =SUM(J45:J49)+J37 -> 64485.15 | K51: =SUM(K45:K49)+K37 -> 71689.16 | L51: =SUM(L45:L49)+L37 -> 109500.2 | M51: =SUM(M45:M49)+M37 -> 55313.13 | ... O51: =SUM(O45:O49)+O37 -> 71847.13 | P51: =SUM(P39:P49)+P37 -> 163438.65 | Q51: =SUM(Q37:Q47) -> 174791.76 | R51: =SUM(R37:R47) -> 145956.41 | S51: =SUM(S37:S47) -> 174073.1 | T51: =SUM(T37:T47) -> 214960.68 | U51: =SUM(U37:U47) -> 174011.61 | V51: =SUM(V37:V47) -> 139042.02 | W51: =SUM(W37:W47) -> 137121.1 | X51: =SUM(X37:X47) -> 108456.6 | ... CK51: =SUM(CK37:CK47) -> 345206.44
B53: Rent | C53: Net of Recharge to PSB | F53: 2823.34 | G53: 2823.34 | H53: 2823.34 | I53: 2823.34 | J53: 2823.34 | K53: 2823.34 | L53: 2823.34 | M53: 4235 | N53: 2999.79 | O53: 2999.79 | P53: 3000.01 | Q53: 3209.56 | R53: 4878.67 | S53: 4878.67 | T53: 4878.67 | U53: 4878.67 | V53: 4878.67 | W53: 4878.67 | X53: 4878.67 | Y53: 4878.67 | Z53: 4878.67 | AA53: 4878.67 | AB53: 4878.67 | AC53: 4878.67 | AD53: 4878.67 | AE53: 4878.67 | AF53: 4878.67 | AG53: 4878.67 | AH53: 4878.67 | AI53: 4878.67 | AJ53: =6000-'PSB-P&L '!AJ54 -> 6000 | AK53: =6000-'PSB-P&L '!AK54 -> 6000 | AL53: =6000-'PSB-P&L '!AL54 -> 6000 | AM53: =6000-'PSB-P&L '!AM54 -> 6000 | AN53: =6000-'PSB-P&L '!AN54 -> 6000 | AO53: =6000-'PSB-P&L '!AO54 -> 6000 | AP53: =6000-'PSB-P&L '!AP54 -> 6000 | AQ53: =6000-'PSB-P&L '!AQ54 -> 6000 | ... CK53: =6000-'PSB-P&L '!CK54 -> 6000
B54: Utilities | F54: 312.99 | G54: 0 | H54: 341.73 | I54: 0 | J54: 304.98 | K54: 0 | L54: 425.14 | M54: 0 | N54: 729.91 | O54: 0 | T54: 646.98 | Y54: 1428.77 | AE54: 600 | AF54: 600 | AG54: 600 | AH54: 600 | AI54: 600 | AJ54: 600 | AK54: 600 | AL54: 600 | AM54: 600 | AN54: 600 | AO54: 600 | AP54: 700 | AQ54: 700 | AR54: 700 | AS54: 700 | AT54: 700 | AU54: 700 | AV54: 700 | AW54: 700 | AX54: 700 | AY54: 700 | AZ54: 700 | BA54: 700 | BB54: 700 | BC54: 700 | BD54: 700 | BE54: 700 | BF54: 700 | BG54: 700 | BH54: 700 | BI54: 700 | BJ54: 700 | BK54: 700 | BL54: 700 | BM54: 700 | BN54: 700 | BO54: 700 | BP54: 700 | BQ54: 700 | BR54: 700 | BS54: 700 | BT54: 700 | BU54: 700 | BV54: 700 | BW54: 700 | BX54: 700 | BY54: 700 | BZ54: 700 | CA54: 700 | CB54: 700 | CC54: 700 | CD54: 700 | CE54: 700 | CF54: 700 | CG54: 700 | CH54: 700 | CI54: 700 | CJ54: 700 | CK54: 700
B55: Insurance | F55: 1136.86 | G55: 1136.86 | H55: 563.51 | I55: 1777.77 | J55: -29182.89 | K55: -198482.74 | L55: 1517.26 | M55: 1517.26 | N55: 1919.09 | O55: 1115.43 | P55: 1517.26 | Q55: 1517.26 | R55: 1517.26 | S55: 1517.26 | T55: 3590.08 | U55: 1814.48 | V55: 401.86 | W55: 401.86 | X55: 401.86 | Y55: 401.86 | Z55: 401.86 | AA55: 401.86 | AB55: 401.86 | AC55: 401.86 | AD55: 401.86 | AE55: 401.86 | AF55: 1200 | AG55: 1200 | AH55: 1200 | AI55: 1200 | AJ55: 2000 | AK55: 2000 | AL55: 2000 | AM55: 2000 | AN55: 2000 | AO55: 2000 | AP55: 2200 | AQ55: 2200 | AR55: 2200 | AS55: 2200 | AT55: 2200 | AU55: 2200 | AV55: 2200 | AW55: 2200 | AX55: 2200 | AY55: 2200 | AZ55: 2200 | BA55: 2200 | BB55: 2200 | BC55: 2200 | BD55: 2200 | BE55: 2200 | BF55: 2200 | BG55: 2200 | BH55: 2200 | BI55: 2200 | BJ55: 2200 | BK55: 2200 | BL55: 2200 | BM55: 2200 | BN55: 2200 | BO55: 2200 | BP55: 2200 | BQ55: 2200 | BR55: 2200 | BS55: 2200 | BT55: 2200 | BU55: 2200 | BV55: 2200 | BW55: 2200 | BX55: 2200 | BY55: 2200 | BZ55: 2200 | CA55: 2200 | CB55: 2200 | CC55: 2200 | CD55: 2200 | CE55: 2200 | CF55: 2200 | CG55: 2200 | CH55: 2200 | CI55: 2200 | CJ55: 2200 | CK55: 2200
B56: Meals and Entertainment | F56: 0 | G56: 0 | H56: 225 | I56: 3460 | J56: 0 | K56: 0 | L56: 0 | M56: 0 | N56: 0 | O56: 0 | Y56: 0 | Z56: 146.88 | AA56: 146.88 | AB56: 146.88 | AC56: 146.88 | AD56: 146.88 | AE56: 146.88 | AF56: 750 | AG56: 750 | AH56: 750 | AI56: 5000 | AJ56: 750 | AK56: 750 | AL56: 750 | AM56: 750 | AN56: 750 | AO56: 10000 | AP56: 1000 | AQ56: 1000 | AR56: 1000 | AS56: 1000 | AT56: 1000 | AU56: 7000 | AV56: 1000 | AW56: 1000 | AX56: 1000 | AY56: 1000 | AZ56: 1000 | BA56: 12500 | BB56: 1000 | BC56: 1000 | BD56: 1000 | BE56: 1000 | BF56: 1000 | BG56: 7000 | BH56: 1000 | BI56: 1000 | BJ56: 1000 | BK56: 1000 | BL56: 1000 | BM56: 12500 | BN56: 1000 | BO56: 1000 | BP56: 1000 | BQ56: 1000 | BR56: 1000 | BS56: 7000 | BT56: 1000 | BU56: 1000 | BV56: 1000 | BW56: 1000 | BX56: 1000 | BY56: 12500 | BZ56: 1000 | CA56: 1000 | CB56: 1000 | CC56: 1000 | CD56: 1000 | CE56: 7000 | CF56: 1000 | CG56: 1000 | CH56: 1000 | CI56: 1000 | CJ56: 1000 | CK56: 12500
B57: Travel Expenses | F57: 0 | G57: 0 | H57: 0 | I57: 0 | J57: 282.78 | K57: 360.01 | L57: 0 | M57: 9822.31 | N57: 769.24 | O57: 769.24 | P57: 769.24 | Q57: 1153.86 | R57: 384.62 | S57: 0 | T57: 0 | U57: 0 | Y57: 0 | Z57: 0.43 | AA57: 0.43 | AB57: 0.43 | AC57: 0.43 | AD57: 0.43 | AE57: 0.43 | AF57: 3000 | AG57: 3000 | AH57: 3000 | AI57: 3000 | AJ57: 3000 | AK57: 3000 | AL57: 3000 | AM57: 3000 | AN57: 3000 | AO57: 3000 | AP57: 4000 | AQ57: 4000 | AR57: 4000 | AS57: 4000 | AT57: 4000 | AU57: 4000 | AV57: 4000 | AW57: 4000 | AX57: 4000 | AY57: 4000 | AZ57: 4000 | BA57: 4000 | BB57: 4000 | BC57: 4000 | BD57: 4000 | BE57: 4000 | BF57: 4000 | BG57: 4000 | BH57: 4000 | BI57: 4000 | BJ57: 4000 | BK57: 4000 | BL57: 4000 | BM57: 4000 | BN57: 4000 | BO57: 4000 | BP57: 4000 | BQ57: 4000 | BR57: 4000 | BS57: 4000 | BT57: 4000 | BU57: 4000 | BV57: 4000 | BW57: 4000 | BX57: 4000 | BY57: 4000 | BZ57: 4000 | CA57: 4000 | CB57: 4000 | CC57: 4000 | CD57: 4000 | CE57: 4000 | CF57: 4000 | CG57: 4000 | CH57: 4000 | CI57: 4000 | CJ57: 4000 | CK57: 4000
B58: Depreciation - (delivery box) | F58: 0 | G58: 0 | H58: 0 | I58: 0 | J58: 0 | K58: 0 | L58: 0 | M58: 0 | N58: 0 | O58: 26739.13 | U58: =U89/36 -> 0 | V58: =U58 -> 0 | W58: =V58 -> 0 | X58: =W58 -> 0 | Y58: 430.16 | Z58: =Y58 -> 430.16 | AA58: =Z58 -> 430.16 | AB58: =AA58 -> 430.16 | AC58: =AB58 -> 430.16 | AD58: =AC58 -> 430.16 | AE58: =AD58 -> 430.16 | AF58: =AE58 -> 430.16 | AG58: =AF58 -> 430.16 | ... CK58: =CJ58 -> 430.16
...

Sheet Salaries & Contractuals
B2: Annual Raise | C2: 0.05
B4: SALARIES | G4: 2022 | S4: 2023 | AE4: 2024 | AQ4: 2025 | BC4: 2026 | BO4: 2027 | CA4: 2027
G5: 44562 | H5: 44593 | I5: 44621 | J5: 44652 | K5: 44682 | L5: 44713 | M5: 44743 | N5: 44774 | O5: 44805 | P5: 44835 | Q5: 44866 | R5: 44896 | S5: 44927 | T5: 44958 | U5: 44986 | V5: 45017 | W5: 45047 | X5: 45078 | Y5: 45108 | Z5: 45139 | AA5: 45170 | AB5: 45200 | AC5: 45231 | AD5: 45261 | AE5: 45292 | AF5: 45323 | AG5: 45352 | AH5: 45383 | AI5: 45413 | AJ5: 45444 | AK5: 45474 | AL5: 45505 | AM5: 45536 | AN5: 45566 | AO5: 45597 | AP5: 45627 | AQ5: 45658 | AR5: 45689 | AS5: 45717 | AT5: 45748 | AU5: 45778 | AV5: 45809 | AW5: 45839 | AX5: 45870 | AY5: 45901 | AZ5: 45931 | BA5: 45962 | BB5: 45992 | BC5: 45658 | BD5: 45689 | BE5: 45717 | BF5: 45748 | BG5: 45778 | BH5: 45809 | BI5: 45839 | BJ5: 45870 | BK5: 45901 | BL5: 45931 | BM5: 45962 | BN5: 45992 | BO5: 45658 | BP5: 45689 | BQ5: 45717 | BR5: 45748 | BS5: 45778 | BT5: 45809 | BU5: 45839 | BV5: 45870 | BW5: 45901 | BX5: 45931 | BY5: 45962 | BZ5: 45992 | CA5: 45658 | CB5: 45689 | CC5: 45717 | CD5: 45748 | CE5: 45778 | CF5: 45809 | CG5: 45839 | CH5: 45870 | CI5: 45901 | CJ5: 45931 | CK5: 45962 | CL5: 45992
B6: Role | C6: Employee | D6: Annual Compensation
B8: IT
B10: CTO | C10: Mathieu | D10: 175000 | O10: =$D10/12 -> 14583.333 | P10: =$D10/12 -> 14583.333 | Q10: =$D10/12 -> 14583.333 | R10: =$D10/12 -> 14583.333 | S10: =($D10/12)*(1+$C$2) -> 15312.5 | T10: =($D10/12)*(1+$C$2) -> 15312.5 | U10: =($D10/12)*(1+$C$2) -> 15312.5 | V10: =($D10/12)*(1+$C$2) -> 15312.5 | W10: =($D10/12)*(1+$C$2) -> 15312.5 | X10: =($D10/12)*(1+$C$2) -> 15312.5 | Y10: =($D10/12)*(1+$C$2) -> 15312.5 | Z10: =($D10/12)*(1+$C$2) -> 15312.5 | ... AD10: =($D10/12)*(1+$C$2) -> 15312.5 | AE10: =($D10/12)*(1+$C$2+$C$2) -> 16041.667 | AF10: =($D10/12)*(1+$C$2+$C$2) -> 16041.667 | AG10: =($D10/12)*(1+$C$2+$C$2) -> 16041.667 | AH10: =($D10/12)*(1+$C$2+$C$2) -> 16041.667 | AI10: =($D10/12)*(1+$C$2+$C$2) -> 16041.667 | AJ10: =($D10/12)*(1+$C$2+$C$2) -> 16041.667 | AK10: =($D10/12)*(1+$C$2+$C$2) -> 16041.667 | AL10: =($D10/12)*(1+$C$2+$C$2) -> 16041.667 | ... AP10: =($D10/12)*(1+$C$2+$C$2) -> 16041.667 | AQ10: =($D10/12)*(1+$C$2+$C$2+$C$2) -> 16770.833 | AR10: =($D10/12)*(1+$C$2+$C$2+$C$2) -> 16770.833 | AS10: =($D10/12)*(1+$C$2+$C$2+$C$2) -> 16770.833 | AT10: =($D10/12)*(1+$C$2+$C$2+$C$2) -> 16770.833 | AU10: =($D10/12)*(1+$C$2+$C$2+$C$2) -> 16770.833 | AV10: =($D10/12)*(1+$C$2+$C$2+$C$2) -> 16770.833 | AW10: =($D10/12)*(1+$C$2+$C$2+$C$2) -> 16770.833 | AX10: =($D10/12)*(1+$C$2+$C$2+$C$2) -> 16770.833 | ... BB10: =($D10/12)*(1+$C$2+$C$2+$C$2) -> 16770.833 | BC10: =($D10/12)*(1+$C$2+$C$2+$C$2+$C$2) -> 17500 | BD10: =($D10/12)*(1+$C$2+$C$2+$C$2+$C$2) -> 17500 | BE10: =($D10/12)*(1+$C$2+$C$2+$C$2+$C$2) -> 17500 | BF10: =($D10/12)*(1+$C$2+$C$2+$C$2+$C$2) -> 17500 | BG10: =($D10/12)*(1+$C$2+$C$2+$C$2+$C$2) -> 17500 | BH10: =($D10/12)*(1+$C$2+$C$2+$C$2+$C$2) -> 17500 | BI10: =($D10/12)*(1+$C$2+$C$2+$C$2+$C$2) -> 17500 | BJ10: =($D10/12)*(1+$C$2+$C$2+$C$2+$C$2) -> 17500 | ... CL10: =($D10/12)*(1+$C$2+$C$2+$C$2+$C$2) -> 17500
B11: Data Scientist | C11: Sitech | D11: 145000 | P11: =$D11/12 -> 12083.333 | Q11: =$D11/12 -> 12083.333 | R11: =$D11/12 -> 12083.333 | S11: =($D11/12)*(1+$C$2) -> 12687.5 | T11: =($D11/12)*(1+$C$2) -> 12687.5 | U11: =($D11/12)*(1+$C$2) -> 12687.5 | V11: =($D11/12)*(1+$C$2) -> 12687.5 | W11: =($D11/12)*(1+$C$2) -> 12687.5 | X11: =($D11/12)*(1+$C$2) -> 12687.5 | Y11: =($D11/12)*(1+$C$2) -> 12687.5 | Z11: =($D11/12)*(1+$C$2) -> 12687.5 | ... AD11: =($D11/12)*(1+$C$2) -> 12687.5 | AE11: =($D11/12)*(1+$C$2+$C$2) -> 13291.667 | AF11: =($D11/12)*(1+$C$2+$C$2) -> 13291.667 | AG11: =($D11/12)*(1+$C$2+$C$2) -> 13291.667 | AH11: =($D11/12)*(1+$C$2+$C$2) -> 13291.667 | AI11: =($D11/12)*(1+$C$2+$C$2) -> 13291.667 | AJ11: =($D11/12)*(1+$C$2+$C$2) -> 13291.667 | AK11: =($D11/12)*(1+$C$2+$C$2) -> 13291.667 | AL11: =($D11/12)*(1+$C$2+$C$2) -> 13291.667 | ... AP11: =($D11/12)*(1+$C$2+$C$2) -> 13291.667 | AQ11: =($D11/12)*(1+$C$2+$C$2+$C$2) -> 13895.833 | AR11: =($D11/12)*(1+$C$2+$C$2+$C$2) -> 13895.833 | AS11: =($D11/12)*(1+$C$2+$C$2+$C$2) -> 13895.833 | AT11: =($D11/12)*(1+$C$2+$C$2+$C$2) -> 13895.833 | AU11: =($D11/12)*(1+$C$2+$C$2+$C$2) -> 13895.833 | AV11: =($D11/12)*(1+$C$2+$C$2+$C$2) -> 13895.833 | AW11: =($D11/12)*(1+$C$2+$C$2+$C$2) -> 13895.833 | AX11: =($D11/12)*(1+$C$2+$C$2+$C$2) -> 13895.833 | ... BB11: =($D11/12)*(1+$C$2+$C$2+$C$2) -> 13895.833 | BC11: =($D11/12)*(1+$C$2+$C$2+$C$2+$C$2) -> 14500 | BD11: =($D11/12)*(1+$C$2+$C$2+$C$2+$C$2) -> 14500 | BE11: =($D11/12)*(1+$C$2+$C$2+$C$2+$C$2) -> 14500 | BF11: =($D11/12)*(1+$C$2+$C$2+$C$2+$C$2) -> 14500 | BG11: =($D11/12)*(1+$C$2+$C$2+$C$2+$C$2) -> 14500 | BH11: =($D11/12)*(1+$C$2+$C$2+$C$2+$C$2) -> 14500 | BI11: =($D11/12)*(1+$C$2+$C$2+$C$2+$C$2) -> 14500 | BJ11: =($D11/12)*(1+$C$2+$C$2+$C$2+$C$2) -> 14500 | ... CL11: =($D11/12)*(1+$C$2+$C$2+$C$2+$C$2) -> 14500
B12: Software Developer | C12: Luis | D12: 118000 | O12: =$D12/12 -> 9833.3333 | P12: =$D12/12 -> 9833.3333 | Q12: =$D12/12 -> 9833.3333 | R12: =$D12/12 -> 9833.3333 | S12: =($D12/12)*(1+$C$2) -> 10325 | T12: =($D12/12)*(1+$C$2) -> 10325 | U12: =($D12/12)*(1+$C$2) -> 10325 | V12: =($D12/12)*(1+$C$2) -> 10325
B13: Software Developer | C13: Vincent | D13: 117500 | E13: 135k in May 23 | O13: =$D13/12 -> 9791.6667 | P13: =$D13/12 -> 9791.6667 | Q13: =$D13/12 -> 9791.6667 | R13: =$D13/12 -> 9791.6667 | S13: =($D13/12)*(1+$C$2) -> 10281.25 | T13: =($D13/12)*(1+$C$2) -> 10281.25 | U13: =($D13/12)*(1+$C$2) -> 10281.25 | V13: =($D13/12)*(1+$C$2) -> 10281.25 | W13: =135000/12 -> 11250 | X13: =135000/12 -> 11250 | Y13: =135000/12 -> 11250 | Z13: =135000/12 -> 11250 | AA13: =135000/12 -> 11250 | AB13: =135000/12 -> 11250 | AC13: =135000/12 -> 11250 | AD13: =135000/12 -> 11250 | AE13: =AD13*(1+$C$2) -> 11812.5 | AF13: =AE13 -> 11812.5 | AG13: =AF13 -> 11812.5 | AH13: =AG13 -> 11812.5 | AI13: =AH13 -> 11812.5 | AJ13: =AI13 -> 11812.5 | AK13: =AJ13 -> 11812.5 | AL13: =AK13 -> 11812.5 | AM13: =AL13 -> 11812.5 | ... AP13: =AO13 -> 11812.5 | AQ13: =AP13*(1+$C$2) -> 12403.125 | AR13: =AQ13 -> 12403.125 | AS13: =AR13 -> 12403.125 | AT13: =AS13 -> 12403.125 | AU13: =AT13 -> 12403.125 | AV13: =AU13 -> 12403.125 | AW13: =AV13 -> 12403.125 | AX13: =AW13 -> 12403.125 | AY13: =AX13 -> 12403.125 | ... BB13: =BA13 -> 12403.125 | BC13: =($D13/12)*(1+$C$2+$C$2+$C$2+$C$2) -> 11750 | BD13: =($D13/12)*(1+$C$2+$C$2+$C$2+$C$2) -> 11750 | BE13: =($D13/12)*(1+$C$2+$C$2+$C$2+$C$2) -> 11750 | BF13: =($D13/12)*(1+$C$2+$C$2+$C$2+$C$2) -> 11750 | BG13: =($D13/12)*(1+$C$2+$C$2+$C$2+$C$2) -> 11750 | BH13: =($D13/12)*(1+$C$2+$C$2+$C$2+$C$2) -> 11750 | BI13: =($D13/12)*(1+$C$2+$C$2+$C$2+$C$2) -> 11750 | BJ13: =($D13/12)*(1+$C$2+$C$2+$C$2+$C$2) -> 11750 | ... CL13: =($D13/12)*(1+$C$2+$C$2+$C$2+$C$2) -> 11750
B14: Software Developer | C14: Carl | D14: 110000 | E14: fin septembre 2022 | O14: =$D14/12 -> 9166.6667
B15: Software Developer | C15: Austin | D15: 100000 | S15: =($D15/12)*(1+$C$2) -> 8750 | T15: =($D15/12)*(1+$C$2) -> 8750 | U15: =($D15/12)*(1+$C$2) -> 8750 | V15: =($D15/12)*(1+$C$2) -> 8750 | W15: =($D15/12)*(1+$C$2) -> 8750 | X15: =($D15/12)*(1+$C$2) -> 8750 | Y15: =($D15/12)*(1+$C$2) -> 8750 | Z15: =($D15/12)*(1+$C$2) -> 8750 | ... AD15: =($D15/12)*(1+$C$2) -> 8750 | AE15: =($D15/12)*(1+$C$2+$C$2) -> 9166.6667 | AF15: =($D15/12)*(1+$C$2+$C$2) -> 9166.6667 | AG15: =($D15/12)*(1+$C$2+$C$2) -> 9166.6667 | AH15: =($D15/12)*(1+$C$2+$C$2) -> 9166.6667 | AI15: =($D15/12)*(1+$C$2+$C$2) -> 9166.6667 | AJ15: =($D15/12)*(1+$C$2+$C$2) -> 9166.6667 | AK15: =($D15/12)*(1+$C$2+$C$2) -> 9166.6667 | AL15: =($D15/12)*(1+$C$2+$C$2) -> 9166.6667 | ... AP15: =($D15/12)*(1+$C$2+$C$2) -> 9166.6667 | AQ15: =($D15/12)*(1+$C$2+$C$2+$C$2) -> 9583.3333 | AR15: =($D15/12)*(1+$C$2+$C$2+$C$2) -> 9583.3333 | AS15: =($D15/12)*(1+$C$2+$C$2+$C$2) -> 9583.3333 | AT15: =($D15/12)*(1+$C$2+$C$2+$C$2) -> 9583.3333 | AU15: =($D15/12)*(1+$C$2+$C$2+$C$2) -> 9583.3333 | AV15: =($D15/12)*(1+$C$2+$C$2+$C$2) -> 9583.3333 | AW15: =($D15/12)*(1+$C$2+$C$2+$C$2) -> 9583.3333 | AX15: =($D15/12)*(1+$C$2+$C$2+$C$2) -> 9583.3333 | ... BB15: =($D15/12)*(1+$C$2+$C$2+$C$2) -> 9583.3333 | BC15: =($D15/12)*(1+$C$2+$C$2+$C$2+$C$2) -> 10000 | BD15: =($D15/12)*(1+$C$2+$C$2+$C$2+$C$2) -> 10000 | BE15: =($D15/12)*(1+$C$2+$C$2+$C$2+$C$2) -> 10000 | BF15: =($D15/12)*(1+$C$2+$C$2+$C$2+$C$2) -> 10000 | BG15: =($D15/12)*(1+$C$2+$C$2+$C$2+$C$2) -> 10000 | BH15: =($D15/12)*(1+$C$2+$C$2+$C$2+$C$2) -> 10000 | BI15: =($D15/12)*(1+$C$2+$C$2+$C$2+$C$2) -> 10000 | BJ15: =($D15/12)*(1+$C$2+$C$2+$C$2+$C$2) -> 10000 | ... CL15: =($D15/12)*(1+$C$2+$C$2+$C$2+$C$2) -> 10000
B16: Software Developer | C16: Adrien | D16: 81000 | O16: =$D16/12 -> 6750 | P16: =$D16/12 -> 6750 | Q16: =$D16/12 -> 6750 | R16: =$D16/12 -> 6750 | S16: =($D16/12)*(1+$C$2) -> 7087.5 | T16: =($D16/12)*(1+$C$2) -> 7087.5 | U16: =($D16/12)*(1+$C$2) -> 7087.5 | V16: =($D16/12)*(1+$C$2) -> 7087.5 | W16: =($D16/12)*(1+$C$2) -> 7087.5 | X16: =($D16/12)*(1+$C$2) -> 7087.5 | Y16: =($D16/12)*(1+$C$2) -> 7087.5 | Z16: =($D16/12)*(1+$C$2) -> 7087.5 | ... AD16: =($D16/12)*(1+$C$2) -> 7087.5 | AE16: =($D16/12)*(1+$C$2+$C$2) -> 7425 | AF16: =($D16/12)*(1+$C$2+$C$2) -> 7425 | AG16: =($D16/12)*(1+$C$2+$C$2) -> 7425 | AH16: =($D16/12)*(1+$C$2+$C$2) -> 7425 | AI16: =($D16/12)*(1+$C$2+$C$2) -> 7425 | AJ16: =($D16/12)*(1+$C$2+$C$2) -> 7425 | AK16: =($D16/12)*(1+$C$2+$C$2) -> 7425 | AL16: =($D16/12)*(1+$C$2+$C$2) -> 7425 | ... AP16: =($D16/12)*(1+$C$2+$C$2) -> 7425 | AQ16: =($D16/12)*(1+$C$2+$C$2+$C$2) -> 7762.5 | AR16: =($D16/12)*(1+$C$2+$C$2+$C$2) -> 7762.5 | AS16: =($D16/12)*(1+$C$2+$C$2+$C$2) -> 7762.5 | AT16: =($D16/12)*(1+$C$2+$C$2+$C$2) -> 7762.5 | AU16: =($D16/12)*(1+$C$2+$C$2+$C$2) -> 7762.5 | AV16: =($D16/12)*(1+$C$2+$C$2+$C$2) -> 7762.5 | AW16: =($D16/12)*(1+$C$2+$C$2+$C$2) -> 7762.5 | AX16: =($D16/12)*(1+$C$2+$C$2+$C$2) -> 7762.5 | ... BB16: =($D16/12)*(1+$C$2+$C$2+$C$2) -> 7762.5 | BC16: =($D16/12)*(1+$C$2+$C$2+$C$2+$C$2) -> 8100 | BD16: =($D16/12)*(1+$C$2+$C$2+$C$2+$C$2) -> 8100 | BE16: =($D16/12)*(1+$C$2+$C$2+$C$2+$C$2) -> 8100 | BF16: =($D16/12)*(1+$C$2+$C$2+$C$2+$C$2) -> 8100 | BG16: =($D16/12)*(1+$C$2+$C$2+$C$2+$C$2) -> 8100 | BH16: =($D16/12)*(1+$C$2+$C$2+$C$2+$C$2) -> 8100 | BI16: =($D16/12)*(1+$C$2+$C$2+$C$2+$C$2) -> 8100 | BJ16: =($D16/12)*(1+$C$2+$C$2+$C$2+$C$2) -> 8100 | ... CL16: =($D16/12)*(1+$C$2+$C$2+$C$2+$C$2) -> 8100
B17: Software Developer | C17: Thomas | D17: 58000 | O17: =$D17/12 -> 4833.3333 | P17: =$D17/12 -> 4833.3333 | Q17: =$D17/12 -> 4833.3333 | R17: =$D17/12 -> 4833.3333 | S17: =($D17/12)*(1+$C$2) -> 5075 | T17: =($D17/12)*(1+$C$2) -> 5075 | U17: =($D17/12)*(1+$C$2) -> 5075 | V17: =($D17/12)*(1+$C$2) -> 5075
B18: Software Developer | C18: Eric L | D18: 70000 | E18: conversion de stagiaire a full time en février | T18: =($D18/12)*(1+$C$2) -> 6125 | U18: =($D18/12)*(1+$C$2) -> 6125 | V18: =($D18/12)*(1+$C$2) -> 6125 | W18: =($D18/12)*(1+$C$2) -> 6125 | X18: =($D18/12)*(1+$C$2) -> 6125 | Y18: =($D18/12)*(1+$C$2) -> 6125 | Z18: =($D18/12)*(1+$C$2) -> 6125 | AA18: =($D18/12)*(1+$C$2) -> 6125 | ... AD18: =($D18/12)*(1+$C$2) -> 6125 | AE18: =($D18/12)*(1+$C$2+$C$2) -> 6416.6667 | AF18: =($D18/12)*(1+$C$2+$C$2) -> 6416.6667 | AG18: =($D18/12)*(1+$C$2+$C$2) -> 6416.6667 | AH18: =($D18/12)*(1+$C$2+$C$2) -> 6416.6667 | AI18: =($D18/12)*(1+$C$2+$C$2) -> 6416.6667 | AJ18: =($D18/12)*(1+$C$2+$C$2) -> 6416.6667 | AK18: =($D18/12)*(1+$C$2+$C$2) -> 6416.6667 | AL18: =($D18/12)*(1+$C$2+$C$2) -> 6416.6667 | ... AP18: =($D18/12)*(1+$C$2+$C$2) -> 6416.6667 | AQ18: =($D18/12)*(1+$C$2+$C$2+$C$2) -> 6708.3333 | AR18: =($D18/12)*(1+$C$2+$C$2+$C$2) -> 6708.3333 | AS18: =($D18/12)*(1+$C$2+$C$2+$C$2) -> 6708.3333 | AT18: =($D18/12)*(1+$C$2+$C$2+$C$2) -> 6708.3333 | AU18: =($D18/12)*(1+$C$2+$C$2+$C$2) -> 6708.3333 | AV18: =($D18/12)*(1+$C$2+$C$2+$C$2) -> 6708.3333 | AW18: =($D18/12)*(1+$C$2+$C$2+$C$2) -> 6708.3333 | AX18: =($D18/12)*(1+$C$2+$C$2+$C$2) -> 6708.3333 | ... BB18: =($D18/12)*(1+$C$2+$C$2+$C$2) -> 6708.3333 | BC18: =($D18/12)*(1+$C$2+$C$2+$C$2+$C$2) -> 7000 | BD18: =($D18/12)*(1+$C$2+$C$2+$C$2+$C$2) -> 7000 | BE18: =($D18/12)*(1+$C$2+$C$2+$C$2+$C$2) -> 7000 | BF18: =($D18/12)*(1+$C$2+$C$2+$C$2+$C$2) -> 7000 | BG18: =($D18/12)*(1+$C$2+$C$2+$C$2+$C$2) -> 7000 | BH18: =($D18/12)*(1+$C$2+$C$2+$C$2+$C$2) -> 7000 | BI18: =($D18/12)*(1+$C$2+$C$2+$C$2+$C$2) -> 7000 | BJ18: =($D18/12)*(1+$C$2+$C$2+$C$2+$C$2) -> 7000 | ... CL18: =($D18/12)*(1+$C$2+$C$2+$C$2+$C$2) -> 7000
B19: Software Developer | C19: Charles | D19: 60000 | E19: conversion de pharmacien en developpeur | T19: =($D19/12)*(1+$C$2) -> 5250 | U19: =($D19/12)*(1+$C$2) -> 5250 | V19: =($D19/12)*(1+$C$2) -> 5250 | W19: =($D19/12)*(1+$C$2) -> 5250 | X19: =($D19/12)*(1+$C$2) -> 5250 | Y19: =($D19/12)*(1+$C$2) -> 5250 | Z19: =($D19/12)*(1+$C$2) -> 5250 | AA19: =($D19/12)*(1+$C$2) -> 5250 | ... AD19: =($D19/12)*(1+$C$2) -> 5250 | AE19: =($D19/12)*(1+$C$2+$C$2) -> 5500 | AF19: =($D19/12)*(1+$C$2+$C$2) -> 5500 | AG19: =($D19/12)*(1+$C$2+$C$2) -> 5500 | AH19: =($D19/12)*(1+$C$2+$C$2) -> 5500 | AI19: =($D19/12)*(1+$C$2+$C$2) -> 5500 | AJ19: =($D19/12)*(1+$C$2+$C$2) -> 5500 | AK19: =($D19/12)*(1+$C$2+$C$2) -> 5500 | AL19: =($D19/12)*(1+$C$2+$C$2) -> 5500 | ... AP19: =($D19/12)*(1+$C$2+$C$2) -> 5500 | AQ19: =($D19/12)*(1+$C$2+$C$2+$C$2) -> 5750 | AR19: =($D19/12)*(1+$C$2+$C$2+$C$2) -> 5750 | AS19: =($D19/12)*(1+$C$2+$C$2+$C$2) -> 5750 | AT19: =($D19/12)*(1+$C$2+$C$2+$C$2) -> 5750 | AU19: =($D19/12)*(1+$C$2+$C$2+$C$2) -> 5750 | AV19: =($D19/12)*(1+$C$2+$C$2+$C$2) -> 5750 | AW19: =($D19/12)*(1+$C$2+$C$2+$C$2) -> 5750 | AX19: =($D19/12)*(1+$C$2+$C$2+$C$2) -> 5750 | ... BB19: =($D19/12)*(1+$C$2+$C$2+$C$2) -> 5750 | BC19: =($D19/12)*(1+$C$2+$C$2+$C$2+$C$2) -> 6000 | BD19: =($D19/12)*(1+$C$2+$C$2+$C$2+$C$2) -> 6000 | BE19: =($D19/12)*(1+$C$2+$C$2+$C$2+$C$2) -> 6000 | BF19: =($D19/12)*(1+$C$2+$C$2+$C$2+$C$2) -> 6000 | BG19: =($D19/12)*(1+$C$2+$C$2+$C$2+$C$2) -> 6000 | BH19: =($D19/12)*(1+$C$2+$C$2+$C$2+$C$2) -> 6000 | BI19: =($D19/12)*(1+$C$2+$C$2+$C$2+$C$2) -> 6000 | BJ19: =($D19/12)*(1+$C$2+$C$2+$C$2+$C$2) -> 6000 | ... CL19: =($D19/12)*(1+$C$2+$C$2+$C$2+$C$2) -> 6000
B20: Software Developer | C20: TBH | D20: 120000 | AB20: =($D20/12)*(1+$C$2) -> 10500 | AC20: =($D20/12)*(1+$C$2) -> 10500 | AD20: =($D20/12)*(1+$C$2) -> 10500 | AE20: =($D20/12)*(1+$C$2+$C$2) -> 11000 | AF20: =($D20/12)*(1+$C$2+$C$2) -> 11000 | AG20: =($D20/12)*(1+$C$2+$C$2) -> 11000 | AH20: =($D20/12)*(1+$C$2+$C$2) -> 11000 | AI20: =($D20/12)*(1+$C$2+$C$2) -> 11000 | AJ20: =($D20/12)*(1+$C$2+$C$2) -> 11000 | AK20: =($D20/12)*(1+$C$2+$C$2) -> 11000 | AL20: =($D20/12)*(1+$C$2+$C$2) -> 11000 | ... AP20: =($D20/12)*(1+$C$2+$C$2) -> 11000 | AQ20: =($D20/12)*(1+$C$2+$C$2+$C$2) -> 11500 | AR20: =($D20/12)*(1+$C$2+$C$2+$C$2) -> 11500 | AS20: =($D20/12)*(1+$C$2+$C$2+$C$2) -> 11500 | AT20: =($D20/12)*(1+$C$2+$C$2+$C$2) -> 11500 | AU20: =($D20/12)*(1+$C$2+$C$2+$C$2) -> 11500 | AV20: =($D20/12)*(1+$C$2+$C$2+$C$2) -> 11500 | AW20: =($D20/12)*(1+$C$2+$C$2+$C$2) -> 11500 | AX20: =($D20/12)*(1+$C$2+$C$2+$C$2) -> 11500 | ... BB20: =($D20/12)*(1+$C$2+$C$2+$C$2) -> 11500 | BC20: =($D20/12)*(1+$C$2+$C$2+$C$2+$C$2) -> 12000 | BD20: =($D20/12)*(1+$C$2+$C$2+$C$2+$C$2) -> 12000 | BE20: =($D20/12)*(1+$C$2+$C$2+$C$2+$C$2) -> 12000 | BF20: =($D20/12)*(1+$C$2+$C$2+$C$2+$C$2) -> 12000 | BG20: =($D20/12)*(1+$C$2+$C$2+$C$2+$C$2) -> 12000 | BH20: =($D20/12)*(1+$C$2+$C$2+$C$2+$C$2) -> 12000 | BI20: =($D20/12)*(1+$C$2+$C$2+$C$2+$C$2) -> 12000 | BJ20: =($D20/12)*(1+$C$2+$C$2+$C$2+$C$2) -> 12000 | ... CL20: =($D20/12)*(1+$C$2+$C$2+$C$2+$C$2) -> 12000
B21: Software Developer | C21: TBH | D21: 80000 | O21: =$D21/12 -> 6666.6667 | P21: =$D21/12 -> 6666.6667 | Q21: =$D21/12 -> 6666.6667 | R21: =$D21/12 -> 6666.6667 | AJ21: =($D21/12)*(1+$C$2+$C$2) -> 7333.3333 | AK21: =($D21/12)*(1+$C$2+$C$2) -> 7333.3333 | AL21: =($D21/12)*(1+$C$2+$C$2) -> 7333.3333 | AM21: =($D21/12)*(1+$C$2+$C$2) -> 7333.3333 | AN21: =($D21/12)*(1+$C$2+$C$2) -> 7333.3333 | AO21: =($D21/12)*(1+$C$2+$C$2) -> 7333.3333 | AP21: =($D21/12)*(1+$C$2+$C$2) -> 7333.3333 | AQ21: =($D21/12)*(1+$C$2+$C$2+$C$2) -> 7666.6667 | AR21: =($D21/12)*(1+$C$2+$C$2+$C$2) -> 7666.6667 | AS21: =($D21/12)*(1+$C$2+$C$2+$C$2) -> 7666.6667 | AT21: =($D21/12)*(1+$C$2+$C$2+$C$2) -> 7666.6667 | AU21: =($D21/12)*(1+$C$2+$C$2+$C$2) -> 7666.6667 | AV21: =($D21/12)*(1+$C$2+$C$2+$C$2) -> 7666.6667 | AW21: =($D21/12)*(1+$C$2+$C$2+$C$2) -> 7666.6667 | AX21: =($D21/12)*(1+$C$2+$C$2+$C$2) -> 7666.6667 | ... BB21: =($D21/12)*(1+$C$2+$C$2+$C$2) -> 7666.6667 | BC21: =($D21/12)*(1+$C$2+$C$2+$C$2+$C$2) -> 8000 | BD21: =($D21/12)*(1+$C$2+$C$2+$C$2+$C$2) -> 8000 | BE21: =($D21/12)*(1+$C$2+$C$2+$C$2+$C$2) -> 8000 | BF21: =($D21/12)*(1+$C$2+$C$2+$C$2+$C$2) -> 8000 | BG21: =($D21/12)*(1+$C$2+$C$2+$C$2+$C$2) -> 8000 | BH21: =($D21/12)*(1+$C$2+$C$2+$C$2+$C$2) -> 8000 | BI21: =($D21/12)*(1+$C$2+$C$2+$C$2+$C$2) -> 8000 | BJ21: =($D21/12)*(1+$C$2+$C$2+$C$2+$C$2) -> 8000 | ... CL21: =($D21/12)*(1+$C$2+$C$2+$C$2+$C$2) -> 8000
B22: Software Developer | C22: TBH | D22: 85000 | AJ22: =D22/12 -> 7083.3333 | AK22: =AJ22 -> 7083.3333 | AL22: =AK22 -> 7083.3333 | AM22: =AL22 -> 7083.3333 | AN22: =AM22 -> 7083.3333 | AO22: =AN22 -> 7083.3333 | AP22: =AO22 -> 7083.3333 | AQ22: =AP22*(1+C2) -> 7437.5 | AR22: =AQ22 -> 7437.5 | AS22: =AR22 -> 7437.5 | AT22: =AS22 -> 7437.5 | AU22: =AT22 -> 7437.5 | AV22: =AU22 -> 7437.5 | AW22: =AV22 -> 7437.5 | AX22: =AW22 -> 7437.5 | AY22: =AX22 -> 7437.5 | ... BB22: =BA22 -> 7437.5 | BC22: =($D22/12)*(1+$C$2+$C$2+$C$2+$C$2) -> 8500 | BD22: =($D22/12)*(1+$C$2+$C$2+$C$2+$C$2) -> 8500 | BE22: =($D22/12)*(1+$C$2+$C$2+$C$2+$C$2) -> 8500 | BF22: =($D22/12)*(1+$C$2+$C$2+$C$2+$C$2) -> 8500 | BG22: =($D22/12)*(1+$C$2+$C$2+$C$2+$C$2) -> 8500 | BH22: =($D22/12)*(1+$C$2+$C$2+$C$2+$C$2) -> 8500 | BI22: =($D22/12)*(1+$C$2+$C$2+$C$2+$C$2) -> 8500 | BJ22: =($D22/12)*(1+$C$2+$C$2+$C$2+$C$2) -> 8500 | ... CL22: =($D22/12)*(1+$C$2+$C$2+$C$2+$C$2) -> 8500
B23: Software Developer | C23: TBH | D23: 85000 | AQ23: =D23/12 -> 7083.3333 | AR23: =AQ23 -> 7083.3333 | AS23: =AR23 -> 7083.3333 | AT23: =AS23 -> 7083.3333 | AU23: =AT23 -> 7083.3333 | AV23: =AU23 -> 7083.3333 | AW23: =AV23 -> 7083.3333 | AX23: =AW23 -> 7083.3333 | AY23: =AX23 -> 7083.3333 | ... BB23: =BA23 -> 7083.3333 | BC23: =($D23/12)*(1+$C$2+$C$2+$C$2+$C$2) -> 8500 | BD23: =($D23/12)*(1+$C$2+$C$2+$C$2+$C$2) -> 8500 | BE23: =($D23/12)*(1+$C$2+$C$2+$C$2+$C$2) -> 8500 | BF23: =($D23/12)*(1+$C$2+$C$2+$C$2+$C$2) -> 8500 | BG23: =($D23/12)*(1+$C$2+$C$2+$C$2+$C$2) -> 8500 | BH23: =($D23/12)*(1+$C$2+$C$2+$C$2+$C$2) -> 8500 | BI23: =($D23/12)*(1+$C$2+$C$2+$C$2+$C$2) -> 8500 | BJ23: =($D23/12)*(1+$C$2+$C$2+$C$2+$C$2) -> 8500 | ... CL23: =($D23/12)*(1+$C$2+$C$2+$C$2+$C$2) -> 8500
B24: Developer AI | C24: William Intern | D24: 125000 | S24: =8*4*32 -> 1024 | T24: =S24 -> 1024 | AQ24: =D24/12 -> 10416.667 | AR24: =AQ24 -> 10416.667 | AS24: =AR24 -> 10416.667 | AT24: =AS24 -> 10416.667 | AU24: =AT24 -> 10416.667 | AV24: =AU24 -> 10416.667 | AW24: =AV24 -> 10416.667 | AX24: =AW24 -> 10416.667 | AY24: =AX24 -> 10416.667 | ... BB24: =BA24 -> 10416.667 | BC24: =($D24/12)*(1+$C$2+$C$2+$C$2+$C$2) -> 12500 | BD24: =($D24/12)*(1+$C$2+$C$2+$C$2+$C$2) -> 12500 | BE24: =($D24/12)*(1+$C$2+$C$2+$C$2+$C$2) -> 12500 | BF24: =($D24/12)*(1+$C$2+$C$2+$C$2+$C$2) -> 12500 | BG24: =($D24/12)*(1+$C$2+$C$2+$C$2+$C$2) -> 12500 | BH24: =($D24/12)*(1+$C$2+$C$2+$C$2+$C$2) -> 12500 | BI24: =($D24/12)*(1+$C$2+$C$2+$C$2+$C$2) -> 12500 | BJ24: =($D24/12)*(1+$C$2+$C$2+$C$2+$C$2) -> 12500 | ... CL24: =($D24/12)*(1+$C$2+$C$2+$C$2+$C$2) -> 12500
B26: Soft Dev FS - Intern | C26: TBH | D26: =4.33*40*30 -> 5196 | E26: per week (60k/year) | W26: =D26 -> 5196 | X26: =W26 -> 5196 | Y26: =X26 -> 5196 | Z26: =Y26 -> 5196
B27: Soft Dev AI - Intern | C27: TBH | D27: =4.33*40*30 -> 5196 | E27: per week (60k/year) | W27: =D27 -> 5196 | X27: =W27 -> 5196 | Y27: =X27 -> 5196 | Z27: =Y27 -> 5196
B29: TOTAL | G29: =SUM(G8:G28) -> 0 | H29: =SUM(H8:H28) -> 0 | I29: =SUM(I8:I28) -> 0 | J29: =SUM(J8:J28) -> 0 | K29: =SUM(K8:K28) -> 0 | L29: =SUM(L8:L28) -> 0 | M29: =SUM(M8:M28) -> 0 | N29: =SUM(N8:N28) -> 0 | ... S29: =SUM(S8:S28) -> 70542.75 | T29: =SUM(T9:T28) -> 81917.75 | U29: =SUM(U9:U28) -> 80893.75 | V29: =SUM(V9:V28) -> 80893.75 | W29: =SUM(W9:W28) -> 76854.5 | X29: =SUM(X9:X28) -> 76854.5 | Y29: =SUM(Y9:Y28) -> 76854.5 | Z29: =SUM(Z9:Z28) -> 76854.5 | AA29: =SUM(AA9:AA28) -> 66462.5 | ... CL29: =SUM(CL9:CL28) -> 124350
B32: Sales & Marketing
B33: CRO | C33: Simon | D33: 175000 | O33: =$D33/12 -> 14583.333 | P33: =$D33/12 -> 14583.333 | Q33: =$D33/12 -> 14583.333 | R33: =$D33/12 -> 14583.333 | W33: =($D33/12)*(1+$C$2) -> 15312.5 | X33: =($D33/12)*(1+$C$2) -> 15312.5 | Y33: =($D33/12)*(1+$C$2) -> 15312.5 | Z33: =($D33/12)*(1+$C$2) -> 15312.5 | AA33: =($D33/12)*(1+$C$2) -> 15312.5
B34: Data Analyst | C34: TBH | D34: 100000 | AL34: =($D34/12)*(1+$C$2+$C$2) -> 9166.6667 | AM34: =($D34/12)*(1+$C$2+$C$2) -> 9166.6667 | AN34: =($D34/12)*(1+$C$2+$C$2) -> 9166.6667 | AO34: =($D34/12)*(1+$C$2+$C$2) -> 9166.6667 | AP34: =($D34/12)*(1+$C$2+$C$2) -> 9166.6667 | AQ34: =($D34/12)*(1+$C$2+$C$2+$C$2) -> 9583.3333 | AR34: =($D34/12)*(1+$C$2+$C$2+$C$2) -> 9583.3333 | AS34: =($D34/12)*(1+$C$2+$C$2+$C$2) -> 9583.3333 | AT34: =($D34/12)*(1+$C$2+$C$2+$C$2) -> 9583.3333 | AU34: =($D34/12)*(1+$C$2+$C$2+$C$2) -> 9583.3333 | AV34: =($D34/12)*(1+$C$2+$C$2+$C$2) -> 9583.3333 | AW34: =($D34/12)*(1+$C$2+$C$2+$C$2) -> 9583.3333 | AX34: =($D34/12)*(1+$C$2+$C$2+$C$2) -> 9583.3333 | ... CL34: =($D34/12)*(1+$C$2+$C$2+$C$2) -> 9583.3333
B35: Biz Dev | C35: Karine | D35: 150000 | AI35: =($D35/12)*(1+$C$2+$C$2) -> 13750 | AJ35: =AI35 -> 13750 | AK35: =AJ35 -> 13750 | AL35: =AK35 -> 13750 | AM35: =AL35 -> 13750 | AN35: =AM35 -> 13750 | AO35: =AN35 -> 13750 | AP35: =AO35 -> 13750 | AQ35: =AP35*(1+$C$2) -> 14437.5 | AR35: =AQ35 -> 14437.5 | AS35: =AR35 -> 14437.5 | AT35: =AS35 -> 14437.5 | AU35: =AT35 -> 14437.5 | AV35: =AU35 -> 14437.5 | AW35: =AV35 -> 14437.5 | AX35: =AW35 -> 14437.5 | AY35: =AX35 -> 14437.5 | ... BB35: =BA35 -> 14437.5 | BC35: =BB35*(1+$C$2) -> 15159.375 | BD35: =BC35 -> 15159.375 | BE35: =BD35 -> 15159.375 | BF35: =BE35 -> 15159.375 | BG35: =BF35 -> 15159.375 | BH35: =BG35 -> 15159.375 | BI35: =BH35 -> 15159.375 | BJ35: =BI35 -> 15159.375 | BK35: =BJ35 -> 15159.375 | ... BN35: =BM35 -> 15159.375 | BO35: =BN35*(1+$C$2) -> 15917.344 | BP35: =BO35 -> 15917.344 | BQ35: =BP35 -> 15917.344 | BR35: =BQ35 -> 15917.344 | BS35: =BR35 -> 15917.344 | BT35: =BS35 -> 15917.344 | BU35: =BT35 -> 15917.344 | BV35: =BU35 -> 15917.344 | BW35: =BV35 -> 15917.344 | ... BZ35: =BY35 -> 15917.344 | CA35: =BZ35*(1+$C$2) -> 16713.211 | CB35: =CA35 -> 16713.211 | CC35: =CB35 -> 16713.211 | CD35: =CC35 -> 16713.211 | CE35: =CD35 -> 16713.211 | CF35: =CE35 -> 16713.211 | CG35: =CF35 -> 16713.211 | CH35: =CG35 -> 16713.211 | CI35: =CH35 -> 16713.211 | ... CL35: =CK35 -> 16713.211
B36: Product Owner | C36: Gabriel | D36: 92000 | O36: =$D36/12 -> 7666.6667 | P36: =$D36/12 -> 7666.6667 | Q36: =$D36/12 -> 7666.6667 | R36: =$D36/12 -> 7666.6667 | S36: =($D36/12)*(1+$C$2) -> 8050 | T36: =($D36/12)*(1+$C$2) -> 8050 | U36: =($D36/12)*(1+$C$2) -> 8050 | V36: =($D36/12)*(1+$C$2) -> 8050 | W36: =($D36/12)*(1+$C$2) -> 8050 | X36: =($D36/12)*(1+$C$2) -> 8050 | AE36: =($D36/12)*(1+$C$2+$C$2) -> 8433.3333 | AF36: =($D36/12)*(1+$C$2+$C$2) -> 8433.3333 | AG36: =($D36/12)*(1+$C$2+$C$2) -> 8433.3333 | AH36: =($D36/12)*(1+$C$2+$C$2) -> 8433.3333 | AI36: =($D36/12)*(1+$C$2+$C$2) -> 8433.3333 | AJ36: =($D36/12)*(1+$C$2+$C$2) -> 8433.3333 | AK36: =($D36/12)*(1+$C$2+$C$2) -> 8433.3333 | AL36: =($D36/12)*(1+$C$2+$C$2) -> 8433.3333 | ... AP36: =($D36/12)*(1+$C$2+$C$2) -> 8433.3333 | AQ36: =($D36/12)*(1+$C$2+$C$2+$C$2) -> 8816.6667 | AR36: =($D36/12)*(1+$C$2+$C$2+$C$2) -> 8816.6667 | AS36: =($D36/12)*(1+$C$2+$C$2+$C$2) -> 8816.6667 | AT36: =($D36/12)*(1+$C$2+$C$2+$C$2) -> 8816.6667 | AU36: =($D36/12)*(1+$C$2+$C$2+$C$2) -> 8816.6667 | AV36: =($D36/12)*(1+$C$2+$C$2+$C$2) -> 8816.6667 | AW36: =($D36/12)*(1+$C$2+$C$2+$C$2) -> 8816.6667 | AX36: =($D36/12)*(1+$C$2+$C$2+$C$2) -> 8816.6667 | ... CL36: =($D36/12)*(1+$C$2+$C$2+$C$2) -> 8816.6667
B37: Marketing Manager | C37: TBH | D37: 90000 | O37: =$D37/12 -> 7500 | P37: =$D37/12 -> 7500 | Q37: =$D37/12 -> 7500 | R37: =$D37/12 -> 7500 | AE37: =($D37/12)*(1+$C$2+$C$2) -> 8250 | AF37: =($D37/12)*(1+$C$2+$C$2) -> 8250 | AG37: =($D37/12)*(1+$C$2+$C$2) -> 8250 | AH37: =($D37/12)*(1+$C$2+$C$2) -> 8250 | AI37: =($D37/12)*(1+$C$2+$C$2) -> 8250 | AJ37: =($D37/12)*(1+$C$2+$C$2) -> 8250 | AK37: =($D37/12)*(1+$C$2+$C$2) -> 8250 | AL37: =($D37/12)*(1+$C$2+$C$2) -> 8250 | ... AP37: =($D37/12)*(1+$C$2+$C$2) -> 8250 | AQ37: =($D37/12)*(1+$C$2+$C$2+$C$2) -> 8625 | AR37: =($D37/12)*(1+$C$2+$C$2+$C$2) -> 8625 | AS37: =($D37/12)*(1+$C$2+$C$2+$C$2) -> 8625 | AT37: =($D37/12)*(1+$C$2+$C$2+$C$2) -> 8625 | AU37: =($D37/12)*(1+$C$2+$C$2+$C$2) -> 8625 | AV37: =($D37/12)*(1+$C$2+$C$2+$C$2) -> 8625 | AW37: =($D37/12)*(1+$C$2+$C$2+$C$2) -> 8625 | AX37: =($D37/12)*(1+$C$2+$C$2+$C$2) -> 8625 | ... CL37: =($D37/12)*(1+$C$2+$C$2+$C$2) -> 8625
B38: Channel Manager | C38: TBH | D38: 90000 | AL38: =($D38/12)*(1+$C$2+$C$2) -> 8250 | AM38: =AL38 -> 8250 | AN38: =AM38 -> 8250 | AO38: =AN38 -> 8250 | AP38: =AO38 -> 8250 | AQ38: =AP38*(1+$C$2) -> 8662.5 | AR38: =AQ38 -> 8662.5 | AS38: =AR38 -> 8662.5 | AT38: =AS38 -> 8662.5 | AU38: =AT38 -> 8662.5 | AV38: =AU38 -> 8662.5 | AW38: =AV38 -> 8662.5 | AX38: =AW38 -> 8662.5 | AY38: =AX38 -> 8662.5 | ... BB38: =BA38 -> 8662.5 | BC38: =BB38*(1+$C$2) -> 9095.625 | BD38: =BC38 -> 9095.625 | BE38: =BD38 -> 9095.625 | BF38: =BE38 -> 9095.625 | BG38: =BF38 -> 9095.625 | BH38: =BG38 -> 9095.625 | BI38: =BH38 -> 9095.625 | BJ38: =BI38 -> 9095.625 | BK38: =BJ38 -> 9095.625 | ... BN38: =BM38 -> 9095.625 | BO38: =BN38*(1+$C$2) -> 9550.4062 | BP38: =BO38 -> 9550.4062 | BQ38: =BP38 -> 9550.4062 | BR38: =BQ38 -> 9550.4062 | BS38: =BR38 -> 9550.4062 | BT38: =BS38 -> 9550.4062 | BU38: =BT38 -> 9550.4062 | BV38: =BU38 -> 9550.4062 | BW38: =BV38 -> 9550.4062 | ... BZ38: =BY38 -> 9550.4062 | CA38: =BZ38*(1+$C$2) -> 10027.927 | CB38: =CA38 -> 10027.927 | CC38: =CB38 -> 10027.927 | CD38: =CC38 -> 10027.927 | CE38: =CD38 -> 10027.927 | CF38: =CE38 -> 10027.927 | CG38: =CF38 -> 10027.927 | CH38: =CG38 -> 10027.927 | CI38: =CH38 -> 10027.927 | ... CL38: =CK38 -> 10027.927
